Workbook
Name Nyquist: I10_P300_T70_HR0!$A$1:$K$55
Name Nyquist: I10_P400_T70_HR50!$A$1:$K$55
Name Nyquist: I10_P500_T70_HR50!$A$1:$K$55
Name Nyquist: I20_P300_T70_HR0!$A$1:$K$55
Name Nyquist: I20_P400_T70_HR50!$A$1:$K$55
Name Nyquist: I20_P500_T70_HR50!$A$1:$K$55
Name Nyquist: I30_P300_T70_HR0!$A$1:$K$55
Name Nyquist: I30_P300_T70_HR50!$A$1:$K$55
Name Nyquist: I30_P400_T70_HR50!$A$1:$K$55
Name Nyquist: I30_P500_T70_HR50!$A$1:$K$55
Name Nyquist: I35_P300_T70_HR0!$A$1:$K$55
Name Nyquist: I35_P300_T70_HR50!$A$1:$K$55
Name Nyquist: I35_P400_T70_HR50!$A$1:$K$55
Name Nyquist: I35_P500_T70_HR50!$A$1:$K$55
Name Nyquist: I40_P300_T70_HR0!$A$1:$K$55
Name Nyquist: I40_P400_T70_HR50!$A$1:$K$55
Name Nyquist: I45_P300_T70_HR0!$A$1:$K$55
Name Nyquist: I50_P500_T70_HRK20!$A$1:$K$68
Name Nyquist_1: I10_P300_T70_HR50!$A$1:$K$55
Name Nyquist_1: I20_P300_T70_HR50!$A$1:$K$55
Name Nyquist_1: I40_P300_T70_HR50!$A$1:$K$55
Name Nyquist_1: I40_P500_T70_HR50!$A$1:$K$55
Name Nyquist_1: I45_P300_T70_HR50!$A$1:$K$55
Name Nyquist_1: I45_P400_T70_HR50!$A$1:$K$55
Name Nyquist_1: I45_P500_T70_HR50!$A$1:$K$55
Name Nyquist_1: I50_P300_T70_HR50!$A$1:$K$49
Name Nyquist_1: I50_P400_T70_HR50!$A$1:$K$55
Name Nyquist_1: I50_P500_T70_HR50!$A$1:$K$55

Sheet I10_P300_T70_HR50
A1: Temps (ms) | B1: Fr駲uence (Hz) | C1: Module de Z (mOhm) | D1: d駱hasage de Z (ｰ) | E1: Partie r馥lle | F1: Partie imaginaire | G1: Module de Zstack (mOhm) | H1: d駱hasage de Zstack (ｰ) | I1: Partie r馥lle stack | J1: Partie imaginaire stack
A2: 0 | B2: 1000 | C2: 38.92397 | D2: -15.67585 | E2: 37.47622 | F2: -10.51705 | G2: NaN | H2: NaN | I2: NaN | J2: NaN
A3: 2039 | B3: 935.71429 | C3: 40.08575 | D3: -14.67619 | E3: 38.77788 | F3: -10.15596 | G3: NaN | H3: NaN | I3: NaN | J3: NaN
A4: 3395 | B4: 871.42857 | C4: 40.21605 | D4: -14.54416 | E4: 38.9273 | F4: -10.0993 | G4: NaN | H4: NaN | I4: NaN | J4: NaN
A5: 4832 | B5: 807.14286 | C5: 40.26085 | D5: -15.6254 | E5: 38.77294 | F5: -10.84413 | G5: NaN | H5: NaN | I5: NaN | J5: NaN
A6: 6023 | B6: 742.85714 | C6: 40.58352 | D6: -375.4684 | E6: 39.11349 | F6: -10.8239 | G6: NaN | H6: NaN | I6: NaN | J6: NaN
A7: 7459 | B7: 678.57143 | C7: 41.63884 | D7: -376.29488 | E7: 39.96622 | F7: -11.68306 | G7: NaN | H7: NaN | I7: NaN | J7: NaN
A8: 8641 | B8: 614.28571 | C8: 41.72388 | D8: -375.81546 | E8: 40.1444 | F8: -11.37142 | G8: NaN | H8: NaN | I8: NaN | J8: NaN
A9: 10044 | B9: 550 | C9: 42.98484 | D9: -377.35517 | E9: 41.02791 | F9: -12.82212 | G9: NaN | H9: NaN | I9: NaN | J9: NaN
A10: 11274 | B10: 485.71429 | C10: 43.60984 | D10: -378.09951 | E10: 41.45195 | F10: -13.54819 | G10: NaN | H10: NaN | I10: NaN | J10: NaN
A11: 12736 | B11: 421.42857 | C11: 44.75331 | D11: -379.16095 | E11: 42.27399 | F11: -14.68906 | G11: NaN | H11: NaN | I11: NaN | J11: NaN
A12: 13888 | B12: 357.14286 | C12: 46.04474 | D12: -379.79565 | E12: 43.32379 | F12: -15.59381 | G12: NaN | H12: NaN | I12: NaN | J12: NaN
A13: 15109 | B13: 292.85714 | C13: 47.75953 | D13: -21.88114 | E13: 44.31888 | F13: -17.79913 | G13: NaN | H13: NaN | I13: NaN | J13: NaN
... A55: 245518 | B55: 0.1 | C55: 248.53949 | D55: 0.2842 | E55: 248.53643 | F55: 1.2328 | G55: NaN | H55: NaN | I55: NaN | J55: NaN

Sheet I10_P400_T70_HR50
A1: Temps (ms) | B1: Fr駲uence (Hz) | C1: Module de Z (mOhm) | D1: d駱hasage de Z (ｰ) | E1: Partie r馥lle | F1: Partie imaginaire | G1: Module de Zstack (mOhm) | H1: d駱hasage de Zstack (ｰ) | I1: Partie r馥lle stack | J1: Partie imaginaire stack
A2: 0 | B2: 1000 | C2: 37.34603 | D2: -12.46368 | E2: 36.46589 | F2: -8.06005 | G2: NaN | H2: NaN | I2: NaN | J2: NaN
A3: 1383 | B3: 935.71429 | C3: 37.89905 | D3: -13.43689 | E3: 36.86162 | F3: -8.80676 | G3: NaN | H3: NaN | I3: NaN | J3: NaN
A4: 2796 | B4: 871.42857 | C4: 37.70753 | D4: -12.73456 | E4: 36.78 | F4: -8.31205 | G4: NaN | H4: NaN | I4: NaN | J4: NaN
A5: 3997 | B5: 807.14286 | C5: 37.83721 | D5: -14.60609 | E5: 36.6144 | F5: -9.54149 | G5: NaN | H5: NaN | I5: NaN | J5: NaN
A6: 5255 | B6: 742.85714 | C6: 38.56801 | D6: -374.51035 | E6: 37.33778 | F6: -9.6634 | G6: NaN | H6: NaN | I6: NaN | J6: NaN
A7: 6618 | B7: 678.57143 | C7: 39.41581 | D7: -375.85121 | E7: 37.91699 | F7: -10.76604 | G7: NaN | H7: NaN | I7: NaN | J7: NaN
A8: 7827 | B8: 614.28571 | C8: 40.34421 | D8: -376.0185 | E8: 38.77775 | F8: -11.13289 | G8: NaN | H8: NaN | I8: NaN | J8: NaN
A9: 9231 | B9: 550 | C9: 40.6052 | D9: -376.25455 | E9: 38.98212 | F9: -11.36561 | G9: NaN | H9: NaN | I9: NaN | J9: NaN
A10: 10476 | B10: 485.71429 | C10: 40.48792 | D10: -377.24564 | E10: 38.66768 | F10: -12.00341 | G10: NaN | H10: NaN | I10: NaN | J10: NaN
A11: 11861 | B11: 421.42857 | C11: 42.13555 | D11: -378.50892 | E11: 39.95606 | F11: -13.37602 | G11: NaN | H11: NaN | I11: NaN | J11: NaN
A12: 13085 | B12: 357.14286 | C12: 43.64453 | D12: -379.72732 | E12: 41.08302 | F12: -14.73195 | G12: NaN | H12: NaN | I12: NaN | J12: NaN
A13: 14740 | B13: 292.85714 | C13: 45.12998 | D13: -21.66707 | E13: 41.94132 | F13: -16.66256 | G13: NaN | H13: NaN | I13: NaN | J13: NaN
... A55: 246556 | B55: 0.1 | C55: 237.61773 | D55: -0.5496 | E55: 237.6068 | F55: -2.27929 | G55: NaN | H55: NaN | I55: NaN | J55: NaN

Sheet I10_P500_T70_HR50
A1: Temps (ms) | B1: Fr駲uence (Hz) | C1: Module de Z (mOhm) | D1: d駱hasage de Z (ｰ) | E1: Partie r馥lle | F1: Partie imaginaire | G1: Module de Zstack (mOhm) | H1: d駱hasage de Zstack (ｰ) | I1: Partie r馥lle stack | J1: Partie imaginaire stack
A2: 0 | B2: 1000 | C2: 37.85664 | D2: -14.49943 | E2: 36.65091 | F2: -9.47818 | G2: NaN | H2: NaN | I2: NaN | J2: NaN
A3: 1080 | B3: 935.71429 | C3: 37.3063 | D3: -14.73218 | E3: 36.07986 | F3: -9.48704 | G3: NaN | H3: NaN | I3: NaN | J3: NaN
A4: 2484 | B4: 871.42857 | C4: 37.63864 | D4: -14.39201 | E4: 36.45746 | F4: -9.35527 | G4: NaN | H4: NaN | I4: NaN | J4: NaN
A5: 3692 | B5: 807.14286 | C5: 37.53395 | D5: -14.51639 | E5: 36.33571 | F5: -9.40814 | G5: NaN | H5: NaN | I5: NaN | J5: NaN
A6: 5137 | B6: 742.85714 | C6: 38.12417 | D6: -375.14464 | E6: 36.80009 | F6: -9.96019 | G6: NaN | H6: NaN | I6: NaN | J6: NaN
A7: 6317 | B7: 678.57143 | C7: 38.67319 | D7: -375.24307 | E7: 37.31263 | F7: -10.16774 | G7: NaN | H7: NaN | I7: NaN | J7: NaN
A8: 7748 | B8: 614.28571 | C8: 39.19759 | D8: -376.16094 | E8: 37.64864 | F8: -10.91011 | G8: NaN | H8: NaN | I8: NaN | J8: NaN
A9: 8943 | B9: 550 | C9: 39.38955 | D9: -377.13275 | E9: 37.64163 | F9: -11.60363 | G9: NaN | H9: NaN | I9: NaN | J9: NaN
A10: 10206 | B10: 485.71429 | C10: 41.0122 | D10: -377.26699 | E10: 39.16386 | F10: -12.17344 | G10: NaN | H10: NaN | I10: NaN | J10: NaN
A11: 11565 | B11: 421.42857 | C11: 41.45072 | D11: -378.26364 | E11: 39.36263 | F11: -12.99024 | G11: NaN | H11: NaN | I11: NaN | J11: NaN
A12: 12800 | B12: 357.14286 | C12: 42.75245 | D12: -379.78097 | E12: 40.22977 | F12: -14.46851 | G12: NaN | H12: NaN | I12: NaN | J12: NaN
A13: 14203 | B13: 292.85714 | C13: 44.48252 | D13: -21.40798 | E13: 41.41345 | F13: -16.23641 | G13: NaN | H13: NaN | I13: NaN | J13: NaN
... A55: 247618 | B55: 0.1 | C55: 233.75297 | D55: 0.56581 | E55: 233.74157 | F55: 2.30834 | G55: NaN | H55: NaN | I55: NaN | J55: NaN

Sheet I20_P300_T70_HR50
A1: Temps (ms) | B1: Fr駲uence (Hz) | C1: Module de Z (mOhm) | D1: d駱hasage de Z (ｰ) | E1: Partie r馥lle | F1: Partie imaginaire | G1: Module de Zstack (mOhm) | H1: d駱hasage de Zstack (ｰ) | I1: Partie r馥lle stack | J1: Partie imaginaire stack
A2: 0 | B2: 1000 | C2: 38.42262 | D2: -13.98194 | E2: 37.28423 | F2: -9.28352 | G2: NaN | H2: NaN | I2: NaN | J2: NaN
A3: 2605 | B3: 935.71429 | C3: 39.87443 | D3: -15.21652 | E3: 38.47646 | F3: -10.46574 | G3: NaN | H3: NaN | I3: NaN | J3: NaN
A4: 5113 | B4: 871.42857 | C4: 39.45643 | D4: -15.80048 | E4: 37.96559 | F4: -10.74353 | G4: NaN | H4: NaN | I4: NaN | J4: NaN
A5: 7705 | B5: 807.14286 | C5: 40.19122 | D5: -14.95207 | E5: 38.83042 | F5: -10.36977 | G5: NaN | H5: NaN | I5: NaN | J5: NaN
A6: 10336 | B6: 742.85714 | C6: 40.69794 | D6: -375.50201 | E6: 39.21739 | F6: -10.87743 | G6: NaN | H6: NaN | I6: NaN | J6: NaN
A7: 12963 | B7: 678.57143 | C7: 41.10944 | D7: -375.90742 | E7: 39.53519 | F7: -11.26743 | G7: NaN | H7: NaN | I7: NaN | J7: NaN
A8: 15617 | B8: 614.28571 | C8: 41.82969 | D8: -376.18327 | E8: 40.1722 | F8: -11.65838 | G8: NaN | H8: NaN | I8: NaN | J8: NaN
A9: 18156 | B9: 550 | C9: 42.43741 | D9: -377.01986 | E9: 40.57879 | F9: -12.42157 | G9: NaN | H9: NaN | I9: NaN | J9: NaN
A10: 20842 | B10: 485.71429 | C10: 43.48687 | D10: -377.84572 | E10: 41.39451 | F10: -13.32677 | G10: NaN | H10: NaN | I10: NaN | J10: NaN
A11: 23347 | B11: 421.42857 | C11: 44.6969 | D11: -378.86302 | E11: 42.29642 | F11: -14.4508 | G11: NaN | H11: NaN | I11: NaN | J11: NaN
A12: 25839 | B12: 357.14286 | C12: 45.99206 | D12: -379.44428 | E12: 43.36894 | F12: -15.31029 | G12: NaN | H12: NaN | I12: NaN | J12: NaN
A13: 28555 | B13: 292.85714 | C13: 47.77543 | D13: -21.08672 | E13: 44.57624 | F13: -17.18867 | G13: NaN | H13: NaN | I13: NaN | J13: NaN
... A55: 301175 | B55: 0.1 | C55: 228.13376 | D55: 1.50299 | E55: 228.05527 | F55: 5.98374 | G55: NaN | H55: NaN | I55: NaN | J55: NaN

Sheet I20_P400_T70_HR50
A1: Temps (ms) | B1: Fr駲uence (Hz) | C1: Module de Z (mOhm) | D1: d駱hasage de Z (ｰ) | E1: Partie r馥lle | F1: Partie imaginaire | G1: Module de Zstack (mOhm) | H1: d駱hasage de Zstack (ｰ) | I1: Partie r馥lle stack | J1: Partie imaginaire stack
A2: 0 | B2: 1000 | C2: 38.668 | D2: -14.0722 | E2: 37.50758 | F2: -9.40191 | G2: NaN | H2: NaN | I2: NaN | J2: NaN
A3: 2017 | B3: 935.71429 | C3: 38.48932 | D3: -14.0994 | E3: 37.32981 | F3: -9.37618 | G3: NaN | H3: NaN | I3: NaN | J3: NaN
A4: 4432 | B4: 871.42857 | C4: 38.63892 | D4: -15.01363 | E4: 37.31995 | F4: -10.00937 | G4: NaN | H4: NaN | I4: NaN | J4: NaN
A5: 6509 | B5: 807.14286 | C5: 38.91003 | D5: -14.543 | E5: 37.66333 | F5: -9.77056 | G5: NaN | H5: NaN | I5: NaN | J5: NaN
A6: 8455 | B6: 742.85714 | C6: 40.11098 | D6: -374.93176 | E6: 38.75657 | F6: -10.33533 | G6: NaN | H6: NaN | I6: NaN | J6: NaN
A7: 10437 | B7: 678.57143 | C7: 40.41485 | D7: -375.63899 | E7: 38.91867 | F7: -10.89484 | G7: NaN | H7: NaN | I7: NaN | J7: NaN
A8: 12857 | B8: 614.28571 | C8: 40.74686 | D8: -376.41186 | E8: 39.08665 | F8: -11.51262 | G8: NaN | H8: NaN | I8: NaN | J8: NaN
A9: 14884 | B9: 550 | C9: 42.13086 | D9: -376.80409 | E9: 40.33183 | F9: -12.18004 | G9: NaN | H9: NaN | I9: NaN | J9: NaN
A10: 16896 | B10: 485.71429 | C10: 42.78192 | D10: -377.94505 | E10: 40.70069 | F10: -13.18131 | G10: NaN | H10: NaN | I10: NaN | J10: NaN
A11: 18751 | B11: 421.42857 | C11: 43.76522 | D11: -377.96996 | E11: 41.63028 | F11: -13.50237 | G11: NaN | H11: NaN | I11: NaN | J11: NaN
A12: 20832 | B12: 357.14286 | C12: 45.09537 | D12: -379.79962 | E12: 42.42946 | F12: -15.27523 | G12: NaN | H12: NaN | I12: NaN | J12: NaN
A13: 23328 | B13: 292.85714 | C13: 46.9779 | D13: -21.41544 | E13: 43.73443 | F13: -17.15293 | G13: NaN | H13: NaN | I13: NaN | J13: NaN
... A55: 287366 | B55: 0.1 | C55: 211.56966 | D55: 1.53325 | E55: 211.49391 | F55: 5.66097 | G55: NaN | H55: NaN | I55: NaN | J55: NaN

Sheet I20_P500_T70_HR50
A1: Temps (ms) | B1: Fr駲uence (Hz) | C1: Module de Z (mOhm) | D1: d駱hasage de Z (ｰ) | E1: Partie r馥lle | F1: Partie imaginaire | G1: Module de Zstack (mOhm) | H1: d駱hasage de Zstack (ｰ) | I1: Partie r馥lle stack | J1: Partie imaginaire stack
A2: 0 | B2: 1000 | C2: 37.53828 | D2: -14.59583 | E2: 36.32683 | F2: -9.4596 | G2: NaN | H2: NaN | I2: NaN | J2: NaN
A3: 1702 | B3: 935.71429 | C3: 37.98381 | D3: -14.55614 | E3: 36.7646 | F3: -9.54641 | G3: NaN | H3: NaN | I3: NaN | J3: NaN
A4: 3683 | B4: 871.42857 | C4: 38.67408 | D4: -15.45364 | E4: 37.27587 | F4: -10.30504 | G4: NaN | H4: NaN | I4: NaN | J4: NaN
A5: 5644 | B5: 807.14286 | C5: 39.3921 | D5: -14.35251 | E5: 38.16263 | F5: -9.76479 | G5: NaN | H5: NaN | I5: NaN | J5: NaN
A6: 7667 | B6: 742.85714 | C6: 40.09187 | D6: -375.36533 | E6: 38.65882 | F6: -10.62325 | G6: NaN | H6: NaN | I6: NaN | J6: NaN
A7: 9508 | B7: 678.57143 | C7: 39.69758 | D7: -375.15068 | E7: 38.31777 | F7: -10.37529 | G7: NaN | H7: NaN | I7: NaN | J7: NaN
A8: 11402 | B8: 614.28571 | C8: 40.70957 | D8: -375.96285 | E8: 39.13982 | F8: -11.1957 | G8: NaN | H8: NaN | I8: NaN | J8: NaN
A9: 13506 | B9: 550 | C9: 41.03135 | D9: -376.53367 | E9: 39.33481 | F9: -11.67665 | G9: NaN | H9: NaN | I9: NaN | J9: NaN
A10: 15374 | B10: 485.71429 | C10: 42.22821 | D10: -377.4912 | E10: 40.27571 | F10: -12.69208 | G10: NaN | H10: NaN | I10: NaN | J10: NaN
A11: 17289 | B11: 421.42857 | C11: 43.19782 | D11: -378.20239 | E11: 41.03615 | F11: -13.4939 | G11: NaN | H11: NaN | I11: NaN | J11: NaN
A12: 19250 | B12: 357.14286 | C12: 45.13651 | D12: -379.0321 | E12: 42.66917 | F12: -14.71891 | G12: NaN | H12: NaN | I12: NaN | J12: NaN
A13: 21232 | B13: 292.85714 | C13: 46.73581 | D13: -20.58921 | E13: 43.75059 | F13: -16.43537 | G13: NaN | H13: NaN | I13: NaN | J13: NaN
... A55: 275527 | B55: 0.1 | C55: 202.80506 | D55: 1.18267 | E55: 202.76186 | F55: 4.18591 | G55: NaN | H55: NaN | I55: NaN | J55: NaN

Sheet I30_P300_T70_HR50
A1: Temps (ms) | B1: Fr駲uence (Hz) | C1: Module de Z (mOhm) | D1: d駱hasage de Z (ｰ) | E1: Partie r馥lle | F1: Partie imaginaire | G1: Module de Zstack (mOhm) | H1: d駱hasage de Zstack (ｰ) | I1: Partie r馥lle stack | J1: Partie imaginaire stack
A2: 0 | B2: 1000 | C2: 40.32845 | D2: -15.11901 | E2: 38.93253 | F2: -10.51866 | G2: NaN | H2: NaN | I2: NaN | J2: NaN
A3: 2826 | B3: 935.71429 | C3: 40.8405 | D3: -15.81052 | E3: 39.29542 | F3: -11.12728 | G3: NaN | H3: NaN | I3: NaN | J3: NaN
A4: 5306 | B4: 871.42857 | C4: 41.75977 | D4: -15.50318 | E4: 40.24036 | F4: -11.16205 | G4: NaN | H4: NaN | I4: NaN | J4: NaN
A5: 7949 | B5: 807.14286 | C5: 41.62272 | D5: -15.49479 | E5: 40.10993 | F5: -11.11954 | G5: NaN | H5: NaN | I5: NaN | J5: NaN
A6: 10375 | B6: 742.85714 | C6: 42.41064 | D6: -376.26277 | E6: 40.71369 | F6: -11.8768 | G6: NaN | H6: NaN | I6: NaN | J6: NaN
A7: 13036 | B7: 678.57143 | C7: 43.1325 | D7: -376.93634 | E7: 41.2618 | F7: -12.56489 | G7: NaN | H7: NaN | I7: NaN | J7: NaN
A8: 15738 | B8: 614.28571 | C8: 44.21098 | D8: -377.39168 | E8: 42.18982 | F8: -13.21476 | G8: NaN | H8: NaN | I8: NaN | J8: NaN
A9: 18225 | B9: 550 | C9: 44.5948 | D9: -378.01094 | E9: 42.40955 | F9: -13.78865 | G9: NaN | H9: NaN | I9: NaN | J9: NaN
A10: 20904 | B10: 485.71429 | C10: 46.08516 | D10: -378.4102 | E10: 43.72652 | F10: -14.55452 | G10: NaN | H10: NaN | I10: NaN | J10: NaN
A11: 23398 | B11: 421.42857 | C11: 47.21335 | D11: -379.61146 | E11: 44.47452 | F11: -15.84668 | G11: NaN | H11: NaN | I11: NaN | J11: NaN
A12: 26135 | B12: 357.14286 | C12: 48.82033 | D12: -380.82919 | E12: 45.62966 | F12: -17.35969 | G12: NaN | H12: NaN | I12: NaN | J12: NaN
A13: 28685 | B13: 292.85714 | C13: 50.74184 | D13: -21.99976 | E13: 47.04709 | F13: -19.00803 | G13: NaN | H13: NaN | I13: NaN | J13: NaN
... A55: 305894 | B55: 0.1 | C55: 340.30609 | D55: 0.21442 | E55: 340.3037 | F55: 1.27353 | G55: NaN | H55: NaN | I55: NaN | J55: NaN

Sheet I30_P400_T70_HR50
A1: Temps (ms) | B1: Fr駲uence (Hz) | C1: Module de Z (mOhm) | D1: d駱hasage de Z (ｰ) | E1: Partie r馥lle | F1: Partie imaginaire | G1: Module de Zstack (mOhm) | H1: d駱hasage de Zstack (ｰ) | I1: Partie r馥lle stack | J1: Partie imaginaire stack
A2: 0 | B2: 1000 | C2: 39.68657 | D2: -15.01328 | E2: 38.3319 | F2: -10.28053 | G2: NaN | H2: NaN | I2: NaN | J2: NaN
A3: 2866 | B3: 935.71429 | C3: 40.35456 | D3: -15.22705 | E3: 38.93782 | F3: -10.59891 | G3: NaN | H3: NaN | I3: NaN | J3: NaN
A4: 5977 | B4: 871.42857 | C4: 41.46228 | D4: -15.20212 | E4: 40.01138 | F4: -10.87244 | G4: NaN | H4: NaN | I4: NaN | J4: NaN
A5: 8586 | B5: 807.14286 | C5: 41.60799 | D5: -16.253 | E5: 39.94513 | F5: -11.64522 | G5: NaN | H5: NaN | I5: NaN | J5: NaN
A6: 11241 | B6: 742.85714 | C6: 42.26392 | D6: -376.06825 | E6: 40.61278 | F6: -11.6979 | G6: NaN | H6: NaN | I6: NaN | J6: NaN
A7: 13756 | B7: 678.57143 | C7: 42.20918 | D7: -376.43765 | E7: 40.48401 | F7: -11.944 | G7: NaN | H7: NaN | I7: NaN | J7: NaN
A8: 16460 | B8: 614.28571 | C8: 42.88479 | D8: -377.19834 | E8: 40.96728 | F8: -12.68019 | G8: NaN | H8: NaN | I8: NaN | J8: NaN
A9: 18967 | B9: 550 | C9: 44.27332 | D9: -377.00297 | E9: 42.33812 | F9: -12.94646 | G9: NaN | H9: NaN | I9: NaN | J9: NaN
A10: 21684 | B10: 485.71429 | C10: 45.0046 | D10: -378.62301 | E10: 42.64818 | F10: -14.37176 | G10: NaN | H10: NaN | I10: NaN | J10: NaN
A11: 24809 | B11: 421.42857 | C11: 46.23633 | D11: -379.29455 | E11: 43.63934 | F11: -15.27762 | G11: NaN | H11: NaN | I11: NaN | J11: NaN
A12: 27363 | B12: 357.14286 | C12: 47.57762 | D12: -380.28092 | E12: 44.62802 | F12: -16.49151 | G12: NaN | H12: NaN | I12: NaN | J12: NaN
A13: 30153 | B13: 292.85714 | C13: 49.75522 | D13: -21.52651 | E13: 46.28469 | F13: -18.25677 | G13: NaN | H13: NaN | I13: NaN | J13: NaN
... A55: 318003 | B55: 0.1 | C55: 307.47867 | D55: 0.89759 | E55: 307.44094 | F55: 4.81675 | G55: NaN | H55: NaN | I55: NaN | J55: NaN

Sheet I30_P500_T70_HR50
A1: Temps (ms) | B1: Fr駲uence (Hz) | C1: Module de Z (mOhm) | D1: d駱hasage de Z (ｰ) | E1: Partie r馥lle | F1: Partie imaginaire | G1: Module de Zstack (mOhm) | H1: d駱hasage de Zstack (ｰ) | I1: Partie r馥lle stack | J1: Partie imaginaire stack
A2: 0 | B2: 1000 | C2: 39.07458 | D2: -15.71266 | E2: 37.61444 | F2: -10.58191 | G2: NaN | H2: NaN | I2: NaN | J2: NaN
A3: 11955 | B3: 935.71429 | C3: 39.41436 | D3: -15.18325 | E3: 38.03853 | F3: -10.3229 | G3: NaN | H3: NaN | I3: NaN | J3: NaN
A4: 14644 | B4: 871.42857 | C4: 39.82619 | D4: -15.6787 | E4: 38.34435 | F4: -10.76273 | G4: NaN | H4: NaN | I4: NaN | J4: NaN
A5: 17953 | B5: 807.14286 | C5: 40.38452 | D5: -16.47541 | E5: 38.72639 | F5: -11.45321 | G5: NaN | H5: NaN | I5: NaN | J5: NaN
A6: 21265 | B6: 742.85714 | C6: 41.54999 | D6: -375.38123 | E6: 40.06177 | F6: -11.02073 | G6: NaN | H6: NaN | I6: NaN | J6: NaN
A7: 24371 | B7: 678.57143 | C7: 41.56558 | D7: -376.34329 | E7: 39.88604 | F7: -11.69621 | G7: NaN | H7: NaN | I7: NaN | J7: NaN
A8: 27702 | B8: 614.28571 | C8: 42.65896 | D8: -376.82129 | E8: 40.83367 | F8: -12.34497 | G8: NaN | H8: NaN | I8: NaN | J8: NaN
A9: 30837 | B9: 550 | C9: 43.29283 | D9: -377.32944 | E9: 41.32768 | F9: -12.89543 | G9: NaN | H9: NaN | I9: NaN | J9: NaN
A10: 34140 | B10: 485.71429 | C10: 44.05158 | D10: -378.01392 | E10: 41.89223 | F10: -13.62287 | G10: NaN | H10: NaN | I10: NaN | J10: NaN
A11: 37483 | B11: 421.42857 | C11: 45.4497 | D11: -379.1097 | E11: 42.94513 | F11: -14.87923 | G11: NaN | H11: NaN | I11: NaN | J11: NaN
A12: 40623 | B12: 357.14286 | C12: 46.86959 | D12: -380.05512 | E12: 44.02757 | F12: -16.07271 | G12: NaN | H12: NaN | I12: NaN | J12: NaN
A13: 43990 | B13: 292.85714 | C13: 48.91009 | D13: -20.85985 | E13: 45.70424 | F13: -17.41607 | G13: NaN | H13: NaN | I13: NaN | J13: NaN
... A55: 337839 | B55: 0.1 | C55: 275.05437 | D55: 1.01667 | E55: 275.01107 | F55: 4.8804 | G55: NaN | H55: NaN | I55: NaN | J55: NaN

Sheet I35_P300_T70_HR50
A1: Temps (ms) | B1: Fr駲uence (Hz) | C1: Module de Z (mOhm) | D1: d駱hasage de Z (ｰ) | E1: Partie r馥lle | F1: Partie imaginaire | G1: Module de Zstack (mOhm) | H1: d駱hasage de Zstack (ｰ) | I1: Partie r馥lle stack | J1: Partie imaginaire stack
A2: 0 | B2: 1000 | C2: 40.82973 | D2: -14.92641 | E2: 39.45203 | F2: -10.51685 | G2: NaN | H2: NaN | I2: NaN | J2: NaN
A3: 3906 | B3: 935.71429 | C3: 41.87281 | D3: -15.09545 | E3: 40.42792 | F3: -10.90485 | G3: NaN | H3: NaN | I3: NaN | J3: NaN
A4: 7805 | B4: 871.42857 | C4: 42.41131 | D4: -16.25567 | E4: 40.7158 | F4: -11.87195 | G4: NaN | H4: NaN | I4: NaN | J4: NaN
A5: 11656 | B5: 807.14286 | C5: 43.06044 | D5: -17.17022 | E5: 41.14132 | F5: -12.71194 | G5: NaN | H5: NaN | I5: NaN | J5: NaN
A6: 15401 | B6: 742.85714 | C6: 43.78227 | D6: -376.54703 | E6: 41.96908 | F6: -12.46929 | G6: NaN | H6: NaN | I6: NaN | J6: NaN
A7: 18714 | B7: 678.57143 | C7: 44.01242 | D7: -377.01805 | E7: 42.08523 | F7: -12.88124 | G7: NaN | H7: NaN | I7: NaN | J7: NaN
A8: 22656 | B8: 614.28571 | C8: 45.36949 | D8: -377.69504 | E8: 43.22296 | F8: -13.79008 | G8: NaN | H8: NaN | I8: NaN | J8: NaN
A9: 26592 | B9: 550 | C9: 45.90296 | D9: -378.46938 | E9: 43.53864 | F9: -14.54196 | G9: NaN | H9: NaN | I9: NaN | J9: NaN
A10: 30500 | B10: 485.71429 | C10: 47.01293 | D10: -379.1681 | E10: 44.4065 | F10: -15.43626 | G10: NaN | H10: NaN | I10: NaN | J10: NaN
A11: 34475 | B11: 421.42857 | C11: 48.55917 | D11: -380.42926 | E11: 45.50499 | F11: -16.94961 | G11: NaN | H11: NaN | I11: NaN | J11: NaN
A12: 38260 | B12: 357.14286 | C12: 49.96934 | D12: -381.14694 | E12: 46.60432 | F12: -18.02699 | G12: NaN | H12: NaN | I12: NaN | J12: NaN
A13: 42075 | B13: 292.85714 | C13: 52.07386 | D13: -22.87979 | E13: 47.97682 | F13: -20.24627 | G13: NaN | H13: NaN | I13: NaN | J13: NaN
... A55: 357598 | B55: 0.1 | C55: 443.59423 | D55: 0.76838 | E55: 443.55434 | F55: 5.94873 | G55: NaN | H55: NaN | I55: NaN | J55: NaN

Sheet I35_P400_T70_HR50
A1: Temps (ms) | B1: Fr駲uence (Hz) | C1: Module de Z (mOhm) | D1: d駱hasage de Z (ｰ) | E1: Partie r馥lle | F1: Partie imaginaire | G1: Module de Zstack (mOhm) | H1: d駱hasage de Zstack (ｰ) | I1: Partie r馥lle stack | J1: Partie imaginaire stack
A2: 0 | B2: 1000 | C2: 40.2999 | D2: -14.73597 | E2: 38.97437 | F2: -10.25089 | G2: NaN | H2: NaN | I2: NaN | J2: NaN
A3: 3271 | B3: 935.71429 | C3: 41.05232 | D3: -15.87881 | E3: 39.48587 | F3: -11.23206 | G3: NaN | H3: NaN | I3: NaN | J3: NaN
A4: 6384 | B4: 871.42857 | C4: 41.4644 | D4: -15.43345 | E4: 39.9692 | F4: -11.03446 | G4: NaN | H4: NaN | I4: NaN | J4: NaN
A5: 9661 | B5: 807.14286 | C5: 41.51898 | D5: -15.90559 | E5: 39.92941 | F5: -11.3784 | G5: NaN | H5: NaN | I5: NaN | J5: NaN
A6: 12952 | B6: 742.85714 | C6: 42.33514 | D6: -377.12214 | E6: 40.45882 | F6: -12.46387 | G6: NaN | H6: NaN | I6: NaN | J6: NaN
A7: 16272 | B7: 678.57143 | C7: 42.99399 | D7: -377.14425 | E7: 41.08358 | F7: -12.6737 | G7: NaN | H7: NaN | I7: NaN | J7: NaN
A8: 19385 | B8: 614.28571 | C8: 43.7305 | D8: -377.3547 | E8: 41.73973 | F8: -13.04421 | G8: NaN | H8: NaN | I8: NaN | J8: NaN
A9: 22716 | B9: 550 | C9: 44.6631 | D9: -378.12989 | E9: 42.44573 | F9: -13.89792 | G9: NaN | H9: NaN | I9: NaN | J9: NaN
A10: 26030 | B10: 485.71429 | C10: 45.38552 | D10: -378.94315 | E10: 42.92749 | F10: -14.7335 | G10: NaN | H10: NaN | I10: NaN | J10: NaN
A11: 29192 | B11: 421.42857 | C11: 47.18573 | D11: -379.27941 | E11: 44.53954 | F11: -15.57956 | G11: NaN | H11: NaN | I11: NaN | J11: NaN
A12: 32544 | B12: 357.14286 | C12: 48.49046 | D12: -380.74786 | E12: 45.34578 | F12: -17.17804 | G12: NaN | H12: NaN | I12: NaN | J12: NaN
A13: 36329 | B13: 292.85714 | C13: 50.39954 | D13: -22.38365 | E13: 46.60217 | F13: -19.19247 | G13: NaN | H13: NaN | I13: NaN | J13: NaN
... A55: 345338 | B55: 0.1 | C55: 393.03614 | D55: 1.41786 | E55: 392.91581 | F55: 9.72518 | G55: NaN | H55: NaN | I55: NaN | J55: NaN

Sheet I35_P500_T70_HR50
A1: Temps (ms) | B1: Fr駲uence (Hz) | C1: Module de Z (mOhm) | D1: d駱hasage de Z (ｰ) | E1: Partie r馥lle | F1: Partie imaginaire | G1: Module de Zstack (mOhm) | H1: d駱hasage de Zstack (ｰ) | I1: Partie r馥lle stack | J1: Partie imaginaire stack
A2: 0 | B2: 1000 | C2: 38.91331 | D2: -15.34772 | E2: 37.52556 | F2: -10.29943 | G2: NaN | H2: NaN | I2: NaN | J2: NaN
A3: 3111 | B3: 935.71429 | C3: 40.57277 | D3: -14.84271 | E3: 39.21897 | F3: -10.39338 | G3: NaN | H3: NaN | I3: NaN | J3: NaN
A4: 6411 | B4: 871.42857 | C4: 41.02715 | D4: -15.46165 | E4: 39.54234 | F4: -10.93757 | G4: NaN | H4: NaN | I4: NaN | J4: NaN
A5: 9707 | B5: 807.14286 | C5: 41.28043 | D5: -16.22985 | E5: 39.63533 | F5: -11.53752 | G5: NaN | H5: NaN | I5: NaN | J5: NaN
A6: 12799 | B6: 742.85714 | C6: 41.85234 | D6: -375.84192 | E6: 40.26273 | F6: -11.42503 | G6: NaN | H6: NaN | I6: NaN | J6: NaN
A7: 16090 | B7: 678.57143 | C7: 42.67913 | D7: -376.56256 | E7: 40.90833 | F7: -12.1662 | G7: NaN | H7: NaN | I7: NaN | J7: NaN
A8: 19446 | B8: 614.28571 | C8: 43.17681 | D8: -376.71443 | E8: 41.3526 | F8: -12.41772 | G8: NaN | H8: NaN | I8: NaN | J8: NaN
A9: 22602 | B9: 550 | C9: 44.02198 | D9: -377.69454 | E9: 41.93932 | F9: -13.38014 | G9: NaN | H9: NaN | I9: NaN | J9: NaN
A10: 25942 | B10: 485.71429 | C10: 44.60901 | D10: -378.7469 | E10: 42.24239 | F10: -14.33681 | G10: NaN | H10: NaN | I10: NaN | J10: NaN
A11: 29494 | B11: 421.42857 | C11: 46.44838 | D11: -379.34252 | E11: 43.82662 | F11: -15.38438 | G11: NaN | H11: NaN | I11: NaN | J11: NaN
A12: 33048 | B12: 357.14286 | C12: 47.65423 | D12: -380.5155 | E12: 44.63187 | F12: -16.70094 | G12: NaN | H12: NaN | I12: NaN | J12: NaN
A13: 36228 | B13: 292.85714 | C13: 49.68642 | D13: -21.93634 | E13: 46.0891 | F13: -18.56167 | G13: NaN | H13: NaN | I13: NaN | J13: NaN
... A55: 335468 | B55: 0.1 | C55: 356.84685 | D55: 1.08801 | E55: 356.78251 | F55: 6.77591 | G55: NaN | H55: NaN | I55: NaN | J55: NaN

Sheet I40_P300_T70_HR50
A1: Temps (ms) | B1: Fr駲uence (Hz) | C1: Module de Z (mOhm) | D1: d駱hasage de Z (ｰ) | E1: Partie r馥lle | F1: Partie imaginaire | G1: Module de Zstack (mOhm) | H1: d駱hasage de Zstack (ｰ) | I1: Partie r馥lle stack | J1: Partie imaginaire stack
A2: 0 | B2: 1000 | C2: 43.30956 | D2: -15.79057 | E2: 41.67517 | F2: -11.78548 | G2: NaN | H2: NaN | I2: NaN | J2: NaN
A3: 3725 | B3: 935.71429 | C3: 43.52217 | D3: -16.20682 | E3: 41.79262 | F3: -12.14727 | G3: NaN | H3: NaN | I3: NaN | J3: NaN
A4: 7770 | B4: 871.42857 | C4: 44.10679 | D4: -16.73475 | E4: 42.23878 | F4: -12.70017 | G4: NaN | H4: NaN | I4: NaN | J4: NaN
A5: 11653 | B5: 807.14286 | C5: 44.86258 | D5: -16.30472 | E5: 43.05831 | F5: -12.59498 | G5: NaN | H5: NaN | I5: NaN | J5: NaN
A6: 15403 | B6: 742.85714 | C6: 45.27287 | D6: -376.91623 | E6: 43.31397 | F6: -13.17319 | G6: NaN | H6: NaN | I6: NaN | J6: NaN
A7: 19358 | B7: 678.57143 | C7: 45.76772 | D7: -377.72797 | E7: 43.59434 | F7: -13.93618 | G7: NaN | H7: NaN | I7: NaN | J7: NaN
A8: 23367 | B8: 614.28571 | C8: 47.13122 | D8: -378.70162 | E8: 44.64275 | F8: -15.11215 | G8: NaN | H8: NaN | I8: NaN | J8: NaN
A9: 27122 | B9: 550 | C9: 47.70556 | D9: -379.29726 | E9: 45.02531 | F9: -15.76522 | G9: NaN | H9: NaN | I9: NaN | J9: NaN
A10: 31077 | B10: 485.71429 | C10: 49.00299 | D10: -379.82236 | E10: 46.09949 | F10: -16.61717 | G10: NaN | H10: NaN | I10: NaN | J10: NaN
A11: 34861 | B11: 421.42857 | C11: 50.48569 | D11: -380.58265 | E11: 47.26299 | F11: -17.74865 | G11: NaN | H11: NaN | I11: NaN | J11: NaN
A12: 38859 | B12: 357.14286 | C12: 52.11222 | D12: -381.96801 | E12: 48.3285 | F12: -19.4946 | G12: NaN | H12: NaN | I12: NaN | J12: NaN
A13: 42870 | B13: 292.85714 | C13: 54.23343 | D13: -23.46358 | E13: 49.74905 | F13: -21.59391 | G13: NaN | H13: NaN | I13: NaN | J13: NaN
... A55: 365403 | B55: 0.1 | C55: 628.89113 | D55: 1.38948 | E55: 628.70621 | F55: 15.24975 | G55: NaN | H55: NaN | I55: NaN | J55: NaN

Sheet I40_P400_T70_HR50
A1: Temps (ms) | B1: Fr駲uence (Hz) | C1: Module de Z (mOhm) | D1: d駱hasage de Z (ｰ) | E1: Partie r馥lle | F1: Partie imaginaire | G1: Module de Zstack (mOhm) | H1: d駱hasage de Zstack (ｰ) | I1: Partie r馥lle stack | J1: Partie imaginaire stack
A2: 0 | B2: 1000 | C2: 42.2837 | D2: -15.09494 | E2: 40.82473 | F2: -11.01149 | G2: NaN | H2: NaN | I2: NaN | J2: NaN
A3: 4125 | B3: 935.71429 | C3: 42.79623 | D3: -16.42467 | E3: 41.04982 | F3: -12.10083 | G3: NaN | H3: NaN | I3: NaN | J3: NaN
A4: 8075 | B4: 871.42857 | C4: 43.21346 | D4: -16.23782 | E4: 41.48964 | F4: -12.08356 | G4: NaN | H4: NaN | I4: NaN | J4: NaN
A5: 11955 | B5: 807.14286 | C5: 43.72329 | D5: -17.00772 | E5: 41.81107 | F5: -12.78909 | G5: NaN | H5: NaN | I5: NaN | J5: NaN
A6: 15911 | B6: 742.85714 | C6: 44.20046 | D6: -376.80008 | E6: 42.31395 | F6: -12.7754 | G6: NaN | H6: NaN | I6: NaN | J6: NaN
A7: 19845 | B7: 678.57143 | C7: 45.19416 | D7: -377.60052 | E7: 43.07853 | F7: -13.66574 | G7: NaN | H7: NaN | I7: NaN | J7: NaN
A8: 24423 | B8: 614.28571 | C8: 45.61542 | D8: -378.12672 | E8: 43.35156 | F8: -14.19185 | G8: NaN | H8: NaN | I8: NaN | J8: NaN
A9: 28200 | B9: 550 | C9: 46.83109 | D9: -379.07954 | E9: 44.25846 | F9: -15.30817 | G9: NaN | H9: NaN | I9: NaN | J9: NaN
A10: 32159 | B10: 485.71429 | C10: 47.79778 | D10: -379.30229 | E10: 45.11096 | F10: -15.79965 | G10: NaN | H10: NaN | I10: NaN | J10: NaN
A11: 35962 | B11: 421.42857 | C11: 49.23301 | D11: -380.52646 | E11: 46.10723 | F11: -17.26306 | G11: NaN | H11: NaN | I11: NaN | J11: NaN
A12: 39944 | B12: 357.14286 | C12: 50.71172 | D12: -381.68531 | E12: 47.12272 | F12: -18.73841 | G12: NaN | H12: NaN | I12: NaN | J12: NaN
A13: 43752 | B13: 292.85714 | C13: 53.0774 | D13: -23.0796 | E13: 48.82914 | F13: -20.80685 | G13: NaN | H13: NaN | I13: NaN | J13: NaN
... A55: 376160 | B55: 0.1 | C55: 531.05561 | D55: 1.336 | E55: 530.91124 | F55: 12.38179 | G55: NaN | H55: NaN | I55: NaN | J55: NaN

Sheet I40_P500_T70_HR50
A1: Temps (ms) | B1: Fr駲uence (Hz) | C1: Module de Z (mOhm) | D1: d駱hasage de Z (ｰ) | E1: Partie r馥lle | F1: Partie imaginaire | G1: Module de Zstack (mOhm) | H1: d駱hasage de Zstack (ｰ) | I1: Partie r馥lle stack | J1: Partie imaginaire stack
A2: 0 | B2: 1000 | C2: 40.56959 | D2: -15.63763 | E2: 39.06794 | F2: -10.93563 | G2: NaN | H2: NaN | I2: NaN | J2: NaN
A3: 4490 | B3: 935.71429 | C3: 41.37911 | D3: -16.29512 | E3: 39.71688 | F3: -11.61036 | G3: NaN | H3: NaN | I3: NaN | J3: NaN
A4: 9034 | B4: 871.42857 | C4: 41.88561 | D4: -16.09006 | E4: 40.24484 | F4: -11.60851 | G4: NaN | H4: NaN | I4: NaN | J4: NaN
A5: 13533 | B5: 807.14286 | C5: 42.27631 | D5: -17.35527 | E5: 40.35162 | F5: -12.61085 | G5: NaN | H5: NaN | I5: NaN | J5: NaN
A6: 18036 | B6: 742.85714 | C6: 43.04313 | D6: -377.19772 | E6: 41.11868 | F6: -12.72656 | G6: NaN | H6: NaN | I6: NaN | J6: NaN
A7: 22592 | B7: 678.57143 | C7: 43.76322 | D7: -377.25678 | E7: 41.79321 | F7: -12.98256 | G7: NaN | H7: NaN | I7: NaN | J7: NaN
A8: 27143 | B8: 614.28571 | C8: 44.42687 | D8: -377.53717 | E8: 42.36198 | F8: -13.3869 | G8: NaN | H8: NaN | I8: NaN | J8: NaN
A9: 31726 | B9: 550 | C9: 45.50424 | D9: -378.52755 | E9: 43.1458 | F9: -14.45946 | G9: NaN | H9: NaN | I9: NaN | J9: NaN
A10: 36285 | B10: 485.71429 | C10: 46.19759 | D10: -379.01571 | E10: 43.67656 | F10: -15.05244 | G10: NaN | H10: NaN | I10: NaN | J10: NaN
A11: 40869 | B11: 421.42857 | C11: 47.60598 | D11: -380.08651 | E11: 44.71035 | F11: -16.34973 | G11: NaN | H11: NaN | I11: NaN | J11: NaN
A12: 45511 | B12: 357.14286 | C12: 49.46487 | D12: -380.82157 | E12: 46.23442 | F12: -17.58272 | G12: NaN | H12: NaN | I12: NaN | J12: NaN
A13: 49954 | B13: 292.85714 | C13: 51.47889 | D13: -22.39412 | E13: 47.59662 | F13: -19.61219 | G13: NaN | H13: NaN | I13: NaN | J13: NaN
... A55: 386160 | B55: 0.1 | C55: 431.24998 | D55: 1.18373 | E55: 431.15794 | F55: 8.90899 | G55: NaN | H55: NaN | I55: NaN | J55: NaN

Sheet I45_P300_T70_HR50
A1: Temps (ms) | B1: Fr駲uence (Hz) | C1: Module de Z (mOhm) | D1: d駱hasage de Z (ｰ) | E1: Partie r馥lle | F1: Partie imaginaire | G1: Module de Zstack (mOhm) | H1: d駱hasage de Zstack (ｰ) | I1: Partie r馥lle stack | J1: Partie imaginaire stack
A2: 0 | B2: 1000 | C2: 44.58968 | D2: -16.37984 | E2: 42.77993 | F2: -12.57447 | G2: NaN | H2: NaN | I2: NaN | J2: NaN
A3: 4717 | B3: 935.71429 | C3: 44.98716 | D3: -15.83118 | E3: 43.28078 | F3: -12.27267 | G3: NaN | H3: NaN | I3: NaN | J3: NaN
A4: 9953 | B4: 871.42857 | C4: 45.77989 | D4: -16.36774 | E4: 43.92456 | F4: -12.90083 | G4: NaN | H4: NaN | I4: NaN | J4: NaN
A5: 15098 | B5: 807.14286 | C5: 46.02033 | D5: -16.59059 | E5: 44.10448 | F5: -13.14023 | G5: NaN | H5: NaN | I5: NaN | J5: NaN
A6: 20294 | B6: 742.85714 | C6: 46.82121 | D6: -377.27701 | E6: 44.70864 | F6: -13.90551 | G6: NaN | H6: NaN | I6: NaN | J6: NaN
A7: 25488 | B7: 678.57143 | C7: 47.35993 | D7: -377.61018 | E7: 45.1405 | F7: -14.32824 | G7: NaN | H7: NaN | I7: NaN | J7: NaN
A8: 30697 | B8: 614.28571 | C8: 48.17708 | D8: -378.33587 | E8: 45.73107 | F8: -15.15587 | G8: NaN | H8: NaN | I8: NaN | J8: NaN
A9: 35888 | B9: 550 | C9: 49.95982 | D9: -378.75657 | E9: 47.30661 | F9: -16.06449 | G9: NaN | H9: NaN | I9: NaN | J9: NaN
A10: 41069 | B10: 485.71429 | C10: 51.34225 | D10: -380.05181 | E10: 48.23004 | F10: -17.6037 | G10: NaN | H10: NaN | I10: NaN | J10: NaN
A11: 46263 | B11: 421.42857 | C11: 52.7514 | D11: -380.65837 | E11: 49.35952 | F11: -18.61044 | G11: NaN | H11: NaN | I11: NaN | J11: NaN
A12: 51467 | B12: 357.14286 | C12: 54.78995 | D12: -382.11846 | E12: 50.75781 | F12: -20.62966 | G12: NaN | H12: NaN | I12: NaN | J12: NaN
A13: 56677 | B13: 292.85714 | C13: 57.13641 | D13: -23.90599 | E13: 52.23477 | F13: -23.1538 | G13: NaN | H13: NaN | I13: NaN | J13: NaN
... A55: 413887 | B55: 0.1 | C55: 994.12585 | D55: 1.31229 | E55: 993.86511 | F55: 22.7673 | G55: NaN | H55: NaN | I55: NaN | J55: NaN

Sheet I45_P400_T70_HR50
A1: Temps (ms) | B1: Fr駲uence (Hz) | C1: Module de Z (mOhm) | D1: d駱hasage de Z (ｰ) | E1: Partie r馥lle | F1: Partie imaginaire | G1: Module de Zstack (mOhm) | H1: d駱hasage de Zstack (ｰ) | I1: Partie r馥lle stack | J1: Partie imaginaire stack
A2: 0 | B2: 1000 | C2: 42.57494 | D2: -15.23188 | E2: 41.0793 | F2: -11.18555 | G2: NaN | H2: NaN | I2: NaN | J2: NaN
A3: 4905 | B3: 935.71429 | C3: 43.67005 | D3: -16.04961 | E3: 41.96791 | F3: -12.07344 | G3: NaN | H3: NaN | I3: NaN | J3: NaN
A4: 9445 | B4: 871.42857 | C4: 44.08816 | D4: -16.05381 | E4: 42.36883 | F4: -12.19214 | G4: NaN | H4: NaN | I4: NaN | J4: NaN
A5: 13798 | B5: 807.14286 | C5: 44.67429 | D5: -16.81925 | E5: 42.76323 | F5: -12.92666 | G5: NaN | H5: NaN | I5: NaN | J5: NaN
A6: 18565 | B6: 742.85714 | C6: 45.17005 | D6: -377.44213 | E6: 43.09314 | F6: -13.53938 | G6: NaN | H6: NaN | I6: NaN | J6: NaN
A7: 22931 | B7: 678.57143 | C7: 45.95611 | D7: -377.70356 | E7: 43.77974 | F7: -13.97489 | G7: NaN | H7: NaN | I7: NaN | J7: NaN
A8: 27512 | B8: 614.28571 | C8: 46.66124 | D8: -377.73749 | E8: 44.44307 | F8: -14.21564 | G8: NaN | H8: NaN | I8: NaN | J8: NaN
A9: 32134 | B9: 550 | C9: 47.41015 | D9: -378.72677 | E9: 44.90027 | F9: -15.22129 | G9: NaN | H9: NaN | I9: NaN | J9: NaN
A10: 36702 | B10: 485.71429 | C10: 48.67862 | D10: -379.64765 | E10: 45.84446 | F10: -16.36745 | G10: NaN | H10: NaN | I10: NaN | J10: NaN
A11: 41282 | B11: 421.42857 | C11: 50.09705 | D11: -380.53163 | E11: 46.91482 | F11: -17.57025 | G11: NaN | H11: NaN | I11: NaN | J11: NaN
A12: 45688 | B12: 357.14286 | C12: 51.67861 | D12: -381.74669 | E12: 48.00069 | F12: -19.14712 | G12: NaN | H12: NaN | I12: NaN | J12: NaN
A13: 50325 | B13: 292.85714 | C13: 53.69855 | D13: -23.51233 | E13: 49.24019 | F13: -21.42284 | G13: NaN | H13: NaN | I13: NaN | J13: NaN
... A55: 400930 | B55: 0.1 | C55: 777.28248 | D55: 1.10674 | E55: 777.13748 | F55: 15.01327 | G55: NaN | H55: NaN | I55: NaN | J55: NaN

Sheet I45_P500_T70_HR50
A1: Temps (ms) | B1: Fr駲uence (Hz) | C1: Module de Z (mOhm) | D1: d駱hasage de Z (ｰ) | E1: Partie r馥lle | F1: Partie imaginaire | G1: Module de Zstack (mOhm) | H1: d駱hasage de Zstack (ｰ) | I1: Partie r馥lle stack | J1: Partie imaginaire stack
A2: 0 | B2: 1000 | C2: 42.07124 | D2: -15.44224 | E2: 40.55245 | F2: -11.20217 | G2: NaN | H2: NaN | I2: NaN | J2: NaN
A3: 4903 | B3: 935.71429 | C3: 41.82736 | D3: -15.69447 | E3: 40.26795 | F3: -11.31462 | G3: NaN | H3: NaN | I3: NaN | J3: NaN
A4: 9676 | B4: 871.42857 | C4: 42.41456 | D4: -16.02537 | E4: 40.76631 | F4: -11.70909 | G4: NaN | H4: NaN | I4: NaN | J4: NaN
A5: 14216 | B5: 807.14286 | C5: 43.05796 | D5: -16.7427 | E5: 41.23265 | F5: -12.40389 | G5: NaN | H5: NaN | I5: NaN | J5: NaN
A6: 18789 | B6: 742.85714 | C6: 43.45846 | D6: -376.67079 | E6: 41.63185 | F6: -12.46702 | G6: NaN | H6: NaN | I6: NaN | J6: NaN
A7: 23402 | B7: 678.57143 | C7: 44.33558 | D7: -377.05801 | E7: 42.38518 | F7: -13.00539 | G7: NaN | H7: NaN | I7: NaN | J7: NaN
A8: 28007 | B8: 614.28571 | C8: 45.21422 | D8: -377.87454 | E8: 43.03177 | F8: -13.87777 | G8: NaN | H8: NaN | I8: NaN | J8: NaN
A9: 32397 | B9: 550 | C9: 46.21083 | D9: -378.59018 | E9: 43.79969 | F9: -14.73187 | G9: NaN | H9: NaN | I9: NaN | J9: NaN
A10: 36972 | B10: 485.71429 | C10: 47.00703 | D10: -379.35767 | E10: 44.34962 | F10: -15.58114 | G10: NaN | H10: NaN | I10: NaN | J10: NaN
A11: 41603 | B11: 421.42857 | C11: 48.25501 | D11: -380.32882 | E11: 45.24942 | F11: -16.76414 | G11: NaN | H11: NaN | I11: NaN | J11: NaN
A12: 46819 | B12: 357.14286 | C12: 49.82143 | D12: -381.37924 | E12: 46.39312 | F12: -18.16187 | G12: NaN | H12: NaN | I12: NaN | J12: NaN
A13: 51312 | B13: 292.85714 | C13: 51.87177 | D13: -22.98415 | E13: 47.75382 | F13: -20.25471 | G13: NaN | H13: NaN | I13: NaN | J13: NaN
... A55: 393580 | B55: 0.1 | C55: 631.0643 | D55: 1.0396 | E55: 630.96042 | F55: 11.44974 | G55: NaN | H55: NaN | I55: NaN | J55: NaN

Sheet I50_P300_T70_HR50
A1: Temps (ms) | B1: Fr駲uence (Hz) | C1: Module de Z (mOhm) | D1: d駱hasage de Z (ｰ) | E1: Partie r馥lle | F1: Partie imaginaire | G1: Module de Zstack (mOhm) | H1: d駱hasage de Zstack (ｰ) | I1: Partie r馥lle stack | J1: Partie imaginaire stack
A2: 0 | B2: 1000 | C2: 49.02431 | D2: -17.47462 | E2: 46.76184 | F2: -14.72118 | G2: NaN | H2: NaN | I2: NaN | J2: NaN
A3: 5134 | B3: 935.71429 | C3: 49.59112 | D3: -17.14559 | E3: 47.38723 | F3: -14.6195 | G3: NaN | H3: NaN | I3: NaN | J3: NaN
A4: 10313 | B4: 871.42857 | C4: 50.62869 | D4: -17.74092 | E4: 48.221 | F4: -15.42724 | G4: NaN | H4: NaN | I4: NaN | J4: NaN
A5: 15469 | B5: 807.14286 | C5: 51.15345 | D5: -18.27272 | E5: 48.57403 | F5: -16.03867 | G5: NaN | H5: NaN | I5: NaN | J5: NaN
A6: 20655 | B6: 742.85714 | C6: 52.25089 | D6: -378.34157 | E6: 49.59641 | F6: -16.44238 | G6: NaN | H6: NaN | I6: NaN | J6: NaN
A7: 25854 | B7: 678.57143 | C7: 52.9651 | D7: -378.94184 | E7: 50.09696 | F7: -17.19291 | G7: NaN | H7: NaN | I7: NaN | J7: NaN
A8: 31062 | B8: 614.28571 | C8: 53.95335 | D8: -379.40694 | E8: 50.88785 | F8: -17.92737 | G8: NaN | H8: NaN | I8: NaN | J8: NaN
A9: 36275 | B9: 550 | C9: 55.31745 | D9: -379.75277 | E9: 52.06255 | F9: -18.69521 | G9: NaN | H9: NaN | I9: NaN | J9: NaN
A10: 41463 | B10: 485.71429 | C10: 56.71081 | D10: -380.75218 | E10: 53.03151 | F10: -20.09415 | G10: NaN | H10: NaN | I10: NaN | J10: NaN
A11: 46670 | B11: 421.42857 | C11: 58.10183 | D11: -381.53713 | E11: 54.04515 | F11: -21.32942 | G11: NaN | H11: NaN | I11: NaN | J11: NaN
A12: 51912 | B12: 357.14286 | C12: 60.27236 | D12: -382.6141 | E12: 55.63836 | F12: -23.17608 | G12: NaN | H12: NaN | I12: NaN | J12: NaN
A13: 56990 | B13: 292.85714 | C13: 62.7311 | D13: -24.23099 | E13: 57.20438 | F13: -25.74587 | G13: NaN | H13: NaN | I13: NaN | J13: NaN
... A49: 278201 | B49: 0.4 | C49: 186.32613 | D49: 35.96182 | E49: 150.81396 | F49: 109.41927 | G49: NaN | H49: NaN | I49: NaN | J49: NaN

Sheet I50_P400_T70_HR50
A1: Temps (ms) | B1: Fr駲uence (Hz) | C1: Module de Z (mOhm) | D1: d駱hasage de Z (ｰ) | E1: Partie r馥lle | F1: Partie imaginaire | G1: Module de Zstack (mOhm) | H1: d駱hasage de Zstack (ｰ) | I1: Partie r馥lle stack | J1: Partie imaginaire stack
A2: 0 | B2: 1000 | C2: 48.60859 | D2: -17.60351 | E2: 46.33235 | F2: -14.70061 | G2: NaN | H2: NaN | I2: NaN | J2: NaN
A3: 5146 | B3: 935.71429 | C3: 49.4897 | D3: -17.49248 | E3: 47.20112 | F3: -14.87564 | G3: NaN | H3: NaN | I3: NaN | J3: NaN
A4: 10439 | B4: 871.42857 | C4: 49.87124 | D4: -18.41898 | E4: 47.31641 | F4: -15.75748 | G4: NaN | H4: NaN | I4: NaN | J4: NaN
A5: 15588 | B5: 807.14286 | C5: 50.88883 | D5: -18.79462 | E5: 48.17541 | F5: -16.3952 | G5: NaN | H5: NaN | I5: NaN | J5: NaN
A6: 20769 | B6: 742.85714 | C6: 51.47645 | D6: -378.95683 | E6: 48.68455 | F6: -16.72241 | G6: NaN | H6: NaN | I6: NaN | J6: NaN
A7: 26003 | B7: 678.57143 | C7: 52.4695 | D7: -379.58991 | E7: 49.43239 | F7: -17.59227 | G7: NaN | H7: NaN | I7: NaN | J7: NaN
A8: 31201 | B8: 614.28571 | C8: 53.67206 | D8: -380.07992 | E8: 50.40958 | F8: -18.42726 | G8: NaN | H8: NaN | I8: NaN | J8: NaN
A9: 36416 | B9: 550 | C9: 54.72394 | D9: -380.62882 | E9: 51.21517 | F9: -19.27993 | G9: NaN | H9: NaN | I9: NaN | J9: NaN
A10: 41607 | B10: 485.71429 | C10: 55.95358 | D10: -381.26246 | E10: 52.14476 | F10: -20.29105 | G10: NaN | H10: NaN | I10: NaN | J10: NaN
A11: 46778 | B11: 421.42857 | C11: 57.69405 | D11: -382.26303 | E11: 53.39321 | F11: -21.85792 | G11: NaN | H11: NaN | I11: NaN | J11: NaN
A12: 51995 | B12: 357.14286 | C12: 59.72304 | D12: -383.02226 | E12: 54.96627 | F12: -23.35701 | G12: NaN | H12: NaN | I12: NaN | J12: NaN
A13: 57251 | B13: 292.85714 | C13: 62.27962 | D13: -24.56764 | E13: 56.64151 | F13: -25.89382 | G13: NaN | H13: NaN | I13: NaN | J13: NaN
... A55: 425323 | B55: 0.1 | C55: 1428.7607 | D55: -0.70164 | E55: 1428.6535 | F55: -17.49611 | G55: NaN | H55: NaN | I55: NaN | J55: NaN

Sheet I50_P500_T70_HR50
A1: Temps (ms) | B1: Fr駲uence (Hz) | C1: Module de Z (mOhm) | D1: d駱hasage de Z (ｰ) | E1: Partie r馥lle | F1: Partie imaginaire | G1: Module de Zstack (mOhm) | H1: d駱hasage de Zstack (ｰ) | I1: Partie r馥lle stack | J1: Partie imaginaire stack
A2: 0 | B2: 1000 | C2: 44.7423 | D2: -16.99973 | E2: 42.78734 | F2: -13.08118 | G2: NaN | H2: NaN | I2: NaN | J2: NaN
A3: 5501 | B3: 935.71429 | C3: 45.38188 | D3: -17.08721 | E3: 43.37867 | F3: -13.33442 | G3: NaN | H3: NaN | I3: NaN | J3: NaN
A4: 11285 | B4: 871.42857 | C4: 46.6148 | D4: -17.32158 | E4: 44.50076 | F4: -13.87883 | G4: NaN | H4: NaN | I4: NaN | J4: NaN
A5: 17034 | B5: 807.14286 | C5: 46.46807 | D5: -17.67193 | E5: 44.27525 | F5: -14.10614 | G5: NaN | H5: NaN | I5: NaN | J5: NaN
A6: 22258 | B6: 742.85714 | C6: 47.17929 | D6: -378.04318 | E6: 44.85918 | F6: -14.61301 | G6: NaN | H6: NaN | I6: NaN | J6: NaN
A7: 27449 | B7: 678.57143 | C7: 48.09581 | D7: -378.15248 | E7: 45.70212 | F7: -14.9841 | G7: NaN | H7: NaN | I7: NaN | J7: NaN
A8: 32642 | B8: 614.28571 | C8: 49.32949 | D8: -378.87585 | E8: 46.67664 | F8: -15.95901 | G8: NaN | H8: NaN | I8: NaN | J8: NaN
A9: 38057 | B9: 550 | C9: 50.44773 | D9: -379.49854 | E9: 47.55455 | F9: -16.83859 | G9: NaN | H9: NaN | I9: NaN | J9: NaN
A10: 43862 | B10: 485.71429 | C10: 51.47541 | D10: -380.47137 | E10: 48.22459 | F10: -18.00297 | G10: NaN | H10: NaN | I10: NaN | J10: NaN
A11: 49681 | B11: 421.42857 | C11: 53.24239 | D11: -381.14263 | E11: 49.6584 | F11: -19.20404 | G11: NaN | H11: NaN | I11: NaN | J11: NaN
A12: 55503 | B12: 357.14286 | C12: 54.9273 | D12: -382.301 | E12: 50.81891 | F12: -20.84339 | G12: NaN | H12: NaN | I12: NaN | J12: NaN
A13: 61398 | B13: 292.85714 | C13: 57.27256 | D13: -23.49836 | E13: 52.52303 | F13: -22.83588 | G13: NaN | H13: NaN | I13: NaN | J13: NaN
... A55: 437847 | B55: 0.1 | C55: 1056.1087 | D55: 0.45299 | E55: 1056.0757 | F55: 8.34966 | G55: NaN | H55: NaN | I55: NaN | J55: NaN

Sheet I50_P500_T70_HRK20
A1: Temps (ms) | B1: Fr駲uence (Hz) | C1: Module de Z (mOhm) | D1: d駱hasage de Z (ｰ) | E1: Partie r馥lle | F1: Partie imaginaire | G1: Module de Zstack (mOhm) | H1: d駱hasage de Zstack (ｰ) | I1: Partie r馥lle stack | J1: Partie imaginaire stack
A2: 0 | B2: 1000 | C2: 47.88643 | D2: -17.30086 | E2: 45.71987 | F2: -14.24091 | G2: NaN | H2: NaN | I2: NaN | J2: NaN
A3: 2398 | B3: 952.63158 | C3: 48.03844 | D3: -17.32604 | E3: 45.85872 | F3: -14.30627 | G3: NaN | H3: NaN | I3: NaN | J3: NaN
A4: 3997 | B4: 905.26316 | C4: 48.85241 | D4: -17.33201 | E4: 46.63424 | F4: -14.55353 | G4: NaN | H4: NaN | I4: NaN | J4: NaN
A5: 5203 | B5: 857.89474 | C5: 49.16497 | D5: -17.97964 | E5: 46.76406 | F5: -15.17619 | G5: NaN | H5: NaN | I5: NaN | J5: NaN
A6: 6681 | B6: 810.52632 | C6: 49.88755 | D6: -18.07949 | E6: 47.42444 | F6: -15.48191 | G6: NaN | H6: NaN | I6: NaN | J6: NaN
A7: 7867 | B7: 763.15789 | C7: 50.42326 | D7: -18.04885 | E7: 47.94206 | F7: -15.62252 | G7: NaN | H7: NaN | I7: NaN | J7: NaN
A8: 9137 | B8: 715.78947 | C8: 51.21065 | D8: -378.42507 | E8: 48.58548 | F8: -16.18585 | G8: NaN | H8: NaN | I8: NaN | J8: NaN
A9: 10497 | B9: 668.42105 | C9: 51.7352 | D9: -379.01829 | E9: 48.91121 | F9: -16.85895 | G9: NaN | H9: NaN | I9: NaN | J9: NaN
A10: 11917 | B10: 621.05263 | C10: 52.51198 | D10: -379.10787 | E10: 49.61878 | F10: -17.18968 | G10: NaN | H10: NaN | I10: NaN | J10: NaN
A11: 13151 | B11: 573.68421 | C11: 53.35152 | D11: -379.40923 | E11: 50.3195 | F11: -17.72941 | G11: NaN | H11: NaN | I11: NaN | J11: NaN
A12: 14359 | B12: 526.31579 | C12: 54.32397 | D12: -379.90649 | E12: 51.07809 | F12: -18.49655 | G12: NaN | H12: NaN | I12: NaN | J12: NaN
A13: 15531 | B13: 478.94737 | C13: 55.42697 | D13: -380.43261 | E13: 51.93969 | F13: -19.34986 | G13: NaN | H13: NaN | I13: NaN | J13: NaN
... A68: 269916 | B68: 0.1 | C68: 787.3802 | D68: 0.32626 | E68: 787.36743 | F68: 4.48353 | G68: NaN | H68: NaN | I68: NaN | J68: NaN

Sheet I10_P300_T70_HR0
A1: Temps (ms) | B1: Fr駲uence (Hz) | C1: Module de Z (mOhm) | D1: d駱hasage de Z (ｰ) | E1: Partie r馥lle | F1: Partie imaginaire | G1: Module de Zstack (mOhm) | H1: d駱hasage de Zstack (ｰ) | I1: Partie r馥lle stack | J1: Partie imaginaire stack
A2: 0 | B2: 1000 | C2: 98.60908 | D2: -18.72823 | E2: 93.38795 | F2: -31.66136 | G2: NaN | H2: NaN | I2: NaN | J2: NaN
A3: 4915 | B3: 935.71429 | C3: 97.90417 | D3: -19.23795 | E3: 92.43704 | F3: -32.25865 | G3: NaN | H3: NaN | I3: NaN | J3: NaN
A4: 9003 | B4: 871.42857 | C4: 99.55048 | D4: -18.23461 | E4: 94.55137 | F4: -31.15022 | G4: NaN | H4: NaN | I4: NaN | J4: NaN
A5: 13074 | B5: 807.14286 | C5: 101.04853 | D5: -18.77522 | E5: 95.67159 | F5: -32.5231 | G5: NaN | H5: NaN | I5: NaN | J5: NaN
A6: 17654 | B6: 742.85714 | C6: 103.42187 | D6: -378.98819 | E6: 97.79424 | F6: -33.65071 | G6: NaN | H6: NaN | I6: NaN | J6: NaN
A7: 22204 | B7: 678.57143 | C7: 106.45996 | D7: -379.32998 | E7: 100.45859 | F7: -35.23911 | G7: NaN | H7: NaN | I7: NaN | J7: NaN
A8: 26567 | B8: 614.28571 | C8: 111.14273 | D8: -379.99442 | E8: 104.4437 | F8: -38.00287 | G8: NaN | H8: NaN | I8: NaN | J8: NaN
A9: 31130 | B9: 550 | C9: 113.12141 | D9: -380.50391 | E9: 105.95498 | F9: -39.62318 | G9: NaN | H9: NaN | I9: NaN | J9: NaN
A10: 35083 | B10: 485.71429 | C10: 116.59994 | D10: -381.08304 | E10: 108.79475 | F10: -41.94341 | G10: NaN | H10: NaN | I10: NaN | J10: NaN
A11: 39662 | B11: 421.42857 | C11: 121.1039 | D11: -381.51153 | E11: 112.66827 | F11: -44.4074 | G11: NaN | H11: NaN | I11: NaN | J11: NaN
A12: 44239 | B12: 357.14286 | C12: 125.94618 | D12: -381.80226 | E12: 116.9374 | F12: -46.77697 | G12: NaN | H12: NaN | I12: NaN | J12: NaN
A13: 48836 | B13: 292.85714 | C13: 132.21935 | D13: -22.30048 | E13: 122.33021 | F13: -50.17247 | G13: NaN | H13: NaN | I13: NaN | J13: NaN
... A55: 396890 | B55: 0.1 | C55: 435.16325 | D55: 2.32885 | E55: 434.80383 | F55: 17.68283 | G55: NaN | H55: NaN | I55: NaN | J55: NaN

Sheet I20_P300_T70_HR0
A1: Temps (ms) | B1: Fr駲uence (Hz) | C1: Module de Z (mOhm) | D1: d駱hasage de Z (ｰ) | E1: Partie r馥lle | F1: Partie imaginaire | G1: Module de Zstack (mOhm) | H1: d駱hasage de Zstack (ｰ) | I1: Partie r馥lle stack | J1: Partie imaginaire stack
A2: 0 | B2: 1000 | C2: 69.3327 | D2: -18.54584 | E2: 65.73222 | F2: -22.05218 | G2: NaN | H2: NaN | I2: NaN | J2: NaN
A3: 4813 | B3: 935.71429 | C3: 71.94212 | D3: -18.23519 | E3: 68.32919 | F3: -22.51201 | G3: NaN | H3: NaN | I3: NaN | J3: NaN
A4: 9541 | B4: 871.42857 | C4: 72.739 | D4: -18.96513 | E4: 68.79047 | F4: -23.63964 | G4: NaN | H4: NaN | I4: NaN | J4: NaN
A5: 14063 | B5: 807.14286 | C5: 74.42604 | D5: -19.33413 | E5: 70.2287 | F5: -24.64071 | G5: NaN | H5: NaN | I5: NaN | J5: NaN
A6: 18604 | B6: 742.85714 | C6: 75.20582 | D6: -380.25598 | E6: 70.55473 | F6: -26.03738 | G6: NaN | H6: NaN | I6: NaN | J6: NaN
A7: 23188 | B7: 678.57143 | C7: 77.01906 | D7: -380.1522 | E7: 72.30401 | F7: -26.53423 | G7: NaN | H7: NaN | I7: NaN | J7: NaN
A8: 27769 | B8: 614.28571 | C8: 78.3422 | D8: -380.17518 | E8: 73.53532 | F8: -27.01956 | G8: NaN | H8: NaN | I8: NaN | J8: NaN
A9: 32366 | B9: 550 | C9: 80.85785 | D9: -380.89197 | E9: 75.5418 | F9: -28.83448 | G9: NaN | H9: NaN | I9: NaN | J9: NaN
A10: 36943 | B10: 485.71429 | C10: 83.92335 | D10: -381.18619 | E10: 78.25105 | F10: -30.32989 | G10: NaN | H10: NaN | I10: NaN | J10: NaN
A11: 41344 | B11: 421.42857 | C11: 86.60695 | D11: -382.01846 | E11: 80.29011 | F11: -32.4694 | G11: NaN | H11: NaN | I11: NaN | J11: NaN
A12: 45961 | B12: 357.14286 | C12: 91.0195 | D12: -382.33752 | E12: 84.18949 | F12: -34.59306 | G12: NaN | H12: NaN | I12: NaN | J12: NaN
A13: 50570 | B13: 292.85714 | C13: 95.98151 | D13: -22.78071 | E13: 88.49433 | F13: -37.16455 | G13: NaN | H13: NaN | I13: NaN | J13: NaN
... A55: 495458 | B55: 0.1 | C55: 366.77448 | D55: 1.91809 | E55: 366.56897 | F55: 12.27622 | G55: NaN | H55: NaN | I55: NaN | J55: NaN

Sheet I30_P300_T70_HR0
A1: Temps (ms) | B1: Fr駲uence (Hz) | C1: Module de Z (mOhm) | D1: d駱hasage de Z (ｰ) | E1: Partie r馥lle | F1: Partie imaginaire | G1: Module de Zstack (mOhm) | H1: d駱hasage de Zstack (ｰ) | I1: Partie r馥lle stack | J1: Partie imaginaire stack
A2: 0 | B2: 1000 | C2: 62.75376 | D2: -18.54311 | E2: 59.49588 | F2: -19.95683 | G2: NaN | H2: NaN | I2: NaN | J2: NaN
A3: 4563 | B3: 935.71429 | C3: 64.34739 | D3: -19.05897 | E3: 60.82006 | F3: -21.01206 | G3: NaN | H3: NaN | I3: NaN | J3: NaN
A4: 9130 | B4: 871.42857 | C4: 65.20088 | D4: -19.09006 | E4: 61.6152 | F4: -21.3242 | G4: NaN | H4: NaN | I4: NaN | J4: NaN
A5: 13627 | B5: 807.14286 | C5: 66.68216 | D5: -19.23836 | E5: 62.95836 | F5: -21.97169 | G5: NaN | H5: NaN | I5: NaN | J5: NaN
A6: 18185 | B6: 742.85714 | C6: 68.40022 | D6: -380.05185 | E6: 64.25399 | F6: -23.4524 | G6: NaN | H6: NaN | I6: NaN | J6: NaN
A7: 22750 | B7: 678.57143 | C7: 69.10284 | D7: -380.22209 | E7: 64.84333 | F7: -23.88609 | G7: NaN | H7: NaN | I7: NaN | J7: NaN
A8: 27329 | B8: 614.28571 | C8: 71.36212 | D8: -380.83474 | E8: 66.69577 | F8: -25.38163 | G8: NaN | H8: NaN | I8: NaN | J8: NaN
A9: 31911 | B9: 550 | C9: 72.81073 | D9: -381.31694 | E9: 67.82929 | F9: -26.46864 | G9: NaN | H9: NaN | I9: NaN | J9: NaN
A10: 36270 | B10: 485.71429 | C10: 74.8893 | D10: -382.0543 | E10: 69.40953 | F10: -28.11982 | G10: NaN | H10: NaN | I10: NaN | J10: NaN
A11: 40874 | B11: 421.42857 | C11: 78.3357 | D11: -382.58729 | E11: 72.327 | F11: -30.088 | G11: NaN | H11: NaN | I11: NaN | J11: NaN
A12: 45472 | B12: 357.14286 | C12: 81.76564 | D12: -382.92278 | E12: 75.30866 | F12: -31.84692 | G12: NaN | H12: NaN | I12: NaN | J12: NaN
A13: 49931 | B13: 292.85714 | C13: 86.35108 | D13: -23.5255 | E13: 79.1738 | F13: -34.46766 | G13: NaN | H13: NaN | I13: NaN | J13: NaN
... A55: 985330 | B55: 0.1 | C55: 381.16912 | D55: 2.80365 | E55: 380.71287 | F55: 18.64425 | G55: NaN | H55: NaN | I55: NaN | J55: NaN

Sheet I35_P300_T70_HR0
A1: Temps (ms) | B1: Fr駲uence (Hz) | C1: Module de Z (mOhm) | D1: d駱hasage de Z (ｰ) | E1: Partie r馥lle | F1: Partie imaginaire | G1: Module de Zstack (mOhm) | H1: d駱hasage de Zstack (ｰ) | I1: Partie r馥lle stack | J1: Partie imaginaire stack
A2: 0 | B2: 1000 | C2: 58.37411 | D2: -17.80633 | E2: 55.57773 | F2: -17.85084 | G2: NaN | H2: NaN | I2: NaN | J2: NaN
A3: 35429 | B3: 935.71429 | C3: 59.29769 | D3: -18.45179 | E3: 56.24922 | F3: -18.76811 | G3: NaN | H3: NaN | I3: NaN | J3: NaN
A4: 40487 | B4: 871.42857 | C4: 60.96175 | D4: -18.99876 | E4: 57.64089 | F4: -19.84596 | G4: NaN | H4: NaN | I4: NaN | J4: NaN
A5: 45682 | B5: 807.14286 | C5: 61.0154 | D5: -19.52945 | E5: 57.50518 | F5: -20.39692 | G5: NaN | H5: NaN | I5: NaN | J5: NaN
A6: 50894 | B6: 742.85714 | C6: 62.09397 | D6: -379.92164 | E6: 58.37823 | F6: -21.15756 | G6: NaN | H6: NaN | I6: NaN | J6: NaN
A7: 56125 | B7: 678.57143 | C7: 63.35589 | D7: -380.26853 | E7: 59.43285 | F7: -21.94777 | G7: NaN | H7: NaN | I7: NaN | J7: NaN
A8: 61329 | B8: 614.28571 | C8: 65.06951 | D8: -380.53737 | E8: 60.93393 | F8: -22.82757 | G8: NaN | H8: NaN | I8: NaN | J8: NaN
A9: 66552 | B9: 550 | C9: 66.63692 | D9: -381.35018 | E9: 62.06381 | F9: -24.26031 | G9: NaN | H9: NaN | I9: NaN | J9: NaN
A10: 71716 | B10: 485.71429 | C10: 68.64753 | D10: -382.03804 | E10: 63.6318 | F10: -25.75807 | G10: NaN | H10: NaN | I10: NaN | J10: NaN
A11: 76905 | B11: 421.42857 | C11: 71.14033 | D11: -382.60792 | E11: 65.6737 | F11: -27.34797 | G11: NaN | H11: NaN | I11: NaN | J11: NaN
A12: 82159 | B12: 357.14286 | C12: 74.20483 | D12: -383.1625 | E12: 68.22341 | F12: -29.18774 | G12: NaN | H12: NaN | I12: NaN | J12: NaN
A13: 87180 | B13: 292.85714 | C13: 78.12922 | D13: -24.17813 | E13: 71.27545 | F13: -31.99976 | G13: NaN | H13: NaN | I13: NaN | J13: NaN
... A55: 461865 | B55: 0.1 | C55: 437.06668 | D55: 1.78204 | E55: 436.85529 | F55: 13.59167 | G55: NaN | H55: NaN | I55: NaN | J55: NaN

Sheet I40_P300_T70_HR0
A1: Temps (ms) | B1: Fr駲uence (Hz) | C1: Module de Z (mOhm) | D1: d駱hasage de Z (ｰ) | E1: Partie r馥lle | F1: Partie imaginaire | G1: Module de Zstack (mOhm) | H1: d駱hasage de Zstack (ｰ) | I1: Partie r馥lle stack | J1: Partie imaginaire stack
A2: 0 | B2: 1000 | C2: 62.66367 | D2: -17.81185 | E2: 59.65996 | F2: -19.16833 | G2: NaN | H2: NaN | I2: NaN | J2: NaN
A3: 5313 | B3: 935.71429 | C3: 63.31989 | D3: -18.66264 | E3: 59.99048 | F3: -20.26206 | G3: NaN | H3: NaN | I3: NaN | J3: NaN
A4: 10487 | B4: 871.42857 | C4: 64.02099 | D4: -19.18805 | E4: 60.4643 | F4: -21.04176 | G4: NaN | H4: NaN | I4: NaN | J4: NaN
A5: 15620 | B5: 807.14286 | C5: 65.02071 | D5: -19.65282 | E5: 61.23311 | F5: -21.86776 | G5: NaN | H5: NaN | I5: NaN | J5: NaN
A6: 20844 | B6: 742.85714 | C6: 66.112 | D6: -379.48483 | E6: 62.32576 | F6: -22.05214 | G6: NaN | H6: NaN | I6: NaN | J6: NaN
A7: 26093 | B7: 678.57143 | C7: 66.82678 | D7: -380.2938 | E7: 62.6786 | F7: -23.17781 | G7: NaN | H7: NaN | I7: NaN | J7: NaN
A8: 31270 | B8: 614.28571 | C8: 68.30257 | D8: -380.60539 | E8: 63.93301 | F8: -24.0377 | G8: NaN | H8: NaN | I8: NaN | J8: NaN
A9: 36499 | B9: 550 | C9: 69.93207 | D9: -381.58038 | E9: 65.03001 | F9: -25.72145 | G9: NaN | H9: NaN | I9: NaN | J9: NaN
A10: 41718 | B10: 485.71429 | C10: 71.16894 | D10: -382.08489 | E10: 65.94712 | F10: -26.75809 | G10: NaN | H10: NaN | I10: NaN | J10: NaN
A11: 46726 | B11: 421.42857 | C11: 73.54329 | D11: -382.61015 | E11: 67.89091 | F11: -28.27436 | G11: NaN | H11: NaN | I11: NaN | J11: NaN
A12: 51958 | B12: 357.14286 | C12: 78.05922 | D12: -383.45931 | E12: 71.60708 | F12: -31.07519 | G12: NaN | H12: NaN | I12: NaN | J12: NaN
A13: 57241 | B13: 292.85714 | C13: 82.69238 | D13: -24.34096 | E13: 75.34176 | F13: -34.08298 | G13: NaN | H13: NaN | I13: NaN | J13: NaN
... A55: 423990 | B55: 0.1 | C55: 557.83387 | D55: 1.83011 | E55: 557.54933 | F55: 17.81499 | G55: NaN | H55: NaN | I55: NaN | J55: NaN

Sheet I45_P300_T70_HR0
A1: Temps (ms) | B1: Fr駲uence (Hz) | C1: Module de Z (mOhm) | D1: d駱hasage de Z (ｰ) | E1: Partie r馥lle | F1: Partie imaginaire | G1: Module de Zstack (mOhm) | H1: d駱hasage de Zstack (ｰ) | I1: Partie r馥lle stack | J1: Partie imaginaire stack
A2: 0 | B2: 1000 | C2: 68.12374 | D2: -18.75454 | E2: 64.50669 | F2: -21.90277 | G2: NaN | H2: NaN | I2: NaN | J2: NaN
A3: 5475 | B3: 935.71429 | C3: 68.95111 | D3: -18.94584 | E3: 65.21575 | F3: -22.38664 | G3: NaN | H3: NaN | I3: NaN | J3: NaN
A4: 10709 | B4: 871.42857 | C4: 69.85783 | D4: -19.45043 | E4: 65.87104 | F4: -23.26204 | G4: NaN | H4: NaN | I4: NaN | J4: NaN
A5: 15939 | B5: 807.14286 | C5: 71.47334 | D5: -19.83935 | E5: 67.23125 | F5: -24.25692 | G5: NaN | H5: NaN | I5: NaN | J5: NaN
A6: 20970 | B6: 742.85714 | C6: 73.04886 | D6: -380.11694 | E6: 68.59234 | F6: -25.12423 | G6: NaN | H6: NaN | I6: NaN | J6: NaN
A7: 26214 | B7: 678.57143 | C7: 73.98383 | D7: -380.69219 | E7: 69.2113 | F7: -26.142 | G7: NaN | H7: NaN | I7: NaN | J7: NaN
A8: 31426 | B8: 614.28571 | C8: 75.42464 | D8: -381.39696 | E8: 70.22601 | F8: -27.51697 | G8: NaN | H8: NaN | I8: NaN | J8: NaN
A9: 36659 | B9: 550 | C9: 76.87479 | D9: -381.75041 | E9: 71.40183 | F9: -28.48704 | G9: NaN | H9: NaN | I9: NaN | J9: NaN
A10: 41870 | B10: 485.71429 | C10: 79.27612 | D10: -382.28221 | E10: 73.35637 | F10: -30.05904 | G10: NaN | H10: NaN | I10: NaN | J10: NaN
A11: 46936 | B11: 421.42857 | C11: 82.42098 | D11: -382.90376 | E11: 75.92289 | F11: -32.07696 | G11: NaN | H11: NaN | I11: NaN | J11: NaN
A12: 52230 | B12: 357.14286 | C12: 86.20767 | D12: -383.55118 | E12: 79.02688 | F12: -34.44584 | G12: NaN | H12: NaN | I12: NaN | J12: NaN
A13: 57536 | B13: 292.85714 | C13: 90.65795 | D13: -24.4961 | E13: 82.49778 | F13: -37.58962 | G13: NaN | H13: NaN | I13: NaN | J13: NaN
... A55: 427486 | B55: 0.1 | C55: 762.3679 | D55: 1.29669 | E55: 762.17267 | F55: 17.25207 | G55: NaN | H55: NaN | I55: NaN | J55: NaN

Sheet SYNTH
A1: Fréquence (Hz) | B1: Re(Z)_mOhm_I10_P300_T70_HR50 | C1: -Im(Z)_mOhm_I10_P300_T70_HR50 | D1: Re(Z)_mOhm_I10_P400_T70_HR50 | E1: -Im(Z)_mOhm_I10_P400_T70_HR50 | F1: Re(Z)_mOhm_I10_P500_T70_HR50 | G1: -Im(Z)_mOhm_I10_P500_T70_HR50 | H1: Re(Z)_mOhm_I20_P300_T70_HR50 | I1: -Im(Z)_mOhm_I20_P300_T70_HR50 | J1: Re(Z)_mOhm_I20_P400_T70_HR50 | K1: -Im(Z)_mOhm_I20_P400_T70_HR50 | L1: Re(Z)_mOhm_I20_P500_T70_HR50 | M1: -Im(Z)_mOhm_I20_P500_T70_HR50 | N1: Re(Z)_mOhm_I30_P300_T70_HR50 | O1: -Im(Z)_mOhm_I30_P300_T70_HR50 | P1: Re(Z)_mOhm_I30_P400_T70_HR50 | Q1: -Im(Z)_mOhm_I30_P400_T70_HR50 | R1: Re(Z)_mOhm_I30_P500_T70_HR50 | S1: -Im(Z)_mOhm_I30_P500_T70_HR50 | T1: Re(Z)_mOhm_I35_P300_T70_HR50 | U1: -Im(Z)_mOhm_I35_P300_T70_HR50 | V1: Re(Z)_mOhm_I35_P400_T70_HR50 | W1: -Im(Z)_mOhm_I35_P400_T70_HR50 | X1: Re(Z)_mOhm_I35_P500_T70_HR50 | Y1: -Im(Z)_mOhm_I35_P500_T70_HR50 | Z1: Re(Z)_mOhm_I40_P300_T70_HR50 | AA1: -Im(Z)_mOhm_I40_P300_T70_HR50 | AB1: Re(Z)_mOhm_I40_P400_T70_HR50 | AC1: -Im(Z)_mOhm_I40_P400_T70_HR50 | AD1: Re(Z)_mOhm_I40_P500_T70_HR50 | AE1: -Im(Z)_mOhm_I40_P500_T70_HR50 | AF1: Re(Z)_mOhm_I45_P300_T70_HR50 | AG1: -Im(Z)_mOhm_I45_P300_T70_HR50 | AH1: Re(Z)_mOhm_I45_P400_T70_HR50 | AI1: -Im(Z)_mOhm_I45_P400_T70_HR50 | AJ1: Re(Z)_mOhm_I45_P500_T70_HR50 | AK1: -Im(Z)_mOhm_I45_P500_T70_HR50 | AL1: Re(Z)_mOhm_I50_P300_T70_HR50 | AM1: -Im(Z)_mOhm_I50_P300_T70_HR50 | AN1: Re(Z)_mOhm_I50_P400_T70_HR50 | AO1: -Im(Z)_mOhm_I50_P400_T70_HR50 | AP1: Re(Z)_mOhm_I50_P500_T70_HR50 | AQ1: -Im(Z)_mOhm_I50_P500_T70_HR50 | AR1: Re(Z)_mOhm_I50_P500_T70_HRK20 | AS1: -Im(Z)_mOhm_I50_P500_T70_HRK20 | AT1: Re(Z)_mOhm_I10_P300_T70_HR0 | AU1: -Im(Z)_mOhm_I10_P300_T70_HR0 | AV1: Re(Z)_mOhm_I20_P300_T70_HR0 | AW1: -Im(Z)_mOhm_I20_P300_T70_HR0 | AX1: Re(Z)_mOhm_I30_P300_T70_HR0 | AY1: -Im(Z)_mOhm_I30_P300_T70_HR0 | AZ1: Re(Z)_mOhm_I35_P300_T70_HR0 | BA1: -Im(Z)_mOhm_I35_P300_T70_HR0 | BB1: Re(Z)_mOhm_I40_P300_T70_HR0 | BC1: -Im(Z)_mOhm_I40_P300_T70_HR0 | BD1: Re(Z)_mOhm_I45_P300_T70_HR0 | BE1: -Im(Z)_mOhm_I45_P300_T70_HR0
