Workbook
Name Nyquist: I10_P300_T60_HR0!$A$1:$K$55
Name Nyquist: I10_P300_T60_HR50!$A$1:$K$55
Name Nyquist: I20_P300_T60_HR0!$A$1:$K$55
Name Nyquist: I30_P300_T60_HR0!$A$1:$K$55
Name Nyquist: I35_P300_T60_HR0!$A$1:$K$55
Name Nyquist: I40_P300_T60_HR0!$A$1:$K$55
Name Nyquist: I40_P500_T60_HR50!$A$1:$K$55
Name Nyquist: I45_P300_T60_HR0!$A$1:$K$55
Name Nyquist: I45_P300_T60_HR50!$A$1:$K$55
Name Nyquist: I45_P400_T60_HR50!$A$1:$K$55
Name Nyquist: I45_P500_T60_HR50!$A$1:$K$55
Name Nyquist: I50_P300_T60_HR0!$A$1:$K$55
Name Nyquist: I50_P300_T60_HR50!$A$1:$K$55
Name Nyquist: I50_P400_T60_HR50!$A$1:$K$55
Name Nyquist: I50_P500_T60_HR50!$A$1:$K$55
Name Nyquist_2: I10_P400_T60_HR50!$A$1:$K$55
Name Nyquist_2: I10_P500_T60_HR50!$A$1:$K$55
Name Nyquist_2: I20_P300_T60_HR50!$A$1:$K$55
Name Nyquist_2: I20_P400_T60_HR50!$A$1:$K$55
Name Nyquist_2: I20_P500_T60_HR50!$A$1:$K$55
Name Nyquist_2: I30_P300_T60_HR50!$A$1:$K$55
Name Nyquist_2: I30_P400_T60_HR50!$A$1:$K$55
Name Nyquist_2: I30_P500_T60_HR50!$A$1:$K$55
Name Nyquist_2: I35_P300_T60_HR50!$A$1:$K$55
Name Nyquist_2: I35_P400_T60_HR50!$A$1:$K$55
Name Nyquist_2: I35_P500_T60_HR50!$A$1:$K$55
Name Nyquist_2: I40_P300_T60_HR50!$A$1:$K$55
Name Nyquist_2: I40_P400_T60_HR50!$A$1:$K$55

Sheet I10_P300_T60_HR50
A1: Temps (ms) | B1: Fr駲uence (Hz) | C1: Module de Z (mOhm) | D1: d駱hasage de Z (ｰ) | E1: Partie r馥lle | F1: Partie imaginaire | G1: Module de Zstack (mOhm) | H1: d駱hasage de Zstack (ｰ) | I1: Partie r馥lle stack | J1: Partie imaginaire stack
A2: 0 | B2: 1000 | C2: 35.14417 | D2: -13.65591 | E2: 34.15068 | F2: -8.2972 | G2: NaN | H2: NaN | I2: NaN | J2: NaN
A3: 2425 | B3: 935.71429 | C3: 37.68596 | D3: -13.82981 | E3: 36.59345 | F3: -9.0084 | G3: NaN | H3: NaN | I3: NaN | J3: NaN
A4: 4838 | B4: 871.42857 | C4: 37.83342 | D4: -13.62121 | E4: 36.76932 | F4: -8.90984 | G4: NaN | H4: NaN | I4: NaN | J4: NaN
A5: 6808 | B5: 807.14286 | C5: 37.63063 | D5: -14.34379 | E5: 36.45756 | F5: -9.32259 | G5: NaN | H5: NaN | I5: NaN | J5: NaN
A6: 8811 | B6: 742.85714 | C6: 38.50595 | D6: -374.27131 | E6: 37.31763 | F6: -9.49225 | G6: NaN | H6: NaN | I6: NaN | J6: NaN
A7: 10622 | B7: 678.57143 | C7: 38.71854 | D7: -375.54762 | E7: 37.30175 | F7: -10.37809 | G7: NaN | H7: NaN | I7: NaN | J7: NaN
A8: 12652 | B8: 614.28571 | C8: 39.4914 | D8: -376.41714 | E8: 37.88131 | F8: -11.16139 | G8: NaN | H8: NaN | I8: NaN | J8: NaN
A9: 14683 | B9: 550 | C9: 39.94095 | D9: -376.24639 | E9: 38.34601 | F9: -11.17422 | G9: NaN | H9: NaN | I9: NaN | J9: NaN
A10: 16509 | B10: 485.71429 | C10: 40.23608 | D10: -376.8952 | E10: 38.49941 | F10: -11.69349 | G10: NaN | H10: NaN | I10: NaN | J10: NaN
A11: 18564 | B11: 421.42857 | C11: 41.36438 | D11: -378.06575 | E11: 39.32517 | F11: -12.82743 | G11: NaN | H11: NaN | I11: NaN | J11: NaN
A12: 21030 | B12: 357.14286 | C12: 42.63263 | D12: -379.16107 | E12: 40.27077 | F12: -13.99309 | G12: NaN | H12: NaN | I12: NaN | J12: NaN
A13: 23135 | B13: 292.85714 | C13: 44.19055 | D13: -21.27694 | E13: 41.1784 | F13: -16.0357 | G13: NaN | H13: NaN | I13: NaN | J13: NaN
... A55: 291001 | B55: 0.1 | C55: 248.45221 | D55: -0.59446 | E55: 248.43883 | F55: -2.57773 | G55: NaN | H55: NaN | I55: NaN | J55: NaN

Sheet I10_P400_T60_HR50
A1: Temps (ms) | B1: Fr駲uence (Hz) | C1: Module de Z (mOhm) | D1: d駱hasage de Z (ｰ) | E1: Partie r馥lle | F1: Partie imaginaire | G1: Module de Zstack (mOhm) | H1: d駱hasage de Zstack (ｰ) | I1: Partie r馥lle stack | J1: Partie imaginaire stack
A2: 0 | B2: 1000 | C2: 36.63542 | D2: -14.91839 | E2: 35.40057 | F2: -9.43153 | G2: NaN | H2: NaN | I2: NaN | J2: NaN
A3: 2425 | B3: 935.71429 | C3: 37.66306 | D3: -13.65198 | E3: 36.59897 | F3: -8.88938 | G3: NaN | H3: NaN | I3: NaN | J3: NaN
A4: 4830 | B4: 871.42857 | C4: 37.54407 | D4: -12.2194 | E4: 36.69348 | F4: -7.94641 | G4: NaN | H4: NaN | I4: NaN | J4: NaN
A5: 6842 | B5: 807.14286 | C5: 38.51825 | D5: -13.66611 | E5: 37.42776 | F5: -9.10045 | G5: NaN | H5: NaN | I5: NaN | J5: NaN
A6: 9477 | B6: 742.85714 | C6: 38.42034 | D6: -374.23463 | E6: 37.24072 | F6: -9.44731 | G6: NaN | H6: NaN | I6: NaN | J6: NaN
A7: 12122 | B7: 678.57143 | C7: 38.98173 | D7: -374.78015 | E7: 37.6919 | F7: -9.94466 | G7: NaN | H7: NaN | I7: NaN | J7: NaN
A8: 14582 | B8: 614.28571 | C8: 39.38073 | D8: -375.57064 | E8: 37.93547 | F8: -10.57082 | G8: NaN | H8: NaN | I8: NaN | J8: NaN
A9: 17239 | B9: 550 | C9: 40.27547 | D9: -375.90674 | E9: 38.73328 | F9: -11.03839 | G9: NaN | H9: NaN | I9: NaN | J9: NaN
A10: 19900 | B10: 485.71429 | C10: 40.37041 | D10: -377.26326 | E10: 38.55178 | F10: -11.98043 | G10: NaN | H10: NaN | I10: NaN | J10: NaN
A11: 22419 | B11: 421.42857 | C11: 41.6338 | D11: -378.05989 | E11: 39.58263 | F11: -12.90693 | G11: NaN | H11: NaN | I11: NaN | J11: NaN
A12: 24926 | B12: 357.14286 | C12: 42.97503 | D12: -378.84981 | E12: 40.67022 | F12: -13.88474 | G12: NaN | H12: NaN | I12: NaN | J12: NaN
A13: 27672 | B13: 292.85714 | C13: 44.27628 | D13: -21.28549 | E13: 41.25589 | F13: -16.07297 | G13: NaN | H13: NaN | I13: NaN | J13: NaN
... A55: 301544 | B55: 0.1 | C55: 256.53493 | D55: -1.77184 | E55: 256.41228 | F55: -7.93193 | G55: NaN | H55: NaN | I55: NaN | J55: NaN

Sheet I10_P500_T60_HR50
A1: Temps (ms) | B1: Fr駲uence (Hz) | C1: Module de Z (mOhm) | D1: d駱hasage de Z (ｰ) | E1: Partie r馥lle | F1: Partie imaginaire | G1: Module de Zstack (mOhm) | H1: d駱hasage de Zstack (ｰ) | I1: Partie r馥lle stack | J1: Partie imaginaire stack
A2: 0 | B2: 1000 | C2: 37.68887 | D2: -13.32933 | E2: 36.67357 | F2: -8.68909 | G2: NaN | H2: NaN | I2: NaN | J2: NaN
A3: 2228 | B3: 935.71429 | C3: 38.16457 | D3: -12.44112 | E3: 37.26839 | F3: -8.22203 | G3: NaN | H3: NaN | I3: NaN | J3: NaN
A4: 4845 | B4: 871.42857 | C4: 37.69891 | D4: -13.71743 | E4: 36.62362 | F4: -8.93968 | G4: NaN | H4: NaN | I4: NaN | J4: NaN
A5: 7518 | B5: 807.14286 | C5: 37.78305 | D5: -14.25452 | E5: 36.61976 | F5: -9.30331 | G5: NaN | H5: NaN | I5: NaN | J5: NaN
A6: 10003 | B6: 742.85714 | C6: 38.26158 | D6: -373.66046 | E6: 37.17925 | F6: -9.03615 | G6: NaN | H6: NaN | I6: NaN | J6: NaN
A7: 12678 | B7: 678.57143 | C7: 39.11025 | D7: -374.68669 | E7: 37.83239 | F7: -9.91575 | G7: NaN | H7: NaN | I7: NaN | J7: NaN
A8: 15157 | B8: 614.28571 | C8: 39.51966 | D8: -374.93467 | E8: 38.1847 | F8: -10.18491 | G8: NaN | H8: NaN | I8: NaN | J8: NaN
A9: 17865 | B9: 550 | C9: 39.98926 | D9: -375.5343 | E9: 38.52846 | F9: -10.70973 | G9: NaN | H9: NaN | I9: NaN | J9: NaN
A10: 20544 | B10: 485.71429 | C10: 40.87243 | D10: -377.00797 | E10: 39.08484 | F10: -11.95538 | G10: NaN | H10: NaN | I10: NaN | J10: NaN
A11: 23055 | B11: 421.42857 | C11: 41.58551 | D11: -377.87558 | E11: 39.57798 | F11: -12.76471 | G11: NaN | H11: NaN | I11: NaN | J11: NaN
A12: 25580 | B12: 357.14286 | C12: 43.0519 | D12: -379.42914 | E12: 40.60025 | F12: -14.32082 | G12: NaN | H12: NaN | I12: NaN | J12: NaN
A13: 28377 | B13: 292.85714 | C13: 44.33382 | D13: -21.74324 | E13: 41.17962 | F13: -16.42337 | G13: NaN | H13: NaN | I13: NaN | J13: NaN
... A55: 306673 | B55: 0.1 | C55: 248.54124 | D55: -1.62438 | E55: 248.44136 | F55: -7.04541 | G55: NaN | H55: NaN | I55: NaN | J55: NaN

Sheet I20_P300_T60_HR50
A1: Temps (ms) | B1: Fr駲uence (Hz) | C1: Module de Z (mOhm) | D1: d駱hasage de Z (ｰ) | E1: Partie r馥lle | F1: Partie imaginaire | G1: Module de Zstack (mOhm) | H1: d駱hasage de Zstack (ｰ) | I1: Partie r馥lle stack | J1: Partie imaginaire stack
A2: 0 | B2: 1000 | C2: 38.09288 | D2: -15.3845 | E2: 36.72791 | F2: -10.10587 | G2: NaN | H2: NaN | I2: NaN | J2: NaN
A3: 3148 | B3: 935.71429 | C3: 38.95468 | D3: -12.47963 | E3: 38.0343 | F3: -8.41782 | G3: NaN | H3: NaN | I3: NaN | J3: NaN
A4: 6378 | B4: 871.42857 | C4: 38.51352 | D4: -14.77354 | E4: 37.24031 | F4: -9.82092 | G4: NaN | H4: NaN | I4: NaN | J4: NaN
A5: 9624 | B5: 807.14286 | C5: 39.93763 | D5: -13.96572 | E5: 38.75709 | F5: -9.6386 | G5: NaN | H5: NaN | I5: NaN | J5: NaN
A6: 12926 | B6: 742.85714 | C6: 39.75496 | D6: -374.88861 | E6: 38.42027 | F6: -10.21467 | G6: NaN | H6: NaN | I6: NaN | J6: NaN
A7: 16273 | B7: 678.57143 | C7: 40.10974 | D7: -375.29503 | E7: 38.68906 | F7: -10.58053 | G7: NaN | H7: NaN | I7: NaN | J7: NaN
A8: 19391 | B8: 614.28571 | C8: 41.04847 | D8: -375.76136 | E8: 39.50511 | F8: -11.15005 | G8: NaN | H8: NaN | I8: NaN | J8: NaN
A9: 22720 | B9: 550 | C9: 41.08878 | D9: -376.31623 | E9: 39.43396 | F9: -11.54343 | G9: NaN | H9: NaN | I9: NaN | J9: NaN
A10: 25828 | B10: 485.71429 | C10: 42.25239 | D10: -377.34858 | E10: 40.33026 | F10: -12.599 | G10: NaN | H10: NaN | I10: NaN | J10: NaN
A11: 29194 | B11: 421.42857 | C11: 43.91197 | D11: -377.89714 | E11: 41.78706 | F11: -13.49455 | G11: NaN | H11: NaN | I11: NaN | J11: NaN
A12: 32363 | B12: 357.14286 | C12: 44.81323 | D12: -379.44024 | E12: 42.25839 | F12: -14.91489 | G12: NaN | H12: NaN | I12: NaN | J12: NaN
A13: 35726 | B13: 292.85714 | C13: 46.38978 | D13: -21.67 | E13: 43.11123 | F13: -17.1299 | G13: NaN | H13: NaN | I13: NaN | J13: NaN
... A55: 336190 | B55: 0.1 | C55: 218.62043 | D55: 0.35445 | E55: 218.61624 | F55: 1.35246 | G55: NaN | H55: NaN | I55: NaN | J55: NaN

Sheet I20_P400_T60_HR50
A1: Temps (ms) | B1: Fr駲uence (Hz) | C1: Module de Z (mOhm) | D1: d駱hasage de Z (ｰ) | E1: Partie r馥lle | F1: Partie imaginaire | G1: Module de Zstack (mOhm) | H1: d駱hasage de Zstack (ｰ) | I1: Partie r馥lle stack | J1: Partie imaginaire stack
A2: 0 | B2: 1000 | C2: 38.61274 | D2: -14.44788 | E2: 37.39161 | F2: -9.63385 | G2: NaN | H2: NaN | I2: NaN | J2: NaN
A3: 3245 | B3: 935.71429 | C3: 38.4154 | D3: -13.4793 | E3: 37.35722 | F3: -8.9544 | G3: NaN | H3: NaN | I3: NaN | J3: NaN
A4: 6523 | B4: 871.42857 | C4: 38.99127 | D4: -13.36577 | E4: 37.93516 | F4: -9.01348 | G4: NaN | H4: NaN | I4: NaN | J4: NaN
A5: 9598 | B5: 807.14286 | C5: 38.78685 | D5: -13.33247 | E5: 37.74148 | F5: -8.94429 | G5: NaN | H5: NaN | I5: NaN | J5: NaN
A6: 12892 | B6: 742.85714 | C6: 39.91753 | D6: -374.21697 | E6: 38.69497 | F6: -9.80353 | G6: NaN | H6: NaN | I6: NaN | J6: NaN
A7: 16215 | B7: 678.57143 | C7: 40.18727 | D7: -374.94836 | E7: 38.82728 | F7: -10.36624 | G7: NaN | H7: NaN | I7: NaN | J7: NaN
A8: 19528 | B8: 614.28571 | C8: 41.39233 | D8: -375.2351 | E8: 39.93762 | F8: -10.87709 | G8: NaN | H8: NaN | I8: NaN | J8: NaN
A9: 22683 | B9: 550 | C9: 41.31471 | D9: -376.68926 | E9: 39.57439 | F9: -11.8648 | G9: NaN | H9: NaN | I9: NaN | J9: NaN
A10: 25984 | B10: 485.71429 | C10: 41.6936 | D10: -376.52225 | E10: 39.97205 | F10: -11.85714 | G10: NaN | H10: NaN | I10: NaN | J10: NaN
A11: 29129 | B11: 421.42857 | C11: 42.65534 | D11: -377.82635 | E11: 40.60741 | F11: -13.05821 | G11: NaN | H11: NaN | I11: NaN | J11: NaN
A12: 32469 | B12: 357.14286 | C12: 44.60299 | D12: -379.18432 | E12: 42.12602 | F12: -14.65691 | G12: NaN | H12: NaN | I12: NaN | J12: NaN
A13: 35653 | B13: 292.85714 | C13: 46.17438 | D13: -21.23113 | E13: 43.0404 | F13: -16.72118 | G13: NaN | H13: NaN | I13: NaN | J13: NaN
... A55: 329646 | B55: 0.1 | C55: 211.50071 | D55: 0.2659 | E55: 211.49843 | F55: 0.98155 | G55: NaN | H55: NaN | I55: NaN | J55: NaN

Sheet I20_P500_T60_HR50
A1: Temps (ms) | B1: Fr駲uence (Hz) | C1: Module de Z (mOhm) | D1: d駱hasage de Z (ｰ) | E1: Partie r馥lle | F1: Partie imaginaire | G1: Module de Zstack (mOhm) | H1: d駱hasage de Zstack (ｰ) | I1: Partie r馥lle stack | J1: Partie imaginaire stack
A2: 0 | B2: 1000 | C2: 36.96878 | D2: -14.71553 | E2: 35.75616 | F2: -9.39081 | G2: NaN | H2: NaN | I2: NaN | J2: NaN
A3: 2880 | B3: 935.71429 | C3: 38.07616 | D3: -13.61558 | E3: 37.00611 | F3: -8.96337 | G3: NaN | H3: NaN | I3: NaN | J3: NaN
A4: 6035 | B4: 871.42857 | C4: 38.7631 | D4: -13.69798 | E4: 37.66058 | F4: -9.17925 | G4: NaN | H4: NaN | I4: NaN | J4: NaN
A5: 8907 | B5: 807.14286 | C5: 38.62455 | D5: -14.43394 | E5: 37.4054 | F5: -9.62769 | G5: NaN | H5: NaN | I5: NaN | J5: NaN
A6: 11335 | B6: 742.85714 | C6: 38.7618 | D6: -375.42425 | E6: 37.36571 | F6: -10.30925 | G6: NaN | H6: NaN | I6: NaN | J6: NaN
A7: 14206 | B7: 678.57143 | C7: 40.17212 | D7: -374.31187 | E7: 38.92536 | F7: -9.93054 | G7: NaN | H7: NaN | I7: NaN | J7: NaN
A8: 17345 | B8: 614.28571 | C8: 40.76959 | D8: -376.29602 | E8: 39.13166 | F8: -11.43995 | G8: NaN | H8: NaN | I8: NaN | J8: NaN
A9: 20473 | B9: 550 | C9: 40.99606 | D9: -376.25068 | E9: 39.35812 | F9: -11.47235 | G9: NaN | H9: NaN | I9: NaN | J9: NaN
A10: 23157 | B10: 485.71429 | C10: 42.28414 | D10: -376.63995 | E10: 40.51341 | F10: -12.10834 | G10: NaN | H10: NaN | I10: NaN | J10: NaN
A11: 25688 | B11: 421.42857 | C11: 42.9288 | D11: -378.45816 | E11: 40.72033 | F11: -13.59178 | G11: NaN | H11: NaN | I11: NaN | J11: NaN
A12: 28436 | B12: 357.14286 | C12: 44.36976 | D12: -378.70799 | E12: 42.0255 | F12: -14.23138 | G12: NaN | H12: NaN | I12: NaN | J12: NaN
A13: 31462 | B13: 292.85714 | C13: 46.38917 | D13: -20.533 | E13: 43.44208 | F13: -16.27085 | G13: NaN | H13: NaN | I13: NaN | J13: NaN
... A55: 317839 | B55: 0.1 | C55: 205.78879 | D55: -0.46234 | E55: 205.78209 | F55: -1.66057 | G55: NaN | H55: NaN | I55: NaN | J55: NaN

Sheet I30_P300_T60_HR50
A1: Temps (ms) | B1: Fr駲uence (Hz) | C1: Module de Z (mOhm) | D1: d駱hasage de Z (ｰ) | E1: Partie r馥lle | F1: Partie imaginaire | G1: Module de Zstack (mOhm) | H1: d駱hasage de Zstack (ｰ) | I1: Partie r馥lle stack | J1: Partie imaginaire stack
A2: 0 | B2: 1000 | C2: 38.61796 | D2: -13.77844 | E2: 37.50669 | F2: -9.19756 | G2: NaN | H2: NaN | I2: NaN | J2: NaN
A3: 3705 | B3: 935.71429 | C3: 39.20408 | D3: -13.81411 | E3: 38.07012 | F3: -9.36086 | G3: NaN | H3: NaN | I3: NaN | J3: NaN
A4: 7485 | B4: 871.42857 | C4: 40.05286 | D4: -14.16643 | E4: 38.83481 | F4: -9.80251 | G4: NaN | H4: NaN | I4: NaN | J4: NaN
A5: 10766 | B5: 807.14286 | C5: 40.53658 | D5: -15.33335 | E5: 39.09363 | F5: -10.71927 | G5: NaN | H5: NaN | I5: NaN | J5: NaN
A6: 14068 | B6: 742.85714 | C6: 40.99544 | D6: -375.17829 | E6: 39.56534 | F6: -10.73357 | G6: NaN | H6: NaN | I6: NaN | J6: NaN
A7: 17227 | B7: 678.57143 | C7: 41.36672 | D7: -375.31638 | E7: 39.89745 | F7: -10.92697 | G7: NaN | H7: NaN | I7: NaN | J7: NaN
A8: 20372 | B8: 614.28571 | C8: 41.64603 | D8: -376.20262 | E8: 39.99189 | F8: -11.6207 | G8: NaN | H8: NaN | I8: NaN | J8: NaN
A9: 23734 | B9: 550 | C9: 42.58339 | D9: -376.75963 | E9: 40.77458 | F9: -12.27923 | G9: NaN | H9: NaN | I9: NaN | J9: NaN
A10: 27112 | B10: 485.71429 | C10: 43.64586 | D10: -376.95553 | E10: 41.74863 | F10: -12.72841 | G10: NaN | H10: NaN | I10: NaN | J10: NaN
A11: 30917 | B11: 421.42857 | C11: 44.41813 | D11: -377.97615 | E11: 42.24986 | F11: -13.70837 | G11: NaN | H11: NaN | I11: NaN | J11: NaN
A12: 34131 | B12: 357.14286 | C12: 46.00314 | D12: -379.34221 | E12: 43.40659 | F12: -15.23668 | G12: NaN | H12: NaN | I12: NaN | J12: NaN
A13: 37335 | B13: 292.85714 | C13: 47.73657 | D13: -20.86496 | E13: 44.60612 | F13: -17.00218 | G13: NaN | H13: NaN | I13: NaN | J13: NaN
... A55: 346404 | B55: 0.1 | C55: 312.34108 | D55: 0.80097 | E55: 312.31056 | F55: 4.36626 | G55: NaN | H55: NaN | I55: NaN | J55: NaN

Sheet I30_P400_T60_HR50
A1: Temps (ms) | B1: Fr駲uence (Hz) | C1: Module de Z (mOhm) | D1: d駱hasage de Z (ｰ) | E1: Partie r馥lle | F1: Partie imaginaire | G1: Module de Zstack (mOhm) | H1: d駱hasage de Zstack (ｰ) | I1: Partie r馥lle stack | J1: Partie imaginaire stack
A2: 0 | B2: 1000 | C2: 38.93967 | D2: -14.06807 | E2: 37.77178 | F2: -9.46524 | G2: NaN | H2: NaN | I2: NaN | J2: NaN
A3: 4720 | B3: 935.71429 | C3: 38.5235 | D3: -13.87784 | E3: 37.39897 | F3: -9.23996 | G3: NaN | H3: NaN | I3: NaN | J3: NaN
A4: 8277 | B4: 871.42857 | C4: 39.50825 | D4: -14.26787 | E4: 38.28959 | F4: -9.73703 | G4: NaN | H4: NaN | I4: NaN | J4: NaN
A5: 11620 | B5: 807.14286 | C5: 40.08485 | D5: -14.46602 | E5: 38.814 | F5: -10.01343 | G5: NaN | H5: NaN | I5: NaN | J5: NaN
A6: 15558 | B6: 742.85714 | C6: 40.64326 | D6: -374.95165 | E6: 39.26723 | F6: -10.48612 | G6: NaN | H6: NaN | I6: NaN | J6: NaN
A7: 19500 | B7: 678.57143 | C7: 41.41417 | D7: -374.93894 | E7: 40.01441 | F7: -10.67614 | G7: NaN | H7: NaN | I7: NaN | J7: NaN
A8: 23249 | B8: 614.28571 | C8: 41.11157 | D8: -375.15736 | E8: 39.68135 | F8: -10.74948 | G8: NaN | H8: NaN | I8: NaN | J8: NaN
A9: 27227 | B9: 550 | C9: 42.3172 | D9: -376.02646 | E9: 40.67251 | F9: -11.68298 | G9: NaN | H9: NaN | I9: NaN | J9: NaN
A10: 31180 | B10: 485.71429 | C10: 42.83768 | D10: -377.08854 | E10: 40.94648 | F10: -12.58782 | G10: NaN | H10: NaN | I10: NaN | J10: NaN
A11: 34947 | B11: 421.42857 | C11: 43.98099 | D11: -377.68699 | E11: 41.90203 | F11: -13.36216 | G11: NaN | H11: NaN | I11: NaN | J11: NaN
A12: 38930 | B12: 357.14286 | C12: 45.24143 | D12: -379.06649 | E12: 42.75949 | F12: -14.7788 | G12: NaN | H12: NaN | I12: NaN | J12: NaN
A13: 42755 | B13: 292.85714 | C13: 47.07047 | D13: -20.60806 | E13: 44.05843 | F13: -16.56755 | G13: NaN | H13: NaN | I13: NaN | J13: NaN
... A55: 358845 | B55: 0.1 | C55: 284.17865 | D55: 0.44623 | E55: 284.17003 | F55: 2.21323 | G55: NaN | H55: NaN | I55: NaN | J55: NaN

Sheet I30_P500_T60_HR50
A1: Temps (ms) | B1: Fr駲uence (Hz) | C1: Module de Z (mOhm) | D1: d駱hasage de Z (ｰ) | E1: Partie r馥lle | F1: Partie imaginaire | G1: Module de Zstack (mOhm) | H1: d駱hasage de Zstack (ｰ) | I1: Partie r馥lle stack | J1: Partie imaginaire stack
A2: 0 | B2: 1000 | C2: 38.16889 | D2: -13.22465 | E2: 37.15668 | F2: -8.73188 | G2: NaN | H2: NaN | I2: NaN | J2: NaN
A3: 3751 | B3: 935.71429 | C3: 39.2793 | D3: -13.50094 | E3: 38.19386 | F3: -9.1702 | G3: NaN | H3: NaN | I3: NaN | J3: NaN
A4: 7735 | B4: 871.42857 | C4: 39.26064 | D4: -13.83028 | E4: 38.1224 | F4: -9.38513 | G4: NaN | H4: NaN | I4: NaN | J4: NaN
A5: 11643 | B5: 807.14286 | C5: 39.48535 | D5: -14.3989 | E5: 38.24503 | F5: -9.81888 | G5: NaN | H5: NaN | I5: NaN | J5: NaN
A6: 15546 | B6: 742.85714 | C6: 40.26557 | D6: -374.55217 | E6: 38.97382 | F6: -10.11719 | G6: NaN | H6: NaN | I6: NaN | J6: NaN
A7: 19537 | B7: 678.57143 | C7: 41.21645 | D7: -375.60089 | E7: 39.69797 | F7: -11.08454 | G7: NaN | H7: NaN | I7: NaN | J7: NaN
A8: 23307 | B8: 614.28571 | C8: 41.70459 | D8: -375.7909 | E8: 40.13071 | F8: -11.34896 | G8: NaN | H8: NaN | I8: NaN | J8: NaN
A9: 27270 | B9: 550 | C9: 41.75183 | D9: -376.24801 | E9: 40.08424 | F9: -11.68198 | G9: NaN | H9: NaN | I9: NaN | J9: NaN
A10: 31024 | B10: 485.71429 | C10: 42.8057 | D10: -376.98046 | E10: 40.93956 | F10: -12.50122 | G10: NaN | H10: NaN | I10: NaN | J10: NaN
A11: 35010 | B11: 421.42857 | C11: 43.76149 | D11: -377.65043 | E11: 41.70138 | F11: -13.26887 | G11: NaN | H11: NaN | I11: NaN | J11: NaN
A12: 39013 | B12: 357.14286 | C12: 44.82035 | D12: -378.54568 | E12: 42.49285 | F12: -14.25559 | G12: NaN | H12: NaN | I12: NaN | J12: NaN
A13: 42798 | B13: 292.85714 | C13: 46.73593 | D13: -20.32277 | E13: 43.82667 | F13: -16.23178 | G13: NaN | H13: NaN | I13: NaN | J13: NaN
... A55: 362854 | B55: 0.1 | C55: 261.20815 | D55: 0.34477 | E55: 261.20342 | F55: 1.57179 | G55: NaN | H55: NaN | I55: NaN | J55: NaN

Sheet I35_P300_T60_HR50
A1: Temps (ms) | B1: Fr駲uence (Hz) | C1: Module de Z (mOhm) | D1: d駱hasage de Z (ｰ) | E1: Partie r馥lle | F1: Partie imaginaire | G1: Module de Zstack (mOhm) | H1: d駱hasage de Zstack (ｰ) | I1: Partie r馥lle stack | J1: Partie imaginaire stack
A2: 0 | B2: 1000 | C2: 38.92192 | D2: -13.78203 | E2: 37.80132 | F2: -9.27233 | G2: NaN | H2: NaN | I2: NaN | J2: NaN
A3: 4166 | B3: 935.71429 | C3: 39.93787 | D3: -13.73079 | E3: 38.79652 | F3: -9.47966 | G3: NaN | H3: NaN | I3: NaN | J3: NaN
A4: 8738 | B4: 871.42857 | C4: 40.58313 | D4: -15.48968 | E4: 39.10909 | F4: -10.83832 | G4: NaN | H4: NaN | I4: NaN | J4: NaN
A5: 13281 | B5: 807.14286 | C5: 40.73015 | D5: -14.588 | E5: 39.41709 | F5: -10.25857 | G5: NaN | H5: NaN | I5: NaN | J5: NaN
A6: 17842 | B6: 742.85714 | C6: 41.14878 | D6: -374.43018 | E6: 39.85062 | F6: -10.25428 | G6: NaN | H6: NaN | I6: NaN | J6: NaN
A7: 22443 | B7: 678.57143 | C7: 41.86776 | D7: -375.42192 | E7: 40.36026 | F7: -11.13368 | G7: NaN | H7: NaN | I7: NaN | J7: NaN
A8: 26842 | B8: 614.28571 | C8: 42.4354 | D8: -376.40145 | E8: 40.70857 | F8: -11.98231 | G8: NaN | H8: NaN | I8: NaN | J8: NaN
A9: 31442 | B9: 550 | C9: 42.89784 | D9: -377.02191 | E9: 41.01861 | F9: -12.5578 | G9: NaN | H9: NaN | I9: NaN | J9: NaN
A10: 36031 | B10: 485.71429 | C10: 43.82697 | D10: -377.48793 | E10: 41.8013 | F10: -13.17022 | G10: NaN | H10: NaN | I10: NaN | J10: NaN
A11: 40650 | B11: 421.42857 | C11: 45.04139 | D11: -378.56288 | E11: 42.6981 | F11: -14.33871 | G11: NaN | H11: NaN | I11: NaN | J11: NaN
A12: 45253 | B12: 357.14286 | C12: 46.55125 | D12: -379.58819 | E12: 43.85717 | F12: -15.60665 | G12: NaN | H12: NaN | I12: NaN | J12: NaN
A13: 49658 | B13: 292.85714 | C13: 48.1697 | D13: -21.3121 | E13: 44.87559 | F13: -17.50718 | G13: NaN | H13: NaN | I13: NaN | J13: NaN
... A55: 393167 | B55: 0.1 | C55: 397.27062 | D55: 0.61099 | E55: 397.24804 | F55: 4.23634 | G55: NaN | H55: NaN | I55: NaN | J55: NaN

Sheet I35_P400_T60_HR50
A1: Temps (ms) | B1: Fr駲uence (Hz) | C1: Module de Z (mOhm) | D1: d駱hasage de Z (ｰ) | E1: Partie r馥lle | F1: Partie imaginaire | G1: Module de Zstack (mOhm) | H1: d駱hasage de Zstack (ｰ) | I1: Partie r馥lle stack | J1: Partie imaginaire stack
A2: 0 | B2: 1000 | C2: 38.33309 | D2: -14.50327 | E2: 37.11154 | F2: -9.59996 | G2: NaN | H2: NaN | I2: NaN | J2: NaN
A3: 4357 | B3: 935.71429 | C3: 39.39187 | D3: -14.1927 | E3: 38.18949 | F3: -9.65825 | G3: NaN | H3: NaN | I3: NaN | J3: NaN
A4: 8908 | B4: 871.42857 | C4: 39.73781 | D4: -14.07593 | E4: 38.54465 | F4: -9.66453 | G4: NaN | H4: NaN | I4: NaN | J4: NaN
A5: 13422 | B5: 807.14286 | C5: 39.9166 | D5: -14.73164 | E5: 38.60445 | F5: -10.15047 | G5: NaN | H5: NaN | I5: NaN | J5: NaN
A6: 17334 | B6: 742.85714 | C6: 40.56226 | D6: -374.8798 | E6: 39.20208 | F6: -10.41607 | G6: NaN | H6: NaN | I6: NaN | J6: NaN
A7: 21886 | B7: 678.57143 | C7: 41.21326 | D7: -375.62392 | E7: 39.69044 | F7: -11.09963 | G7: NaN | H7: NaN | I7: NaN | J7: NaN
A8: 26442 | B8: 614.28571 | C8: 41.95948 | D8: -376.29983 | E8: 40.27297 | F8: -11.77651 | G8: NaN | H8: NaN | I8: NaN | J8: NaN
A9: 30992 | B9: 550 | C9: 42.55652 | D9: -376.50689 | E9: 40.80258 | F9: -12.09161 | G9: NaN | H9: NaN | I9: NaN | J9: NaN
A10: 35567 | B10: 485.71429 | C10: 43.44578 | D10: -377.41081 | E10: 41.45526 | F10: -12.99988 | G10: NaN | H10: NaN | I10: NaN | J10: NaN
A11: 40120 | B11: 421.42857 | C11: 44.59737 | D11: -378.19946 | E11: 42.36638 | F11: -13.92892 | G11: NaN | H11: NaN | I11: NaN | J11: NaN
A12: 44714 | B12: 357.14286 | C12: 45.69392 | D12: -379.52194 | E12: 43.06714 | F12: -15.26943 | G12: NaN | H12: NaN | I12: NaN | J12: NaN
A13: 49328 | B13: 292.85714 | C13: 47.47199 | D13: -21.02987 | E13: 44.31004 | F13: -17.03554 | G13: NaN | H13: NaN | I13: NaN | J13: NaN
... A55: 385461 | B55: 0.1 | C55: 351.31224 | D55: 1.02368 | E55: 351.25617 | F55: 6.2764 | G55: NaN | H55: NaN | I55: NaN | J55: NaN

Sheet I35_P500_T60_HR50
A1: Temps (ms) | B1: Fr駲uence (Hz) | C1: Module de Z (mOhm) | D1: d駱hasage de Z (ｰ) | E1: Partie r馥lle | F1: Partie imaginaire | G1: Module de Zstack (mOhm) | H1: d駱hasage de Zstack (ｰ) | I1: Partie r馥lle stack | J1: Partie imaginaire stack
A2: 0 | B2: 1000 | C2: 37.89188 | D2: -12.95765 | E2: 36.927 | F2: -8.49652 | G2: NaN | H2: NaN | I2: NaN | J2: NaN
A3: 4088 | B3: 935.71429 | C3: 38.96779 | D3: -13.83905 | E3: 37.83661 | F3: -9.32091 | G3: NaN | H3: NaN | I3: NaN | J3: NaN
A4: 8068 | B4: 871.42857 | C4: 39.33559 | D4: -14.76413 | E4: 38.03685 | F4: -10.0243 | G4: NaN | H4: NaN | I4: NaN | J4: NaN
A5: 11969 | B5: 807.14286 | C5: 39.61654 | D5: -14.64712 | E5: 38.32907 | F5: -10.01764 | G5: NaN | H5: NaN | I5: NaN | J5: NaN
A6: 15737 | B6: 742.85714 | C6: 40.46613 | D6: -374.59175 | E6: 39.16092 | F6: -10.19463 | G6: NaN | H6: NaN | I6: NaN | J6: NaN
A7: 19665 | B7: 678.57143 | C7: 40.78084 | D7: -375.2461 | E7: 39.34556 | F7: -10.72395 | G7: NaN | H7: NaN | I7: NaN | J7: NaN
A8: 23603 | B8: 614.28571 | C8: 41.28457 | D8: -376.08256 | E8: 39.66883 | F8: -11.43674 | G8: NaN | H8: NaN | I8: NaN | J8: NaN
A9: 27556 | B9: 550 | C9: 41.94995 | D9: -376.60619 | E9: 40.20029 | F9: -11.98896 | G9: NaN | H9: NaN | I9: NaN | J9: NaN
A10: 31532 | B10: 485.71429 | C10: 42.81478 | D10: -377.22975 | E10: 40.89345 | F10: -12.68191 | G10: NaN | H10: NaN | I10: NaN | J10: NaN
A11: 35893 | B11: 421.42857 | C11: 43.75007 | D11: -378.31849 | E11: 41.53299 | F11: -13.75059 | G11: NaN | H11: NaN | I11: NaN | J11: NaN
A12: 39878 | B12: 357.14286 | C12: 45.16145 | D12: -379.54158 | E12: 42.56011 | F12: -15.10609 | G12: NaN | H12: NaN | I12: NaN | J12: NaN
A13: 44116 | B13: 292.85714 | C13: 46.86314 | D13: -20.81217 | E13: 43.80533 | F13: -16.65073 | G13: NaN | H13: NaN | I13: NaN | J13: NaN
... A55: 372780 | B55: 0.1 | C55: 327.54289 | D55: 0.58103 | E55: 327.52605 | F55: 3.32153 | G55: NaN | H55: NaN | I55: NaN | J55: NaN

Sheet I40_P300_T60_HR50
A1: Temps (ms) | B1: Fr駲uence (Hz) | C1: Module de Z (mOhm) | D1: d駱hasage de Z (ｰ) | E1: Partie r馥lle | F1: Partie imaginaire | G1: Module de Zstack (mOhm) | H1: d駱hasage de Zstack (ｰ) | I1: Partie r馥lle stack | J1: Partie imaginaire stack
A2: 0 | B2: 1000 | C2: 39.83086 | D2: -14.6412 | E2: 38.53746 | F2: -10.06786 | G2: NaN | H2: NaN | I2: NaN | J2: NaN
A3: 4953 | B3: 935.71429 | C3: 40.28312 | D3: -14.48287 | E3: 39.00302 | F3: -10.07443 | G3: NaN | H3: NaN | I3: NaN | J3: NaN
A4: 9544 | B4: 871.42857 | C4: 40.1637 | D4: -14.60977 | E4: 38.86505 | F4: -10.13067 | G4: NaN | H4: NaN | I4: NaN | J4: NaN
A5: 14062 | B5: 807.14286 | C5: 41.03203 | D5: -15.65737 | E5: 39.50944 | F5: -11.07389 | G5: NaN | H5: NaN | I5: NaN | J5: NaN
A6: 18664 | B6: 742.85714 | C6: 41.54851 | D6: -375.94125 | E6: 39.95071 | F6: -11.41136 | G6: NaN | H6: NaN | I6: NaN | J6: NaN
A7: 23270 | B7: 678.57143 | C7: 41.86081 | D7: -375.89592 | E7: 40.26009 | F7: -11.46529 | G7: NaN | H7: NaN | I7: NaN | J7: NaN
A8: 27644 | B8: 614.28571 | C8: 42.5347 | D8: -376.61921 | E8: 40.75789 | F8: -12.16534 | G8: NaN | H8: NaN | I8: NaN | J8: NaN
A9: 32232 | B9: 550 | C9: 43.33088 | D9: -376.85855 | E9: 41.46867 | F9: -12.56639 | G9: NaN | H9: NaN | I9: NaN | J9: NaN
A10: 36788 | B10: 485.71429 | C10: 44.13157 | D10: -377.85096 | E10: 42.00695 | F10: -13.52818 | G10: NaN | H10: NaN | I10: NaN | J10: NaN
A11: 41392 | B11: 421.42857 | C11: 45.43518 | D11: -378.51205 | E11: 43.08423 | F11: -14.42585 | G11: NaN | H11: NaN | I11: NaN | J11: NaN
A12: 46014 | B12: 357.14286 | C12: 46.57548 | D12: -379.93091 | E12: 43.78581 | F12: -15.87696 | G12: NaN | H12: NaN | I12: NaN | J12: NaN
A13: 50451 | B13: 292.85714 | C13: 48.35538 | D13: -21.86707 | E13: 44.87623 | F13: -18.01017 | G13: NaN | H13: NaN | I13: NaN | J13: NaN
... A55: 400548 | B55: 0.1 | C55: 525.98322 | D55: 0.94589 | E55: 525.91155 | F55: 8.683 | G55: NaN | H55: NaN | I55: NaN | J55: NaN

Sheet I40_P400_T60_HR50
A1: Temps (ms) | B1: Fr駲uence (Hz) | C1: Module de Z (mOhm) | D1: d駱hasage de Z (ｰ) | E1: Partie r馥lle | F1: Partie imaginaire | G1: Module de Zstack (mOhm) | H1: d駱hasage de Zstack (ｰ) | I1: Partie r馥lle stack | J1: Partie imaginaire stack
A2: 0 | B2: 1000 | C2: 39.12743 | D2: -14.43967 | E2: 37.89143 | F2: -9.75683 | G2: NaN | H2: NaN | I2: NaN | J2: NaN
A3: 4758 | B3: 935.71429 | C3: 39.4396 | D3: -14.1786 | E3: 38.23815 | F3: -9.66054 | G3: NaN | H3: NaN | I3: NaN | J3: NaN
A4: 10009 | B4: 871.42857 | C4: 40.02725 | D4: -13.94606 | E4: 38.84737 | F4: -9.6469 | G4: NaN | H4: NaN | I4: NaN | J4: NaN
A5: 15148 | B5: 807.14286 | C5: 40.6842 | D5: -15.32836 | E5: 39.23693 | F5: -10.75489 | G5: NaN | H5: NaN | I5: NaN | J5: NaN
A6: 20344 | B6: 742.85714 | C6: 41.02761 | D6: -375.25727 | E6: 39.58155 | F6: -10.79656 | G6: NaN | H6: NaN | I6: NaN | J6: NaN
A7: 25575 | B7: 678.57143 | C7: 41.60219 | D7: -375.86763 | E7: 40.01698 | F7: -11.3747 | G7: NaN | H7: NaN | I7: NaN | J7: NaN
A8: 31785 | B8: 614.28571 | C8: 42.12328 | D8: -376.24838 | E8: 40.44079 | F8: -11.78617 | G8: NaN | H8: NaN | I8: NaN | J8: NaN
A9: 36582 | B9: 550 | C9: 42.76427 | D9: -376.90336 | E9: 40.9167 | F9: -12.43407 | G9: NaN | H9: NaN | I9: NaN | J9: NaN
A10: 41182 | B10: 485.71429 | C10: 43.73728 | D10: -377.56296 | E10: 41.69851 | F10: -13.19788 | G10: NaN | H10: NaN | I10: NaN | J10: NaN
A11: 46387 | B11: 421.42857 | C11: 44.98384 | D11: -378.65919 | E11: 42.61942 | F11: -14.39205 | G11: NaN | H11: NaN | I11: NaN | J11: NaN
A12: 51594 | B12: 357.14286 | C12: 45.95479 | D12: -379.92078 | E12: 43.20507 | F12: -15.65774 | G12: NaN | H12: NaN | I12: NaN | J12: NaN
A13: 56840 | B13: 292.85714 | C13: 47.75544 | D13: -21.6783 | E13: 44.37782 | F13: -17.64062 | G13: NaN | H13: NaN | I13: NaN | J13: NaN
... A55: 413369 | B55: 0.1 | C55: 452.44105 | D55: 0.65499 | E55: 452.41148 | F55: 5.17205 | G55: NaN | H55: NaN | I55: NaN | J55: NaN

Sheet I40_P500_T60_HR50
A1: Temps (ms) | B1: Fr駲uence (Hz) | C1: Module de Z (mOhm) | D1: d駱hasage de Z (ｰ) | E1: Partie r馥lle | F1: Partie imaginaire | G1: Module de Zstack (mOhm) | H1: d駱hasage de Zstack (ｰ) | I1: Partie r馥lle stack | J1: Partie imaginaire stack
A2: 0 | B2: 1000 | C2: 38.63611 | D2: -13.32281 | E2: 37.5963 | F2: -8.9032 | G2: NaN | H2: NaN | I2: NaN | J2: NaN
A3: 5148 | B3: 935.71429 | C3: 38.7807 | D3: -13.89344 | E3: 37.64613 | F3: -9.3119 | G3: NaN | H3: NaN | I3: NaN | J3: NaN
A4: 10204 | B4: 871.42857 | C4: 39.32438 | D4: -15.23409 | E4: 37.94253 | F4: -10.333 | G4: NaN | H4: NaN | I4: NaN | J4: NaN
A5: 15331 | B5: 807.14286 | C5: 39.88577 | D5: -14.61948 | E5: 38.5944 | F5: -10.0671 | G5: NaN | H5: NaN | I5: NaN | J5: NaN
A6: 20524 | B6: 742.85714 | C6: 40.50355 | D6: -375.47729 | E6: 39.03474 | F6: -10.80863 | G6: NaN | H6: NaN | I6: NaN | J6: NaN
A7: 25763 | B7: 678.57143 | C7: 40.90498 | D7: -375.89809 | E7: 39.34039 | F7: -11.20498 | G7: NaN | H7: NaN | I7: NaN | J7: NaN
A8: 30964 | B8: 614.28571 | C8: 41.70499 | D8: -375.45734 | E8: 40.19649 | F8: -11.11525 | G8: NaN | H8: NaN | I8: NaN | J8: NaN
A9: 36204 | B9: 550 | C9: 42.23554 | D9: -376.41858 | E9: 40.51328 | F9: -11.93798 | G9: NaN | H9: NaN | I9: NaN | J9: NaN
A10: 41422 | B10: 485.71429 | C10: 42.89494 | D10: -377.18274 | E10: 40.98043 | F10: -12.67204 | G10: NaN | H10: NaN | I10: NaN | J10: NaN
A11: 46698 | B11: 421.42857 | C11: 44.12737 | D11: -378.24313 | E11: 41.90938 | F11: -13.81407 | G11: NaN | H11: NaN | I11: NaN | J11: NaN
A12: 51762 | B12: 357.14286 | C12: 45.35245 | D12: -379.0194 | E12: 42.87658 | F12: -14.77983 | G12: NaN | H12: NaN | I12: NaN | J12: NaN
A13: 57064 | B13: 292.85714 | C13: 46.81231 | D13: -20.82668 | E13: 43.7536 | F13: -16.64375 | G13: NaN | H13: NaN | I13: NaN | J13: NaN
... A55: 419306 | B55: 0.1 | C55: 402.87348 | D55: 0.57367 | E55: 402.85329 | F55: 4.03369 | G55: NaN | H55: NaN | I55: NaN | J55: NaN

Sheet I45_P300_T60_HR50
A1: Temps (ms) | B1: Fr駲uence (Hz) | C1: Module de Z (mOhm) | D1: d駱hasage de Z (ｰ) | E1: Partie r馥lle | F1: Partie imaginaire | G1: Module de Zstack (mOhm) | H1: d駱hasage de Zstack (ｰ) | I1: Partie r馥lle stack | J1: Partie imaginaire stack
A2: 0 | B2: 1000 | C2: 40.10679 | D2: -14.53659 | E2: 38.82287 | F2: -10.06673 | G2: NaN | H2: NaN | I2: NaN | J2: NaN
A3: 5793 | B3: 935.71429 | C3: 40.79124 | D3: -14.1679 | E3: 39.55048 | F3: -9.98424 | G3: NaN | H3: NaN | I3: NaN | J3: NaN
A4: 11632 | B4: 871.42857 | C4: 41.1619 | D4: -15.00802 | E4: 39.75785 | F4: -10.65905 | G4: NaN | H4: NaN | I4: NaN | J4: NaN
A5: 17416 | B5: 807.14286 | C5: 41.74497 | D5: -14.69422 | E5: 40.37963 | F5: -10.58905 | G5: NaN | H5: NaN | I5: NaN | J5: NaN
A6: 23233 | B6: 742.85714 | C6: 42.3603 | D6: -375.03118 | E6: 40.91093 | F6: -10.98592 | G6: NaN | H6: NaN | I6: NaN | J6: NaN
A7: 29078 | B7: 678.57143 | C7: 43.06095 | D7: -375.86147 | E7: 41.42142 | F7: -11.76909 | G7: NaN | H7: NaN | I7: NaN | J7: NaN
A8: 34956 | B8: 614.28571 | C8: 43.43179 | D8: -376.18123 | E8: 41.71124 | F8: -12.10342 | G8: NaN | H8: NaN | I8: NaN | J8: NaN
A9: 40837 | B9: 550 | C9: 44.36065 | D9: -376.88819 | E9: 42.44753 | F9: -12.88699 | G9: NaN | H9: NaN | I9: NaN | J9: NaN
A10: 46724 | B10: 485.71429 | C10: 45.33452 | D10: -378.14174 | E10: 43.08091 | F10: -14.11575 | G10: NaN | H10: NaN | I10: NaN | J10: NaN
A11: 52619 | B11: 421.42857 | C11: 46.51405 | D11: -378.74577 | E11: 44.04665 | F11: -14.9482 | G11: NaN | H11: NaN | I11: NaN | J11: NaN
A12: 58380 | B12: 357.14286 | C12: 47.58697 | D12: -379.91691 | E12: 44.74068 | F12: -16.21084 | G12: NaN | H12: NaN | I12: NaN | J12: NaN
A13: 64276 | B13: 292.85714 | C13: 49.14022 | D13: -22.36613 | E13: 45.44346 | F13: -18.69902 | G13: NaN | H13: NaN | I13: NaN | J13: NaN
... A55: 448555 | B55: 0.1 | C55: 701.07972 | D55: 1.43145 | E55: 700.86093 | F55: 17.51361 | G55: NaN | H55: NaN | I55: NaN | J55: NaN

Sheet I45_P400_T60_HR50
A1: Temps (ms) | B1: Fr駲uence (Hz) | C1: Module de Z (mOhm) | D1: d駱hasage de Z (ｰ) | E1: Partie r馥lle | F1: Partie imaginaire | G1: Module de Zstack (mOhm) | H1: d駱hasage de Zstack (ｰ) | I1: Partie r馥lle stack | J1: Partie imaginaire stack
A2: 0 | B2: 1000 | C2: 39.5059 | D2: -13.73152 | E2: 38.37677 | F2: -9.37762 | G2: NaN | H2: NaN | I2: NaN | J2: NaN
A3: 5790 | B3: 935.71429 | C3: 39.63497 | D3: -14.4486 | E3: 38.38139 | F3: -9.88938 | G3: NaN | H3: NaN | I3: NaN | J3: NaN
A4: 11611 | B4: 871.42857 | C4: 40.52366 | D4: -14.22764 | E4: 39.28067 | F4: -9.9597 | G4: NaN | H4: NaN | I4: NaN | J4: NaN
A5: 17393 | B5: 807.14286 | C5: 40.76205 | D5: -14.84652 | E5: 39.40124 | F5: -10.44449 | G5: NaN | H5: NaN | I5: NaN | J5: NaN
A6: 23237 | B6: 742.85714 | C6: 41.22406 | D6: -375.10752 | E6: 39.79929 | F6: -10.74428 | G6: NaN | H6: NaN | I6: NaN | J6: NaN
A7: 28431 | B7: 678.57143 | C7: 41.71473 | D7: -375.93652 | E7: 40.11149 | F7: -11.4537 | G7: NaN | H7: NaN | I7: NaN | J7: NaN
A8: 33616 | B8: 614.28571 | C8: 42.46588 | D8: -376.25677 | E8: 40.76795 | F8: -11.888 | G8: NaN | H8: NaN | I8: NaN | J8: NaN
A9: 39449 | B9: 550 | C9: 43.17826 | D9: -377.14466 | E9: 41.25957 | F9: -12.72832 | G9: NaN | H9: NaN | I9: NaN | J9: NaN
A10: 44653 | B10: 485.71429 | C10: 44.08757 | D10: -377.62531 | E10: 42.01796 | F10: -13.34931 | G10: NaN | H10: NaN | I10: NaN | J10: NaN
A11: 49880 | B11: 421.42857 | C11: 44.85497 | D11: -378.78904 | E11: 42.46469 | F11: -14.44709 | G11: NaN | H11: NaN | I11: NaN | J11: NaN
A12: 55727 | B12: 357.14286 | C12: 46.2573 | D12: -379.82625 | E12: 43.51542 | F12: -15.68904 | G12: NaN | H12: NaN | I12: NaN | J12: NaN
A13: 61616 | B13: 292.85714 | C13: 47.93247 | D13: -21.66443 | E13: 44.54662 | F13: -17.69523 | G13: NaN | H13: NaN | I13: NaN | J13: NaN
... A55: 442154 | B55: 0.1 | C55: 634.68029 | D55: 1.5292 | E55: 634.45425 | F55: 16.93729 | G55: NaN | H55: NaN | I55: NaN | J55: NaN

Sheet I45_P500_T60_HR50
A1: Temps (ms) | B1: Fr駲uence (Hz) | C1: Module de Z (mOhm) | D1: d駱hasage de Z (ｰ) | E1: Partie r馥lle | F1: Partie imaginaire | G1: Module de Zstack (mOhm) | H1: d駱hasage de Zstack (ｰ) | I1: Partie r馥lle stack | J1: Partie imaginaire stack
A2: 0 | B2: 1000 | C2: 38.65011 | D2: -14.17734 | E2: 37.47292 | F2: -9.46634 | G2: NaN | H2: NaN | I2: NaN | J2: NaN
A3: 6607 | B3: 935.71429 | C3: 39.07355 | D3: -14.15471 | E3: 37.88723 | F3: -9.55509 | G3: NaN | H3: NaN | I3: NaN | J3: NaN
A4: 11615 | B4: 871.42857 | C4: 40.0609 | D4: -14.77405 | E4: 38.73644 | F4: -10.21584 | G4: NaN | H4: NaN | I4: NaN | J4: NaN
A5: 16990 | B5: 807.14286 | C5: 40.06029 | D5: -15.14953 | E5: 38.66808 | F5: -10.46932 | G5: NaN | H5: NaN | I5: NaN | J5: NaN
A6: 22220 | B6: 742.85714 | C6: 40.72185 | D6: -375.31324 | E6: 39.27608 | F6: -10.75448 | G6: NaN | H6: NaN | I6: NaN | J6: NaN
A7: 27236 | B7: 678.57143 | C7: 41.36561 | D7: -375.69639 | E7: 39.82304 | F7: -11.19104 | G7: NaN | H7: NaN | I7: NaN | J7: NaN
A8: 32467 | B8: 614.28571 | C8: 41.84228 | D8: -376.27286 | E8: 40.166 | F8: -11.72471 | G8: NaN | H8: NaN | I8: NaN | J8: NaN
A9: 37752 | B9: 550 | C9: 42.51086 | D9: -377.00883 | E9: 40.65142 | F9: -12.43524 | G9: NaN | H9: NaN | I9: NaN | J9: NaN
A10: 42985 | B10: 485.71429 | C10: 43.00624 | D10: -377.85258 | E10: 40.93542 | F10: -13.18438 | G10: NaN | H10: NaN | I10: NaN | J10: NaN
A11: 48197 | B11: 421.42857 | C11: 44.30754 | D11: -378.71005 | E11: 41.96606 | F11: -14.21293 | G11: NaN | H11: NaN | I11: NaN | J11: NaN
A12: 53254 | B12: 357.14286 | C12: 45.7179 | D12: -379.7748 | E12: 43.0219 | F12: -15.46747 | G12: NaN | H12: NaN | I12: NaN | J12: NaN
A13: 58562 | B13: 292.85714 | C13: 47.29133 | D13: -21.8544 | E13: 43.89263 | F13: -17.60416 | G13: NaN | H13: NaN | I13: NaN | J13: NaN
... A55: 430478 | B55: 0.1 | C55: 541.67478 | D55: 1.51984 | E55: 541.48422 | F55: 14.36694 | G55: NaN | H55: NaN | I55: NaN | J55: NaN

Sheet I50_P300_T60_HR50
A1: Temps (ms) | B1: Fr駲uence (Hz) | C1: Module de Z (mOhm) | D1: d駱hasage de Z (ｰ) | E1: Partie r馥lle | F1: Partie imaginaire | G1: Module de Zstack (mOhm) | H1: d駱hasage de Zstack (ｰ) | I1: Partie r馥lle stack | J1: Partie imaginaire stack
A2: 0 | B2: 1000 | C2: 42.55811 | D2: -15.35512 | E2: 41.03892 | F2: -11.26943 | G2: NaN | H2: NaN | I2: NaN | J2: NaN
A3: 5804 | B3: 935.71429 | C3: 42.91615 | D3: -15.41608 | E3: 41.37207 | F3: -11.40826 | G3: NaN | H3: NaN | I3: NaN | J3: NaN
A4: 11653 | B4: 871.42857 | C4: 43.73783 | D4: -15.7364 | E4: 42.09852 | F4: -11.86222 | G4: NaN | H4: NaN | I4: NaN | J4: NaN
A5: 17628 | B5: 807.14286 | C5: 44.06566 | D5: -15.8614 | E5: 42.38789 | F5: -12.04364 | G5: NaN | H5: NaN | I5: NaN | J5: NaN
A6: 23492 | B6: 742.85714 | C6: 44.65764 | D6: -376.27132 | E6: 42.8689 | F6: -12.51246 | G6: NaN | H6: NaN | I6: NaN | J6: NaN
A7: 29318 | B7: 678.57143 | C7: 45.32144 | D7: -376.37049 | E7: 43.48407 | F7: -12.77373 | G7: NaN | H7: NaN | I7: NaN | J7: NaN
A8: 35126 | B8: 614.28571 | C8: 45.82239 | D8: -377.04935 | E8: 43.80861 | F8: -13.43491 | G8: NaN | H8: NaN | I8: NaN | J8: NaN
A9: 40967 | B9: 550 | C9: 46.62431 | D9: -377.59586 | E9: 44.44287 | F9: -14.09457 | G9: NaN | H9: NaN | I9: NaN | J9: NaN
A10: 46803 | B10: 485.71429 | C10: 47.4398 | D10: -378.43131 | E10: 45.0063 | F10: -14.99893 | G10: NaN | H10: NaN | I10: NaN | J10: NaN
A11: 52629 | B11: 421.42857 | C11: 48.66279 | D11: -379.50273 | E11: 45.87079 | F11: -16.24616 | G11: NaN | H11: NaN | I11: NaN | J11: NaN
A12: 58491 | B12: 357.14286 | C12: 50.1262 | D12: -380.63703 | E12: 46.9097 | F12: -17.6668 | G12: NaN | H12: NaN | I12: NaN | J12: NaN
A13: 64368 | B13: 292.85714 | C13: 51.74937 | D13: -22.71918 | E13: 47.73407 | F13: -19.98637 | G13: NaN | H13: NaN | I13: NaN | J13: NaN
... A55: 456558 | B55: 0.1 | C55: 1118.9203 | D55: 0.89997 | E55: 1118.7822 | F55: 17.57463 | G55: NaN | H55: NaN | I55: NaN | J55: NaN

Sheet I50_P400_T60_HR50
A1: Temps (ms) | B1: Fr駲uence (Hz) | C1: Module de Z (mOhm) | D1: d駱hasage de Z (ｰ) | E1: Partie r馥lle | F1: Partie imaginaire | G1: Module de Zstack (mOhm) | H1: d駱hasage de Zstack (ｰ) | I1: Partie r馥lle stack | J1: Partie imaginaire stack
A2: 0 | B2: 1000 | C2: 41.22833 | D2: -14.4203 | E2: 39.92943 | F2: -10.26722 | G2: NaN | H2: NaN | I2: NaN | J2: NaN
A3: 5975 | B3: 935.71429 | C3: 41.64581 | D3: -15.35761 | E3: 40.15871 | F3: -11.02959 | G3: NaN | H3: NaN | I3: NaN | J3: NaN
A4: 12442 | B4: 871.42857 | C4: 42.26597 | D4: -14.95609 | E4: 40.83417 | F4: -10.90795 | G4: NaN | H4: NaN | I4: NaN | J4: NaN
A5: 18230 | B5: 807.14286 | C5: 42.65046 | D5: -15.67394 | E5: 41.0645 | F5: -11.52256 | G5: NaN | H5: NaN | I5: NaN | J5: NaN
A6: 24077 | B6: 742.85714 | C6: 43.17035 | D6: -375.56754 | E6: 41.58663 | F6: -11.5858 | G6: NaN | H6: NaN | I6: NaN | J6: NaN
A7: 29965 | B7: 678.57143 | C7: 43.93839 | D7: -376.04603 | E7: 42.22655 | F7: -12.14499 | G7: NaN | H7: NaN | I7: NaN | J7: NaN
A8: 36427 | B8: 614.28571 | C8: 44.60722 | D8: -376.6933 | E8: 42.7273 | F8: -12.81336 | G8: NaN | H8: NaN | I8: NaN | J8: NaN
A9: 42296 | B9: 550 | C9: 45.10702 | D9: -377.32572 | E9: 43.06038 | F9: -13.43303 | G9: NaN | H9: NaN | I9: NaN | J9: NaN
A10: 48148 | B10: 485.71429 | C10: 46.15344 | D10: -377.90141 | E10: 43.91901 | F10: -14.18665 | G10: NaN | H10: NaN | I10: NaN | J10: NaN
A11: 54186 | B11: 421.42857 | C11: 46.87542 | D11: -378.47456 | E11: 44.45966 | F11: -14.85405 | G11: NaN | H11: NaN | I11: NaN | J11: NaN
A12: 60661 | B12: 357.14286 | C12: 48.12454 | D12: -379.53306 | E12: 45.35491 | F12: -16.09047 | G12: NaN | H12: NaN | I12: NaN | J12: NaN
A13: 67119 | B13: 292.85714 | C13: 49.76878 | D13: -21.93864 | E13: 46.16475 | F13: -18.59428 | G13: NaN | H13: NaN | I13: NaN | J13: NaN
... A55: 465260 | B55: 0.1 | C55: 927.39388 | D55: 1.10449 | E55: 927.22158 | F55: 17.87623 | G55: NaN | H55: NaN | I55: NaN | J55: NaN

Sheet I50_P500_T60_HR50
A1: Temps (ms) | B1: Fr駲uence (Hz) | C1: Module de Z (mOhm) | D1: d駱hasage de Z (ｰ) | E1: Partie r馥lle | F1: Partie imaginaire | G1: Module de Zstack (mOhm) | H1: d駱hasage de Zstack (ｰ) | I1: Partie r馥lle stack | J1: Partie imaginaire stack
A2: 0 | B2: 1000 | C2: 39.6821 | D2: -13.82344 | E2: 38.53278 | F2: -9.48127 | G2: NaN | H2: NaN | I2: NaN | J2: NaN
A3: 6225 | B3: 935.71429 | C3: 40.16931 | D3: -14.43294 | E3: 38.90157 | F3: -10.01207 | G3: NaN | H3: NaN | I3: NaN | J3: NaN
A4: 12691 | B4: 871.42857 | C4: 41.11236 | D4: -15.02495 | E4: 39.70685 | F4: -10.65795 | G4: NaN | H4: NaN | I4: NaN | J4: NaN
A5: 19339 | B5: 807.14286 | C5: 41.61668 | D5: -15.22597 | E5: 40.15584 | F5: -10.92965 | G5: NaN | H5: NaN | I5: NaN | J5: NaN
A6: 25795 | B6: 742.85714 | C6: 42.25578 | D6: -375.40089 | E6: 40.73843 | F6: -11.22191 | G6: NaN | H6: NaN | I6: NaN | J6: NaN
A7: 32309 | B7: 678.57143 | C7: 42.63095 | D7: -375.46309 | E7: 41.08781 | F7: -11.36616 | G7: NaN | H7: NaN | I7: NaN | J7: NaN
A8: 38762 | B8: 614.28571 | C8: 43.26097 | D8: -376.39666 | E8: 41.50156 | F8: -12.21194 | G8: NaN | H8: NaN | I8: NaN | J8: NaN
A9: 45245 | B9: 550 | C9: 43.84778 | D9: -376.87188 | E9: 41.9604 | F9: -12.72606 | G9: NaN | H9: NaN | I9: NaN | J9: NaN
A10: 51734 | B10: 485.71429 | C10: 44.68094 | D10: -377.67062 | E10: 42.57277 | F10: -13.56265 | G10: NaN | H10: NaN | I10: NaN | J10: NaN
A11: 58344 | B11: 421.42857 | C11: 45.93354 | D11: -378.60511 | E11: 43.53305 | F11: -14.65481 | G11: NaN | H11: NaN | I11: NaN | J11: NaN
A12: 64864 | B12: 357.14286 | C12: 47.03844 | D12: -380.0368 | E12: 44.19133 | F12: -16.11648 | G12: NaN | H12: NaN | I12: NaN | J12: NaN
A13: 71357 | B13: 292.85714 | C13: 48.71876 | D13: -21.32388 | E13: 45.38346 | F13: -17.71607 | G13: NaN | H13: NaN | I13: NaN | J13: NaN
... A55: 477803 | B55: 0.1 | C55: 727.49962 | D55: 1.0288 | E55: 727.38234 | F55: 13.06218 | G55: NaN | H55: NaN | I55: NaN | J55: NaN

Sheet I10_P300_T60_HR0
A1: Temps (ms) | B1: Fr駲uence (Hz) | C1: Module de Z (mOhm) | D1: d駱hasage de Z (ｰ) | E1: Partie r馥lle | F1: Partie imaginaire | G1: Module de Zstack (mOhm) | H1: d駱hasage de Zstack (ｰ) | I1: Partie r馥lle stack | J1: Partie imaginaire stack
A2: 0 | B2: 1000 | C2: 40.57362 | D2: -13.96044 | E2: 39.37518 | F2: -9.78847 | G2: NaN | H2: NaN | I2: NaN | J2: NaN
A3: 2834 | B3: 935.71429 | C3: 40.44272 | D3: -14.32703 | E3: 39.18492 | F3: -10.0078 | G3: NaN | H3: NaN | I3: NaN | J3: NaN
A4: 5533 | B4: 871.42857 | C4: 42.28921 | D4: -13.26156 | E4: 41.16148 | F4: -9.70101 | G4: NaN | H4: NaN | I4: NaN | J4: NaN
A5: 8160 | B5: 807.14286 | C5: 42.62855 | D5: -14.77546 | E5: 41.21894 | F5: -10.87163 | G5: NaN | H5: NaN | I5: NaN | J5: NaN
A6: 11235 | B6: 742.85714 | C6: 42.4662 | D6: -375.32062 | E6: 40.95705 | F6: -11.22043 | G6: NaN | H6: NaN | I6: NaN | J6: NaN
A7: 13911 | B7: 678.57143 | C7: 43.14256 | D7: -375.00924 | E7: 41.67071 | F7: -11.17284 | G7: NaN | H7: NaN | I7: NaN | J7: NaN
A8: 16477 | B8: 614.28571 | C8: 44.1673 | D8: -376.16456 | E8: 42.42119 | F8: -12.29605 | G8: NaN | H8: NaN | I8: NaN | J8: NaN
A9: 19178 | B9: 550 | C9: 44.62022 | D9: -376.45541 | E9: 42.7926 | F9: -12.63953 | G9: NaN | H9: NaN | I9: NaN | J9: NaN
A10: 21677 | B10: 485.71429 | C10: 45.72098 | D10: -377.26019 | E10: 43.66204 | F10: -13.56594 | G10: NaN | H10: NaN | I10: NaN | J10: NaN
A11: 24401 | B11: 421.42857 | C11: 46.94979 | D11: -378.52153 | E11: 44.51799 | F11: -14.91412 | G11: NaN | H11: NaN | I11: NaN | J11: NaN
A12: 27536 | B12: 357.14286 | C12: 48.38648 | D12: -379.14719 | E12: 45.7097 | F12: -15.87058 | G12: NaN | H12: NaN | I12: NaN | J12: NaN
A13: 30079 | B13: 292.85714 | C13: 50.06751 | D13: -20.86864 | E13: 46.78306 | F13: -17.83538 | G13: NaN | H13: NaN | I13: NaN | J13: NaN
... A55: 318239 | B55: 0.1 | C55: 280.43197 | D55: -1.54713 | E55: 280.32974 | F55: -7.57146 | G55: NaN | H55: NaN | I55: NaN | J55: NaN

Sheet I20_P300_T60_HR0
A1: Temps (ms) | B1: Fr駲uence (Hz) | C1: Module de Z (mOhm) | D1: d駱hasage de Z (ｰ) | E1: Partie r馥lle | F1: Partie imaginaire | G1: Module de Zstack (mOhm) | H1: d駱hasage de Zstack (ｰ) | I1: Partie r馥lle stack | J1: Partie imaginaire stack
A2: 0 | B2: 1000 | C2: 40.56194 | D2: -13.32737 | E2: 39.46956 | F2: -9.35012 | G2: NaN | H2: NaN | I2: NaN | J2: NaN
A3: 3344 | B3: 935.71429 | C3: 41.49061 | D3: -14.2945 | E3: 40.20604 | F3: -10.24428 | G3: NaN | H3: NaN | I3: NaN | J3: NaN
A4: 6625 | B4: 871.42857 | C4: 41.56974 | D4: -15.81894 | E4: 39.99541 | F4: -11.33184 | G4: NaN | H4: NaN | I4: NaN | J4: NaN
A5: 9880 | B5: 807.14286 | C5: 43.09137 | D5: -14.65905 | E5: 41.6887 | F5: -10.90498 | G5: NaN | H5: NaN | I5: NaN | J5: NaN
A6: 12987 | B6: 742.85714 | C6: 42.74404 | D6: -375.671 | E6: 41.15518 | F6: -11.54573 | G6: NaN | H6: NaN | I6: NaN | J6: NaN
A7: 16288 | B7: 678.57143 | C7: 43.9559 | D7: -375.14136 | E7: 42.42994 | F7: -11.48134 | G7: NaN | H7: NaN | I7: NaN | J7: NaN
A8: 19622 | B8: 614.28571 | C8: 44.25413 | D8: -375.93612 | E8: 42.55337 | F8: -12.15065 | G8: NaN | H8: NaN | I8: NaN | J8: NaN
A9: 22764 | B9: 550 | C9: 45.43342 | D9: -376.78686 | E9: 43.49731 | F9: -13.12173 | G9: NaN | H9: NaN | I9: NaN | J9: NaN
A10: 26092 | B10: 485.71429 | C10: 46.48636 | D10: -377.16914 | E10: 44.41481 | F10: -13.72247 | G10: NaN | H10: NaN | I10: NaN | J10: NaN
A11: 29234 | B11: 421.42857 | C11: 47.09646 | D11: -378.43433 | E11: 44.67978 | F11: -14.89272 | G11: NaN | H11: NaN | I11: NaN | J11: NaN
A12: 32621 | B12: 357.14286 | C12: 49.1452 | D12: -379.16014 | E12: 46.4228 | F12: -16.12992 | G12: NaN | H12: NaN | I12: NaN | J12: NaN
A13: 35834 | B13: 292.85714 | C13: 51.0226 | D13: -20.20933 | E13: 47.88149 | F13: -17.62581 | G13: NaN | H13: NaN | I13: NaN | J13: NaN
... A55: 329124 | B55: 0.1 | C55: 211.50734 | D55: 1.08338 | E55: 211.46953 | F55: 3.99904 | G55: NaN | H55: NaN | I55: NaN | J55: NaN

Sheet I30_P300_T60_HR0
A1: Temps (ms) | B1: Fr駲uence (Hz) | C1: Module de Z (mOhm) | D1: d駱hasage de Z (ｰ) | E1: Partie r馥lle | F1: Partie imaginaire | G1: Module de Zstack (mOhm) | H1: d駱hasage de Zstack (ｰ) | I1: Partie r馥lle stack | J1: Partie imaginaire stack
A2: 0 | B2: 1000 | C2: 42.87672 | D2: -15.59451 | E2: 41.29835 | F2: -11.52644 | G2: NaN | H2: NaN | I2: NaN | J2: NaN
A3: 3464 | B3: 935.71429 | C3: 42.83816 | D3: -14.92393 | E3: 41.39316 | F3: -11.03239 | G3: NaN | H3: NaN | I3: NaN | J3: NaN
A4: 6793 | B4: 871.42857 | C4: 44.1977 | D4: -15.97243 | E4: 42.49141 | F4: -12.16209 | G4: NaN | H4: NaN | I4: NaN | J4: NaN
A5: 10059 | B5: 807.14286 | C5: 44.38416 | D5: -15.72968 | E5: 42.72204 | F5: -12.03251 | G5: NaN | H5: NaN | I5: NaN | J5: NaN
A6: 13168 | B6: 742.85714 | C6: 44.59741 | D6: -375.51517 | E6: 42.97226 | F6: -11.92952 | G6: NaN | H6: NaN | I6: NaN | J6: NaN
A7: 16490 | B7: 678.57143 | C7: 45.34665 | D7: -375.50022 | E7: 43.69736 | F7: -12.11853 | G7: NaN | H7: NaN | I7: NaN | J7: NaN
A8: 19821 | B8: 614.28571 | C8: 45.9949 | D8: -376.94364 | E8: 43.99835 | F8: -13.40433 | G8: NaN | H8: NaN | I8: NaN | J8: NaN
A9: 23165 | B9: 550 | C9: 46.98036 | D9: -376.88944 | E9: 44.95396 | F9: -13.64901 | G9: NaN | H9: NaN | I9: NaN | J9: NaN
A10: 26301 | B10: 485.71429 | C10: 48.40706 | D10: -377.99166 | E10: 46.04003 | F10: -14.9519 | G10: NaN | H10: NaN | I10: NaN | J10: NaN
A11: 29466 | B11: 421.42857 | C11: 49.51582 | D11: -378.59644 | E11: 46.93052 | F11: -15.79062 | G11: NaN | H11: NaN | I11: NaN | J11: NaN
A12: 32817 | B12: 357.14286 | C12: 50.90295 | D12: -379.7594 | E12: 47.90581 | F12: -17.20882 | G12: NaN | H12: NaN | I12: NaN | J12: NaN
A13: 35984 | B13: 292.85714 | C13: 53.17772 | D13: -21.00383 | E13: 49.64441 | F13: -19.06051 | G13: NaN | H13: NaN | I13: NaN | J13: NaN
... A55: 335853 | B55: 0.1 | C55: 292.01231 | D55: 0.95789 | E55: 291.9715 | F55: 4.88175 | G55: NaN | H55: NaN | I55: NaN | J55: NaN

Sheet I35_P300_T60_HR0
A1: Temps (ms) | B1: Fr駲uence (Hz) | C1: Module de Z (mOhm) | D1: d駱hasage de Z (ｰ) | E1: Partie r馥lle | F1: Partie imaginaire | G1: Module de Zstack (mOhm) | H1: d駱hasage de Zstack (ｰ) | I1: Partie r馥lle stack | J1: Partie imaginaire stack
A2: 0 | B2: 1000 | C2: 43.14276 | D2: -15.51303 | E2: 41.57105 | F2: -11.53886 | G2: NaN | H2: NaN | I2: NaN | J2: NaN
A3: 3616 | B3: 935.71429 | C3: 43.43108 | D3: -15.38815 | E3: 41.87409 | F3: -11.52473 | G3: NaN | H3: NaN | I3: NaN | J3: NaN
A4: 6904 | B4: 871.42857 | C4: 44.10929 | D4: -15.51645 | E4: 42.50167 | F4: -11.7999 | G4: NaN | H4: NaN | I4: NaN | J4: NaN
A5: 10143 | B5: 807.14286 | C5: 44.7084 | D5: -16.43574 | E5: 42.88151 | F5: -12.64979 | G5: NaN | H5: NaN | I5: NaN | J5: NaN
A6: 13428 | B6: 742.85714 | C6: 44.9153 | D6: -376.36716 | E6: 43.09514 | F6: -12.65675 | G6: NaN | H6: NaN | I6: NaN | J6: NaN
A7: 16574 | B7: 678.57143 | C7: 45.53034 | D7: -376.00719 | E7: 43.765 | F7: -12.55536 | G7: NaN | H7: NaN | I7: NaN | J7: NaN
A8: 19900 | B8: 614.28571 | C8: 46.57609 | D8: -376.85433 | E8: 44.57542 | F8: -13.50425 | G8: NaN | H8: NaN | I8: NaN | J8: NaN
A9: 23221 | B9: 550 | C9: 47.17501 | D9: -377.41195 | E9: 45.01335 | F9: -14.11664 | G9: NaN | H9: NaN | I9: NaN | J9: NaN
A10: 26338 | B10: 485.71429 | C10: 48.16471 | D10: -378.2366 | E10: 45.74551 | F10: -15.07274 | G10: NaN | H10: NaN | I10: NaN | J10: NaN
A11: 29723 | B11: 421.42857 | C11: 49.80449 | D11: -378.78967 | E11: 47.15028 | F11: -16.04178 | G11: NaN | H11: NaN | I11: NaN | J11: NaN
A12: 32883 | B12: 357.14286 | C12: 51.46157 | D12: -380.09125 | E12: 48.32997 | F12: -17.67789 | G12: NaN | H12: NaN | I12: NaN | J12: NaN
A13: 36237 | B13: 292.85714 | C13: 53.58082 | D13: -21.43096 | E13: 49.87616 | F13: -19.57735 | G13: NaN | H13: NaN | I13: NaN | J13: NaN
... A55: 345887 | B55: 0.1 | C55: 359.16759 | D55: 0.76531 | E55: 359.13555 | F55: 4.79734 | G55: NaN | H55: NaN | I55: NaN | J55: NaN

Sheet I40_P300_T60_HR0
A1: Temps (ms) | B1: Fr駲uence (Hz) | C1: Module de Z (mOhm) | D1: d駱hasage de Z (ｰ) | E1: Partie r馥lle | F1: Partie imaginaire | G1: Module de Zstack (mOhm) | H1: d駱hasage de Zstack (ｰ) | I1: Partie r馥lle stack | J1: Partie imaginaire stack
A2: 0 | B2: 1000 | C2: 43.77768 | D2: -15.09942 | E2: 42.26627 | F2: -11.40385 | G2: NaN | H2: NaN | I2: NaN | J2: NaN
A3: 3868 | B3: 935.71429 | C3: 43.91907 | D3: -15.68237 | E3: 42.28418 | F3: -11.87151 | G3: NaN | H3: NaN | I3: NaN | J3: NaN
A4: 7836 | B4: 871.42857 | C4: 44.79434 | D4: -15.55756 | E4: 43.15315 | F4: -12.01412 | G4: NaN | H4: NaN | I4: NaN | J4: NaN
A5: 11759 | B5: 807.14286 | C5: 45.15821 | D5: -16.20898 | E5: 43.36317 | F5: -12.60553 | G5: NaN | H5: NaN | I5: NaN | J5: NaN
A6: 15720 | B6: 742.85714 | C6: 45.69222 | D6: -375.96821 | E6: 43.92916 | F6: -12.57011 | G6: NaN | H6: NaN | I6: NaN | J6: NaN
A7: 19469 | B7: 678.57143 | C7: 46.71554 | D7: -376.66287 | E7: 44.75388 | F7: -13.3952 | G7: NaN | H7: NaN | I7: NaN | J7: NaN
A8: 23428 | B8: 614.28571 | C8: 47.65858 | D8: -377.13724 | E8: 45.54262 | F8: -14.04315 | G8: NaN | H8: NaN | I8: NaN | J8: NaN
A9: 27380 | B9: 550 | C9: 48.38698 | D9: -377.52731 | E9: 46.14054 | F9: -14.57224 | G9: NaN | H9: NaN | I9: NaN | J9: NaN
A10: 31351 | B10: 485.71429 | C10: 49.38116 | D10: -378.40795 | E10: 46.85444 | F10: -15.59362 | G10: NaN | H10: NaN | I10: NaN | J10: NaN
A11: 35159 | B11: 421.42857 | C11: 50.69388 | D11: -379.43714 | E11: 47.80469 | F11: -16.86953 | G11: NaN | H11: NaN | I11: NaN | J11: NaN
A12: 39170 | B12: 357.14286 | C12: 52.38475 | D12: -380.65132 | E12: 49.01871 | F12: -18.47505 | G12: NaN | H12: NaN | I12: NaN | J12: NaN
A13: 42994 | B13: 292.85714 | C13: 54.36435 | D13: -21.77564 | E13: 50.48511 | F13: -20.16771 | G13: NaN | H13: NaN | I13: NaN | J13: NaN
... A55: 359043 | B55: 0.1 | C55: 449.01203 | D55: 1.39974 | E55: 448.87805 | F55: 10.96828 | G55: NaN | H55: NaN | I55: NaN | J55: NaN

Sheet I45_P300_T60_HR0
A1: Temps (ms) | B1: Fr駲uence (Hz) | C1: Module de Z (mOhm) | D1: d駱hasage de Z (ｰ) | E1: Partie r馥lle | F1: Partie imaginaire | G1: Module de Zstack (mOhm) | H1: d駱hasage de Zstack (ｰ) | I1: Partie r馥lle stack | J1: Partie imaginaire stack
A2: 0 | B2: 1000 | C2: 45.73536 | D2: -15.65995 | E2: 44.03769 | F2: -12.34523 | G2: NaN | H2: NaN | I2: NaN | J2: NaN
A3: 4089 | B3: 935.71429 | C3: 45.84201 | D3: -15.4592 | E3: 44.18347 | F3: -12.21929 | G3: NaN | H3: NaN | I3: NaN | J3: NaN
A4: 8079 | B4: 871.42857 | C4: 46.21592 | D4: -15.98015 | E4: 44.43 | F4: -12.72344 | G4: NaN | H4: NaN | I4: NaN | J4: NaN
A5: 11946 | B5: 807.14286 | C5: 46.96736 | D5: -16.53818 | E5: 45.02433 | F5: -13.36946 | G5: NaN | H5: NaN | I5: NaN | J5: NaN
A6: 15948 | B6: 742.85714 | C6: 47.82378 | D6: -376.33186 | E6: 45.89405 | F6: -13.44806 | G6: NaN | H6: NaN | I6: NaN | J6: NaN
A7: 19663 | B7: 678.57143 | C7: 48.41349 | D7: -376.88968 | E7: 46.32522 | F7: -14.06556 | G7: NaN | H7: NaN | I7: NaN | J7: NaN
A8: 23609 | B8: 614.28571 | C8: 49.02273 | D8: -377.50311 | E8: 46.75301 | F8: -14.74396 | G8: NaN | H8: NaN | I8: NaN | J8: NaN
A9: 27544 | B9: 550 | C9: 49.7912 | D9: -378.19065 | E9: 47.30278 | F9: -15.54381 | G9: NaN | H9: NaN | I9: NaN | J9: NaN
A10: 31528 | B10: 485.71429 | C10: 51.19039 | D10: -378.66366 | E10: 48.49846 | F10: -16.38154 | G10: NaN | H10: NaN | I10: NaN | J10: NaN
A11: 35334 | B11: 421.42857 | C11: 52.55995 | D11: -379.54446 | E11: 49.53156 | F11: -17.58331 | G11: NaN | H11: NaN | I11: NaN | J11: NaN
A12: 39128 | B12: 357.14286 | C12: 54.29378 | D12: -380.58274 | E12: 50.82796 | F12: -19.0875 | G12: NaN | H12: NaN | I12: NaN | J12: NaN
A13: 43126 | B13: 292.85714 | C13: 56.32174 | D13: -22.14793 | E13: 52.16596 | F13: -21.23326 | G13: NaN | H13: NaN | I13: NaN | J13: NaN
... A55: 364376 | B55: 0.1 | C55: 601.58512 | D55: 1.48164 | E55: 601.38399 | F55: 15.55494 | G55: NaN | H55: NaN | I55: NaN | J55: NaN

Sheet I50_P300_T60_HR0
A1: Temps (ms) | B1: Fr駲uence (Hz) | C1: Module de Z (mOhm) | D1: d駱hasage de Z (ｰ) | E1: Partie r馥lle | F1: Partie imaginaire | G1: Module de Zstack (mOhm) | H1: d駱hasage de Zstack (ｰ) | I1: Partie r馥lle stack | J1: Partie imaginaire stack
A2: 0 | B2: 1000 | C2: 48.6548 | D2: -16.00758 | E2: 46.76823 | F2: -13.41727 | G2: NaN | H2: NaN | I2: NaN | J2: NaN
A3: 3979 | B3: 935.71429 | C3: 49.33122 | D3: -16.76521 | E3: 47.23439 | F3: -14.22961 | G3: NaN | H3: NaN | I3: NaN | J3: NaN
A4: 7672 | B4: 871.42857 | C4: 49.45509 | D4: -16.64634 | E4: 47.38249 | F4: -14.16707 | G4: NaN | H4: NaN | I4: NaN | J4: NaN
A5: 11549 | B5: 807.14286 | C5: 50.29622 | D5: -16.79029 | E5: 48.15202 | F5: -14.52905 | G5: NaN | H5: NaN | I5: NaN | J5: NaN
A6: 15501 | B6: 742.85714 | C6: 51.37775 | D6: -377.11659 | E6: 49.10212 | F6: -15.12135 | G6: NaN | H6: NaN | I6: NaN | J6: NaN
A7: 19440 | B7: 678.57143 | C7: 51.94316 | D7: -377.21885 | E7: 49.61512 | F7: -15.37634 | G7: NaN | H7: NaN | I7: NaN | J7: NaN
A8: 23410 | B8: 614.28571 | C8: 52.84404 | D8: -378.06263 | E8: 50.23979 | F8: -16.38463 | G8: NaN | H8: NaN | I8: NaN | J8: NaN
A9: 27182 | B9: 550 | C9: 53.82318 | D9: -378.55783 | E9: 51.02453 | F9: -17.12985 | G9: NaN | H9: NaN | I9: NaN | J9: NaN
A10: 31150 | B10: 485.71429 | C10: 55.0646 | D10: -379.32759 | E10: 51.96125 | F10: -18.22467 | G10: NaN | H10: NaN | I10: NaN | J10: NaN
A11: 35137 | B11: 421.42857 | C11: 56.25293 | D11: -380.19797 | E11: 52.79367 | F11: -19.42216 | G11: NaN | H11: NaN | I11: NaN | J11: NaN
A12: 39543 | B12: 357.14286 | C12: 57.47058 | D12: -380.97565 | E12: 53.66216 | F12: -20.57281 | G12: NaN | H12: NaN | I12: NaN | J12: NaN
A13: 43557 | B13: 292.85714 | C13: 60.03162 | D13: -22.57378 | E13: 55.43236 | F13: -23.04451 | G13: NaN | H13: NaN | I13: NaN | J13: NaN
... A55: 371872 | B55: 0.1 | C55: 874.29372 | D55: 2.45442 | E55: 873.49164 | F55: 37.44128 | G55: NaN | H55: NaN | I55: NaN | J55: NaN

Sheet SYNTH
A1: Fréquence (Hz) | B1: Re(Z)_mOhm_I10_P300_T60_HR50 | C1: -Im(Z)_mOhm_I10_P300_T60_HR50 | D1: Re(Z)_mOhm_I10_P400_T60_HR50 | E1: -Im(Z)_mOhm_I10_P400_T60_HR50 | F1: Re(Z)_mOhm_I10_P500_T60_HR50 | G1: -Im(Z)_mOhm_I10_P500_T60_HR50 | H1: Re(Z)_mOhm_I20_P300_T60_HR50 | I1: -Im(Z)_mOhm_I20_P300_T60_HR50 | J1: Re(Z)_mOhm_I20_P400_T60_HR50 | K1: -Im(Z)_mOhm_I20_P400_T60_HR50 | L1: Re(Z)_mOhm_I20_P500_T60_HR50 | M1: -Im(Z)_mOhm_I20_P500_T60_HR50 | N1: Re(Z)_mOhm_I30_P300_T60_HR50 | O1: -Im(Z)_mOhm_I30_P300_T60_HR50 | P1: Re(Z)_mOhm_I30_P400_T60_HR50 | Q1: -Im(Z)_mOhm_I30_P400_T60_HR50 | R1: Re(Z)_mOhm_I30_P500_T60_HR50 | S1: -Im(Z)_mOhm_I30_P500_T60_HR50 | T1: Re(Z)_mOhm_I35_P300_T60_HR50 | U1: -Im(Z)_mOhm_I35_P300_T60_HR50 | V1: Re(Z)_mOhm_I35_P400_T60_HR50 | W1: -Im(Z)_mOhm_I35_P400_T60_HR50 | X1: Re(Z)_mOhm_I35_P500_T60_HR50 | Y1: -Im(Z)_mOhm_I35_P500_T60_HR50 | Z1: Re(Z)_mOhm_I40_P300_T60_HR50 | AA1: -Im(Z)_mOhm_I40_P300_T60_HR50 | AB1: Re(Z)_mOhm_I40_P400_T60_HR50 | AC1: -Im(Z)_mOhm_I40_P400_T60_HR50 | AD1: Re(Z)_mOhm_I40_P500_T60_HR50 | AE1: -Im(Z)_mOhm_I40_P500_T60_HR50 | AF1: Re(Z)_mOhm_I45_P300_T60_HR50 | AG1: -Im(Z)_mOhm_I45_P300_T60_HR50 | AH1: Re(Z)_mOhm_I45_P400_T60_HR50 | AI1: -Im(Z)_mOhm_I45_P400_T60_HR50 | AJ1: Re(Z)_mOhm_I45_P500_T60_HR50 | AK1: -Im(Z)_mOhm_I45_P500_T60_HR50 | AL1: Re(Z)_mOhm_I50_P300_T60_HR50 | AM1: -Im(Z)_mOhm_I50_P300_T60_HR50 | AN1: Re(Z)_mOhm_I50_P400_T60_HR50 | AO1: -Im(Z)_mOhm_I50_P400_T60_HR50 | AP1: Re(Z)_mOhm_I50_P500_T60_HR50 | AQ1: -Im(Z)_mOhm_I50_P500_T60_HR50 | AR1: Re(Z)_mOhm_I10_P300_T60_HR0 | AS1: -Im(Z)_mOhm_I10_P300_T60_HR0 | AT1: Re(Z)_mOhm_I20_P300_T60_HR0 | AU1: -Im(Z)_mOhm_I20_P300_T60_HR0 | AV1: Re(Z)_mOhm_I30_P300_T60_HR0 | AW1: -Im(Z)_mOhm_I30_P300_T60_HR0 | AX1: Re(Z)_mOhm_I35_P300_T60_HR0 | AY1: -Im(Z)_mOhm_I35_P300_T60_HR0 | AZ1: Re(Z)_mOhm_I40_P300_T60_HR0 | BA1: -Im(Z)_mOhm_I40_P300_T60_HR0 | BB1: Re(Z)_mOhm_I45_P300_T60_HR0 | BC1: -Im(Z)_mOhm_I45_P300_T60_HR0 | BD1: Re(Z)_mOhm_I50_P300_T60_HR0 | BE1: -Im(Z)_mOhm_I50_P300_T60_HR0
