Workbook
Name Nyquist: I10_P300_T50_HR0!$A$1:$K$55
Name Nyquist: I10_P300_T50_HR50!$A$1:$K$48
Name Nyquist: I10_P400_T50_HR50!$A$1:$K$48
Name Nyquist: I10_P500_T50_HR50!$A$1:$K$48
Name Nyquist: I20_P300_T50_HR0!$A$1:$K$55
Name Nyquist: I20_P300_T50_HR50!$A$1:$K$48
Name Nyquist: I20_P300_T50_HRLOW_TBH2_20!$A$1:$K$55
Name Nyquist: I20_P300_T50_HRLOW_TBH2_40!$A$1:$K$55
Name Nyquist: I20_P300_T50_HRLOW_TBH2_65!$A$1:$K$55
Name Nyquist: I20_P400_T50_HR50!$A$1:$K$48
Name Nyquist: I20_P500_T50_HR50!$A$1:$K$48
Name Nyquist: I30_P300_T50_HR0!$A$1:$K$55
Name Nyquist: I30_P300_T50_HR50!$A$1:$K$48
Name Nyquist: I30_P400_T50_HR50!$A$1:$K$48
Name Nyquist: I30_P500_T50_HR50!$A$1:$K$48
Name Nyquist: I35_P300_T50_HR0!$A$1:$K$55
Name Nyquist: I35_P300_T50_HR50!$A$1:$K$48
Name Nyquist: I35_P400_T50_HR50!$A$1:$K$48
Name Nyquist: I35_P500_T50_HR50!$A$1:$K$48
Name Nyquist: I40_P300_T50_HR0!$A$1:$K$55
Name Nyquist: I40_P300_T50_HR50!$A$1:$K$48
Name Nyquist: I40_P400_T50_HR50!$A$1:$K$48
Name Nyquist: I45_P300_T50_HR0!$A$1:$K$55
Name Nyquist: I50_P300_T50_HR0!$A$1:$K$55

Sheet I10_P300_T50_HR50
A1: Temps (ms) | B1: Fr駲uence (Hz) | C1: Module de Z (mOhm) | D1: d駱hasage de Z (ｰ) | E1: Partie r馥lle | F1: Partie imaginaire | G1: Module de Zstack (mOhm) | H1: d駱hasage de Zstack (ｰ) | I1: Partie r馥lle stack | J1: Partie imaginaire stack
A2: 0 | B2: 1000 | C2: 40.65372 | D2: -14.69139 | E2: 39.32459 | F2: -10.3103 | G2: NaN | H2: NaN | I2: NaN | J2: NaN
A3: 1592 | B3: 935.71429 | C3: 40.98773 | D3: -13.97072 | E3: 39.77528 | F3: -9.89551 | G3: NaN | H3: NaN | I3: NaN | J3: NaN
A4: 3208 | B4: 871.42857 | C4: 42.21884 | D4: -14.65458 | E4: 40.8454 | F4: -10.68099 | G4: NaN | H4: NaN | I4: NaN | J4: NaN
A5: 4592 | B5: 807.14286 | C5: 42.55186 | D5: -15.36386 | E5: 41.03118 | F5: -11.27403 | G5: NaN | H5: NaN | I5: NaN | J5: NaN
A6: 5794 | B6: 742.85714 | C6: 42.90635 | D6: -376.10841 | E6: 41.22178 | F6: -11.90461 | G6: NaN | H6: NaN | I6: NaN | J6: NaN
A7: 7033 | B7: 678.57143 | C7: 43.29359 | D7: -375.12245 | E7: 41.79436 | F7: -11.29455 | G7: NaN | H7: NaN | I7: NaN | J7: NaN
A8: 8432 | B8: 614.28571 | C8: 43.87633 | D8: -376.16709 | E8: 42.14119 | F8: -12.2169 | G8: NaN | H8: NaN | I8: NaN | J8: NaN
A9: 9639 | B9: 550 | C9: 44.2725 | D9: -376.88265 | E9: 42.36442 | F9: -12.85729 | G9: NaN | H9: NaN | I9: NaN | J9: NaN
A10: 11050 | B10: 485.71429 | C10: 45.7782 | D10: -377.8663 | E10: 43.57055 | F10: -14.04461 | G10: NaN | H10: NaN | I10: NaN | J10: NaN
A11: 12304 | B11: 421.42857 | C11: 46.65091 | D11: -378.41153 | E11: 44.26296 | F11: -14.73422 | G11: NaN | H11: NaN | I11: NaN | J11: NaN
A12: 13678 | B12: 357.14286 | C12: 48.23544 | D12: -379.46344 | E12: 45.479 | F12: -16.0723 | G12: NaN | H12: NaN | I12: NaN | J12: NaN
A13: 14902 | B13: 292.85714 | C13: 49.74114 | D13: -20.68962 | E13: 46.53324 | F13: -17.57381 | G13: NaN | H13: NaN | I13: NaN | J13: NaN
... A48: 170283 | B48: 0.1 | C48: 311.03422 | D48: -2.34027 | E48: 310.7748 | F48: -12.70078 | G48: NaN | H48: NaN | I48: NaN | J48: NaN

Sheet I10_P400_T50_HR50
A1: Temps (ms) | B1: Fr駲uence (Hz) | C1: Module de Z (mOhm) | D1: d駱hasage de Z (ｰ) | E1: Partie r馥lle | F1: Partie imaginaire | G1: Module de Zstack (mOhm) | H1: d駱hasage de Zstack (ｰ) | I1: Partie r馥lle stack | J1: Partie imaginaire stack
A2: 0 | B2: 1000 | C2: 40.95925 | D2: -13.57415 | E2: 39.81513 | F2: -9.61328 | G2: NaN | H2: NaN | I2: NaN | J2: NaN
A3: 1401 | B3: 935.71429 | C3: 42.12046 | D3: -15.1338 | E3: 40.65967 | F3: -10.99656 | G3: NaN | H3: NaN | I3: NaN | J3: NaN
A4: 2569 | B4: 871.42857 | C4: 42.2655 | D4: -14.39288 | E4: 40.93896 | F4: -10.50592 | G4: NaN | H4: NaN | I4: NaN | J4: NaN
A5: 3866 | B5: 807.14286 | C5: 42.93819 | D5: -14.62926 | E5: 41.54615 | F5: -10.84462 | G5: NaN | H5: NaN | I5: NaN | J5: NaN
A6: 5064 | B6: 742.85714 | C6: 43.40191 | D6: -374.83121 | E6: 41.95594 | F6: -11.10969 | G6: NaN | H6: NaN | I6: NaN | J6: NaN
A7: 6483 | B7: 678.57143 | C7: 44.14901 | D7: -375.97702 | E7: 42.44362 | F7: -12.15209 | G7: NaN | H7: NaN | I7: NaN | J7: NaN
A8: 7706 | B8: 614.28571 | C8: 44.29715 | D8: -376.31369 | E8: 42.51367 | F8: -12.44289 | G8: NaN | H8: NaN | I8: NaN | J8: NaN
A9: 9092 | B9: 550 | C9: 44.88831 | D9: -376.77536 | E9: 42.97803 | F9: -12.95567 | G9: NaN | H9: NaN | I9: NaN | J9: NaN
A10: 10317 | B10: 485.71429 | C10: 45.90355 | D10: -377.74535 | E10: 43.71948 | F10: -13.9908 | G10: NaN | H10: NaN | I10: NaN | J10: NaN
A11: 11731 | B11: 421.42857 | C11: 47.05988 | D11: -379.07933 | E11: 44.47474 | F11: -15.38279 | G11: NaN | H11: NaN | I11: NaN | J11: NaN
A12: 12952 | B12: 357.14286 | C12: 48.4315 | D12: -379.72693 | E12: 45.58915 | F12: -16.34746 | G12: NaN | H12: NaN | I12: NaN | J12: NaN
A13: 14186 | B13: 292.85714 | C13: 50.38449 | D13: -21.10641 | E13: 47.00436 | F13: -18.14351 | G13: NaN | H13: NaN | I13: NaN | J13: NaN
... A48: 169732 | B48: 0.1 | C48: 312.07204 | D48: -2.47963 | E48: 311.77984 | F48: -13.50152 | G48: NaN | H48: NaN | I48: NaN | J48: NaN

Sheet I10_P500_T50_HR50
A1: Temps (ms) | B1: Fr駲uence (Hz) | C1: Module de Z (mOhm) | D1: d駱hasage de Z (ｰ) | E1: Partie r馥lle | F1: Partie imaginaire | G1: Module de Zstack (mOhm) | H1: d駱hasage de Zstack (ｰ) | I1: Partie r馥lle stack | J1: Partie imaginaire stack
A2: 0 | B2: 1000 | C2: 42.23617 | D2: -13.62034 | E2: 41.04838 | F2: -9.94608 | G2: NaN | H2: NaN | I2: NaN | J2: NaN
A3: 1401 | B3: 935.71429 | C3: 41.1479 | D3: -15.65222 | E3: 39.62202 | F3: -11.1016 | G3: NaN | H3: NaN | I3: NaN | J3: NaN
A4: 2797 | B4: 871.42857 | C4: 42.80497 | D4: -13.93318 | E4: 41.54553 | F4: -10.30702 | G4: NaN | H4: NaN | I4: NaN | J4: NaN
A5: 3999 | B5: 807.14286 | C5: 42.38352 | D5: -15.15121 | E5: 40.91024 | F5: -11.07767 | G5: NaN | H5: NaN | I5: NaN | J5: NaN
A6: 5198 | B6: 742.85714 | C6: 43.07067 | D6: -374.97189 | E6: 41.60853 | F6: -11.1271 | G6: NaN | H6: NaN | I6: NaN | J6: NaN
A7: 6658 | B7: 678.57143 | C7: 42.94915 | D7: -374.98213 | E7: 41.48915 | F7: -11.10312 | G7: NaN | H7: NaN | I7: NaN | J7: NaN
A8: 7839 | B8: 614.28571 | C8: 43.53015 | D8: -376.00213 | E8: 41.84342 | F8: -12.00009 | G8: NaN | H8: NaN | I8: NaN | J8: NaN
A9: 9284 | B9: 550 | C9: 44.43651 | D9: -377.22053 | E9: 42.44453 | F9: -13.15544 | G9: NaN | H9: NaN | I9: NaN | J9: NaN
A10: 10489 | B10: 485.71429 | C10: 45.54981 | D10: -377.72718 | E10: 43.38697 | F10: -13.86923 | G10: NaN | H10: NaN | I10: NaN | J10: NaN
A11: 11739 | B11: 421.42857 | C11: 47.0971 | D11: -378.83561 | E11: 44.57499 | F11: -15.20549 | G11: NaN | H11: NaN | I11: NaN | J11: NaN
A12: 13121 | B12: 357.14286 | C12: 48.26718 | D12: -379.76467 | E12: 45.42374 | F12: -16.32192 | G12: NaN | H12: NaN | I12: NaN | J12: NaN
A13: 14333 | B13: 292.85714 | C13: 50.30954 | D13: -21.84692 | E13: 46.69638 | F13: -18.72159 | G13: NaN | H13: NaN | I13: NaN | J13: NaN
... A48: 169939 | B48: 0.1 | C48: 313.137 | D48: -3.36271 | E48: 312.59785 | F48: -18.36756 | G48: NaN | H48: NaN | I48: NaN | J48: NaN

Sheet I20_P300_T50_HR50
A1: Temps (ms) | B1: Fr駲uence (Hz) | C1: Module de Z (mOhm) | D1: d駱hasage de Z (ｰ) | E1: Partie r馥lle | F1: Partie imaginaire | G1: Module de Zstack (mOhm) | H1: d駱hasage de Zstack (ｰ) | I1: Partie r馥lle stack | J1: Partie imaginaire stack
A2: 0 | B2: 1000 | C2: 40.24232 | D2: -13.07635 | E2: 39.19882 | F2: -9.1048 | G2: NaN | H2: NaN | I2: NaN | J2: NaN
A3: 1477 | B3: 935.71429 | C3: 40.44729 | D3: -14.1997 | E3: 39.21149 | F3: -9.92181 | G3: NaN | H3: NaN | I3: NaN | J3: NaN
A4: 2640 | B4: 871.42857 | C4: 40.82649 | D4: -13.94422 | E4: 39.62337 | F4: -9.83825 | G4: NaN | H4: NaN | I4: NaN | J4: NaN
A5: 4061 | B5: 807.14286 | C5: 41.04091 | D5: -13.97272 | E5: 39.82654 | F5: -9.90974 | G5: NaN | H5: NaN | I5: NaN | J5: NaN
A6: 5261 | B6: 742.85714 | C6: 42.29906 | D6: -375.57942 | E6: 40.74496 | F6: -11.36042 | G6: NaN | H6: NaN | I6: NaN | J6: NaN
A7: 6690 | B7: 678.57143 | C7: 42.68458 | D7: -375.38596 | E7: 41.15478 | F7: -11.32507 | G7: NaN | H7: NaN | I7: NaN | J7: NaN
A8: 7882 | B8: 614.28571 | C8: 43.01069 | D8: -375.57843 | E8: 41.43064 | F8: -11.55083 | G8: NaN | H8: NaN | I8: NaN | J8: NaN
A9: 9119 | B9: 550 | C9: 44.41406 | D9: -376.21058 | E9: 42.64825 | F9: -12.399 | G9: NaN | H9: NaN | I9: NaN | J9: NaN
A10: 10505 | B10: 485.71429 | C10: 44.99516 | D10: -377.35474 | E10: 42.94681 | F10: -13.42147 | G10: NaN | H10: NaN | I10: NaN | J10: NaN
A11: 11737 | B11: 421.42857 | C11: 45.62488 | D11: -377.93667 | E11: 43.40739 | F11: -14.05089 | G11: NaN | H11: NaN | I11: NaN | J11: NaN
A12: 13137 | B12: 357.14286 | C12: 47.10984 | D12: -379.61725 | E12: 44.37542 | F12: -15.81643 | G12: NaN | H12: NaN | I12: NaN | J12: NaN
A13: 14371 | B13: 292.85714 | C13: 48.80439 | D13: -20.74906 | E13: 45.63899 | F13: -17.29021 | G13: NaN | H13: NaN | I13: NaN | J13: NaN
... A48: 177553 | B48: 0.1 | C48: 310.66937 | D48: -2.29619 | E48: 310.41993 | F48: -12.44705 | G48: NaN | H48: NaN | I48: NaN | J48: NaN

Sheet I20_P400_T50_HR50
A1: Temps (ms) | B1: Fr駲uence (Hz) | C1: Module de Z (mOhm) | D1: d駱hasage de Z (ｰ) | E1: Partie r馥lle | F1: Partie imaginaire | G1: Module de Zstack (mOhm) | H1: d駱hasage de Zstack (ｰ) | I1: Partie r馥lle stack | J1: Partie imaginaire stack
A2: 0 | B2: 1000 | C2: 40.24671 | D2: -13.30939 | E2: 39.16573 | F2: -9.26516 | G2: NaN | H2: NaN | I2: NaN | J2: NaN
A3: 1753 | B3: 935.71429 | C3: 40.29674 | D3: -13.28919 | E3: 39.21768 | F3: -9.26286 | G3: NaN | H3: NaN | I3: NaN | J3: NaN
A4: 3727 | B4: 871.42857 | C4: 40.91544 | D4: -15.21404 | E4: 39.48145 | F4: -10.73726 | G4: NaN | H4: NaN | I4: NaN | J4: NaN
A5: 5694 | B5: 807.14286 | C5: 41.26769 | D5: -14.63584 | E5: 39.92861 | F5: -10.4273 | G5: NaN | H5: NaN | I5: NaN | J5: NaN
A6: 7681 | B6: 742.85714 | C6: 41.9646 | D6: -375.29077 | E6: 40.47905 | F6: -11.06681 | G6: NaN | H6: NaN | I6: NaN | J6: NaN
A7: 9509 | B7: 678.57143 | C7: 42.86737 | D7: -374.92297 | E7: 41.42158 | F7: -11.03922 | G7: NaN | H7: NaN | I7: NaN | J7: NaN
A8: 11604 | B8: 614.28571 | C8: 43.53445 | D8: -376.00592 | E8: 41.84676 | F8: -12.00405 | G8: NaN | H8: NaN | I8: NaN | J8: NaN
A9: 14615 | B9: 550 | C9: 44.3957 | D9: -377.25661 | E9: 42.39726 | F9: -13.17007 | G9: NaN | H9: NaN | I9: NaN | J9: NaN
A10: 17649 | B10: 485.71429 | C10: 45.25805 | D10: -376.78545 | E10: 43.32974 | F10: -13.07002 | G10: NaN | H10: NaN | I10: NaN | J10: NaN
A11: 19928 | B11: 421.42857 | C11: 46.00919 | D11: -378.43941 | E11: 43.64702 | F11: -14.55279 | G11: NaN | H11: NaN | I11: NaN | J11: NaN
A12: 22013 | B12: 357.14286 | C12: 47.29118 | D12: -379.18213 | E12: 44.66552 | F12: -15.53856 | G12: NaN | H12: NaN | I12: NaN | J12: NaN
A13: 23901 | B13: 292.85714 | C13: 49.25398 | D13: -20.74272 | E13: 46.06135 | F13: -17.44439 | G13: NaN | H13: NaN | I13: NaN | J13: NaN
... A48: 196884 | B48: 0.1 | C48: 323.42333 | D48: -2.01054 | E48: 323.22423 | F48: -11.34674 | G48: NaN | H48: NaN | I48: NaN | J48: NaN

Sheet I20_P500_T50_HR50
A1: Temps (ms) | B1: Fr駲uence (Hz) | C1: Module de Z (mOhm) | D1: d駱hasage de Z (ｰ) | E1: Partie r馥lle | F1: Partie imaginaire | G1: Module de Zstack (mOhm) | H1: d駱hasage de Zstack (ｰ) | I1: Partie r馥lle stack | J1: Partie imaginaire stack
A2: 0 | B2: 1000 | C2: 40.11698 | D2: -14.29104 | E2: 38.87553 | F2: -9.90277 | G2: NaN | H2: NaN | I2: NaN | J2: NaN
A3: 3065 | B3: 935.71429 | C3: 40.57164 | D3: -15.22439 | E3: 39.14778 | F3: -10.65411 | G3: NaN | H3: NaN | I3: NaN | J3: NaN
A4: 5521 | B4: 871.42857 | C4: 41.67553 | D4: -14.22331 | E4: 40.39798 | F4: -10.23975 | G4: NaN | H4: NaN | I4: NaN | J4: NaN
A5: 7543 | B5: 807.14286 | C5: 41.35196 | D5: -14.54443 | E5: 40.02676 | F5: -10.38475 | G5: NaN | H5: NaN | I5: NaN | J5: NaN
A6: 9386 | B6: 742.85714 | C6: 42.15709 | D6: -375.73269 | E6: 40.57776 | F6: -11.43088 | G6: NaN | H6: NaN | I6: NaN | J6: NaN
A7: 11447 | B7: 678.57143 | C7: 43.15376 | D7: -375.91036 | E7: 41.50062 | F7: -11.82988 | G7: NaN | H7: NaN | I7: NaN | J7: NaN
A8: 13933 | B8: 614.28571 | C8: 42.9261 | D8: -376.25783 | E8: 41.20956 | F8: -12.0176 | G8: NaN | H8: NaN | I8: NaN | J8: NaN
A9: 16004 | B9: 550 | C9: 44.19666 | D9: -376.45613 | E9: 42.38623 | F9: -12.52008 | G9: NaN | H9: NaN | I9: NaN | J9: NaN
A10: 18472 | B10: 485.71429 | C10: 44.54254 | D10: -377.15886 | E10: 42.55997 | F10: -13.14103 | G10: NaN | H10: NaN | I10: NaN | J10: NaN
A11: 20386 | B11: 421.42857 | C11: 45.75631 | D11: -377.94383 | E11: 43.53068 | F11: -14.09681 | G11: NaN | H11: NaN | I11: NaN | J11: NaN
A12: 22720 | B12: 357.14286 | C12: 47.25677 | D12: -379.082 | E12: 44.66009 | F12: -15.44923 | G12: NaN | H12: NaN | I12: NaN | J12: NaN
A13: 25015 | B13: 292.85714 | C13: 48.83046 | D13: -20.94572 | E13: 45.60372 | F13: -17.45608 | G13: NaN | H13: NaN | I13: NaN | J13: NaN
... A48: 206391 | B48: 0.1 | C48: 305.74371 | D48: -1.15462 | E48: 305.68163 | F48: -6.1609 | G48: NaN | H48: NaN | I48: NaN | J48: NaN

Sheet I30_P300_T50_HR50
A1: Temps (ms) | B1: Fr駲uence (Hz) | C1: Module de Z (mOhm) | D1: d駱hasage de Z (ｰ) | E1: Partie r馥lle | F1: Partie imaginaire | G1: Module de Zstack (mOhm) | H1: d駱hasage de Zstack (ｰ) | I1: Partie r馥lle stack | J1: Partie imaginaire stack
A2: 0 | B2: 1000 | C2: 39.18831 | D2: -12.59516 | E2: 38.24525 | F2: -8.54543 | G2: NaN | H2: NaN | I2: NaN | J2: NaN
A3: 2887 | B3: 935.71429 | C3: 40.73099 | D3: -13.12414 | E3: 39.66711 | F3: -9.24845 | G3: NaN | H3: NaN | I3: NaN | J3: NaN
A4: 5341 | B4: 871.42857 | C4: 40.86761 | D4: -14.75201 | E4: 39.52049 | F4: -10.40636 | G4: NaN | H4: NaN | I4: NaN | J4: NaN
A5: 7956 | B5: 807.14286 | C5: 41.27476 | D5: -14.50769 | E5: 39.95867 | F5: -10.33974 | G5: NaN | H5: NaN | I5: NaN | J5: NaN
A6: 10587 | B6: 742.85714 | C6: 41.86532 | D6: -375.06155 | E6: 40.42713 | F6: -10.87898 | G6: NaN | H6: NaN | I6: NaN | J6: NaN
A7: 13053 | B7: 678.57143 | C7: 42.51939 | D7: -375.39889 | E7: 40.99297 | F7: -11.29049 | G7: NaN | H7: NaN | I7: NaN | J7: NaN
A8: 15742 | B8: 614.28571 | C8: 43.39058 | D8: -376.44394 | E8: 41.61578 | F8: -12.28288 | G8: NaN | H8: NaN | I8: NaN | J8: NaN
A9: 18392 | B9: 550 | C9: 43.84545 | D9: -376.98202 | E9: 41.93363 | F9: -12.80601 | G9: NaN | H9: NaN | I9: NaN | J9: NaN
A10: 20834 | B10: 485.71429 | C10: 44.60332 | D10: -377.67025 | E10: 42.4989 | F10: -13.53882 | G10: NaN | H10: NaN | I10: NaN | J10: NaN
A11: 23528 | B11: 421.42857 | C11: 45.51456 | D11: -378.40414 | E11: 43.18664 | F11: -14.36975 | G11: NaN | H11: NaN | I11: NaN | J11: NaN
A12: 26043 | B12: 357.14286 | C12: 46.91682 | D12: -379.027 | E12: 44.35353 | F12: -15.29552 | G12: NaN | H12: NaN | I12: NaN | J12: NaN
A13: 28764 | B13: 292.85714 | C13: 48.70905 | D13: -21.44712 | E13: 45.33621 | F13: -17.81009 | G13: NaN | H13: NaN | I13: NaN | J13: NaN
... A48: 215345 | B48: 0.1 | C48: 386.31096 | D48: 0.25978 | E48: 386.30699 | F48: 1.75156 | G48: NaN | H48: NaN | I48: NaN | J48: NaN

Sheet I30_P400_T50_HR50
A1: Temps (ms) | B1: Fr駲uence (Hz) | C1: Module de Z (mOhm) | D1: d駱hasage de Z (ｰ) | E1: Partie r馥lle | F1: Partie imaginaire | G1: Module de Zstack (mOhm) | H1: d駱hasage de Zstack (ｰ) | I1: Partie r馥lle stack | J1: Partie imaginaire stack
A2: 0 | B2: 1000 | C2: 38.7174 | D2: -13.78515 | E2: 37.60219 | F2: -9.22565 | G2: NaN | H2: NaN | I2: NaN | J2: NaN
A3: 2439 | B3: 935.71429 | C3: 39.66842 | D3: -13.16545 | E3: 38.62579 | F3: -9.03503 | G3: NaN | H3: NaN | I3: NaN | J3: NaN
A4: 4880 | B4: 871.42857 | C4: 39.83318 | D4: -14.43235 | E4: 38.57614 | F4: -9.92789 | G4: NaN | H4: NaN | I4: NaN | J4: NaN
A5: 7497 | B5: 807.14286 | C5: 40.42542 | D5: -13.81438 | E5: 39.25609 | F5: -9.65267 | G5: NaN | H5: NaN | I5: NaN | J5: NaN
A6: 10107 | B6: 742.85714 | C6: 41.02156 | D6: -375.3441 | E6: 39.55931 | F6: -10.85493 | G6: NaN | H6: NaN | I6: NaN | J6: NaN
A7: 12728 | B7: 678.57143 | C7: 42.1997 | D7: -376.06189 | E7: 40.55237 | F7: -11.67563 | G7: NaN | H7: NaN | I7: NaN | J7: NaN
A8: 15392 | B8: 614.28571 | C8: 42.85709 | D8: -375.74288 | E8: 41.24947 | F8: -11.62802 | G8: NaN | H8: NaN | I8: NaN | J8: NaN
A9: 18060 | B9: 550 | C9: 42.99651 | D9: -376.03966 | E9: 41.32269 | F9: -11.88005 | G9: NaN | H9: NaN | I9: NaN | J9: NaN
A10: 20488 | B10: 485.71429 | C10: 44.51104 | D10: -376.82941 | E10: 42.60468 | F10: -12.88698 | G10: NaN | H10: NaN | I10: NaN | J10: NaN
A11: 23183 | B11: 421.42857 | C11: 45.02018 | D11: -378.22084 | E11: 42.76279 | F11: -14.07693 | G11: NaN | H11: NaN | I11: NaN | J11: NaN
A12: 25683 | B12: 357.14286 | C12: 46.15351 | D12: -379.38601 | E12: 43.53678 | F12: -15.31978 | G12: NaN | H12: NaN | I12: NaN | J12: NaN
A13: 28387 | B13: 292.85714 | C13: 48.0266 | D13: -20.78853 | E13: 44.89991 | F13: -17.04559 | G13: NaN | H13: NaN | I13: NaN | J13: NaN
... A48: 217660 | B48: 0.1 | C48: 414.26029 | D48: -0.22591 | E48: 414.25707 | F48: -1.63334 | G48: NaN | H48: NaN | I48: NaN | J48: NaN

Sheet I30_P500_T50_HR50
A1: Temps (ms) | B1: Fr駲uence (Hz) | C1: Module de Z (mOhm) | D1: d駱hasage de Z (ｰ) | E1: Partie r馥lle | F1: Partie imaginaire | G1: Module de Zstack (mOhm) | H1: d駱hasage de Zstack (ｰ) | I1: Partie r馥lle stack | J1: Partie imaginaire stack
A2: 0 | B2: 1000 | C2: 38.9158 | D2: -13.76118 | E2: 37.79875 | F2: -9.25711 | G2: NaN | H2: NaN | I2: NaN | J2: NaN
A3: 2350 | B3: 935.71429 | C3: 39.69095 | D3: -13.5531 | E3: 38.58568 | F3: -9.30143 | G3: NaN | H3: NaN | I3: NaN | J3: NaN
A4: 4996 | B4: 871.42857 | C4: 39.81731 | D4: -14.04157 | E4: 38.62757 | F4: -9.6607 | G4: NaN | H4: NaN | I4: NaN | J4: NaN
A5: 7580 | B5: 807.14286 | C5: 40.48326 | D5: -13.8289 | E5: 39.30981 | F5: -9.67644 | G5: NaN | H5: NaN | I5: NaN | J5: NaN
A6: 10216 | B6: 742.85714 | C6: 41.00361 | D6: -375.10843 | E6: 39.58629 | F6: -10.68745 | G6: NaN | H6: NaN | I6: NaN | J6: NaN
A7: 12822 | B7: 678.57143 | C7: 41.67125 | D7: -374.91778 | E7: 40.26677 | F7: -10.72754 | G7: NaN | H7: NaN | I7: NaN | J7: NaN
A8: 15457 | B8: 614.28571 | C8: 41.9651 | D8: -376.39075 | E8: 40.25962 | F8: -11.84199 | G8: NaN | H8: NaN | I8: NaN | J8: NaN
A9: 17884 | B9: 550 | C9: 42.67434 | D9: -376.30595 | E9: 40.95781 | F9: -11.98152 | G9: NaN | H9: NaN | I9: NaN | J9: NaN
A10: 20507 | B10: 485.71429 | C10: 43.40314 | D10: -377.10352 | E10: 41.48363 | F10: -12.76482 | G10: NaN | H10: NaN | I10: NaN | J10: NaN
A11: 23176 | B11: 421.42857 | C11: 44.83745 | D11: -377.8594 | E11: 42.67682 | F11: -13.75085 | G11: NaN | H11: NaN | I11: NaN | J11: NaN
A12: 25840 | B12: 357.14286 | C12: 45.74325 | D12: -378.90511 | E12: 43.27569 | F12: -14.82089 | G12: NaN | H12: NaN | I12: NaN | J12: NaN
A13: 28293 | B13: 292.85714 | C13: 47.29321 | D13: -19.92486 | E13: 44.46225 | F13: -16.11693 | G13: NaN | H13: NaN | I13: NaN | J13: NaN
... A48: 224099 | B48: 0.1 | C48: 417.58913 | D48: -0.83223 | E48: 417.54508 | F48: -6.06534 | G48: NaN | H48: NaN | I48: NaN | J48: NaN

Sheet I35_P300_T50_HR50
A1: Temps (ms) | B1: Fr駲uence (Hz) | C1: Module de Z (mOhm) | D1: d駱hasage de Z (ｰ) | E1: Partie r馥lle | F1: Partie imaginaire | G1: Module de Zstack (mOhm) | H1: d駱hasage de Zstack (ｰ) | I1: Partie r馥lle stack | J1: Partie imaginaire stack
A2: 0 | B2: 1000 | C2: 39.04967 | D2: -12.78615 | E2: 38.08135 | F2: -8.64219 | G2: NaN | H2: NaN | I2: NaN | J2: NaN
A3: 2803 | B3: 935.71429 | C3: 39.25914 | D3: -13.26572 | E3: 38.21156 | F3: -9.0087 | G3: NaN | H3: NaN | I3: NaN | J3: NaN
A4: 6026 | B4: 871.42857 | C4: 40.22344 | D4: -13.66812 | E4: 39.08434 | F4: -9.5047 | G4: NaN | H4: NaN | I4: NaN | J4: NaN
A5: 8564 | B5: 807.14286 | C5: 40.24212 | D5: -14.27956 | E5: 38.99879 | F5: -9.92585 | G5: NaN | H5: NaN | I5: NaN | J5: NaN
A6: 11136 | B6: 742.85714 | C6: 40.62404 | D6: -374.43308 | E6: 39.34192 | F6: -10.1255 | G6: NaN | H6: NaN | I6: NaN | J6: NaN
A7: 13731 | B7: 678.57143 | C7: 41.46006 | D7: -375.48996 | E7: 39.95412 | F7: -11.07272 | G7: NaN | H7: NaN | I7: NaN | J7: NaN
A8: 16339 | B8: 614.28571 | C8: 41.79015 | D8: -375.53738 | E8: 40.26297 | F8: -11.1942 | G8: NaN | H8: NaN | I8: NaN | J8: NaN
A9: 18935 | B9: 550 | C9: 42.16677 | D9: -376.05929 | E9: 40.52125 | F9: -11.66468 | G9: NaN | H9: NaN | I9: NaN | J9: NaN
A10: 21524 | B10: 485.71429 | C10: 43.23503 | D10: -376.79649 | E10: 41.39051 | F10: -12.49376 | G10: NaN | H10: NaN | I10: NaN | J10: NaN
A11: 24140 | B11: 421.42857 | C11: 44.2298 | D11: -378.13814 | E11: 42.03197 | F11: -13.76914 | G11: NaN | H11: NaN | I11: NaN | J11: NaN
A12: 26800 | B12: 357.14286 | C12: 45.39304 | D12: -379.31335 | E12: 42.8385 | F12: -15.01304 | G12: NaN | H12: NaN | I12: NaN | J12: NaN
A13: 30096 | B13: 292.85714 | C13: 46.98856 | D13: -21.01762 | E13: 43.86242 | F13: -16.85268 | G13: NaN | H13: NaN | I13: NaN | J13: NaN
... A48: 231772 | B48: 0.1 | C48: 423.30297 | D48: 1.77942 | E48: 423.09884 | F48: 13.14432 | G48: NaN | H48: NaN | I48: NaN | J48: NaN

Sheet I35_P400_T50_HR50
A1: Temps (ms) | B1: Fr駲uence (Hz) | C1: Module de Z (mOhm) | D1: d駱hasage de Z (ｰ) | E1: Partie r馥lle | F1: Partie imaginaire | G1: Module de Zstack (mOhm) | H1: d駱hasage de Zstack (ｰ) | I1: Partie r馥lle stack | J1: Partie imaginaire stack
A2: 0 | B2: 1000 | C2: 39.48507 | D2: -12.42471 | E2: 38.56031 | F2: -8.49547 | G2: NaN | H2: NaN | I2: NaN | J2: NaN
A3: 2994 | B3: 935.71429 | C3: 39.72636 | D3: -13.43489 | E3: 38.63924 | F3: -9.23003 | G3: NaN | H3: NaN | I3: NaN | J3: NaN
A4: 6358 | B4: 871.42857 | C4: 40.244 | D4: -14.20586 | E4: 39.01334 | F4: -9.87614 | G4: NaN | H4: NaN | I4: NaN | J4: NaN
A5: 9459 | B5: 807.14286 | C5: 40.44328 | D5: -14.4462 | E5: 39.16456 | F5: -10.08942 | G5: NaN | H5: NaN | I5: NaN | J5: NaN
A6: 12791 | B6: 742.85714 | C6: 41.15583 | D6: -374.89686 | E6: 39.77259 | F6: -10.58034 | G6: NaN | H6: NaN | I6: NaN | J6: NaN
A7: 15973 | B7: 678.57143 | C7: 41.70543 | D7: -375.22114 | E7: 40.24239 | F7: -10.94956 | G7: NaN | H7: NaN | I7: NaN | J7: NaN
A8: 19157 | B8: 614.28571 | C8: 41.96643 | D8: -375.8895 | E8: 40.36296 | F8: -11.4897 | G8: NaN | H8: NaN | I8: NaN | J8: NaN
A9: 22556 | B9: 550 | C9: 43.05873 | D9: -376.10642 | E9: 41.36859 | F9: -11.94545 | G9: NaN | H9: NaN | I9: NaN | J9: NaN
A10: 25754 | B10: 485.71429 | C10: 43.87494 | D10: -377.35556 | E10: 41.8774 | F10: -13.08792 | G10: NaN | H10: NaN | I10: NaN | J10: NaN
A11: 28982 | B11: 421.42857 | C11: 44.79714 | D11: -378.11281 | E11: 42.57727 | F11: -13.92694 | G11: NaN | H11: NaN | I11: NaN | J11: NaN
A12: 32202 | B12: 357.14286 | C12: 45.96326 | D12: -378.69959 | E12: 43.53698 | F12: -14.73611 | G12: NaN | H12: NaN | I12: NaN | J12: NaN
A13: 35446 | B13: 292.85714 | C13: 47.55113 | D13: -20.61014 | E13: 44.50773 | F13: -16.73834 | G13: NaN | H13: NaN | I13: NaN | J13: NaN
... A48: 237759 | B48: 0.1 | C48: 423.46697 | D48: 1.42041 | E48: 423.33685 | F48: 10.49706 | G48: NaN | H48: NaN | I48: NaN | J48: NaN

Sheet I35_P500_T50_HR50
A1: Temps (ms) | B1: Fr駲uence (Hz) | C1: Module de Z (mOhm) | D1: d駱hasage de Z (ｰ) | E1: Partie r馥lle | F1: Partie imaginaire | G1: Module de Zstack (mOhm) | H1: d駱hasage de Zstack (ｰ) | I1: Partie r馥lle stack | J1: Partie imaginaire stack
A2: 0 | B2: 1000 | C2: 39.13714 | D2: -13.96408 | E2: 37.98053 | F2: -9.44432 | G2: NaN | H2: NaN | I2: NaN | J2: NaN
A3: 3540 | B3: 935.71429 | C3: 40.01315 | D3: -14.46923 | E3: 38.74401 | F3: -9.99769 | G3: NaN | H3: NaN | I3: NaN | J3: NaN
A4: 6681 | B4: 871.42857 | C4: 40.64427 | D4: -14.12332 | E4: 39.4157 | F4: -9.91759 | G4: NaN | H4: NaN | I4: NaN | J4: NaN
A5: 9968 | B5: 807.14286 | C5: 40.89465 | D5: -14.48476 | E5: 39.59478 | F5: -10.22868 | G5: NaN | H5: NaN | I5: NaN | J5: NaN
A6: 13269 | B6: 742.85714 | C6: 41.69185 | D6: -375.08536 | E6: 40.25511 | F6: -10.85063 | G6: NaN | H6: NaN | I6: NaN | J6: NaN
A7: 16422 | B7: 678.57143 | C7: 42.07173 | D7: -375.51297 | E7: 40.53905 | F7: -11.25236 | G7: NaN | H7: NaN | I7: NaN | J7: NaN
A8: 19760 | B8: 614.28571 | C8: 42.49384 | D8: -376.16067 | E8: 40.81469 | F8: -11.82739 | G8: NaN | H8: NaN | I8: NaN | J8: NaN
A9: 22918 | B9: 550 | C9: 43.41595 | D9: -376.57514 | E9: 41.61186 | F9: -12.38538 | G9: NaN | H9: NaN | I9: NaN | J9: NaN
A10: 26248 | B10: 485.71429 | C10: 44.48248 | D10: -377.42506 | E10: 42.44116 | F10: -13.32064 | G10: NaN | H10: NaN | I10: NaN | J10: NaN
A11: 29452 | B11: 421.42857 | C11: 45.14422 | D11: -378.63811 | E11: 42.77668 | F11: -14.42763 | G11: NaN | H11: NaN | I11: NaN | J11: NaN
A12: 32638 | B12: 357.14286 | C12: 46.46752 | D12: -379.63806 | E12: 43.7647 | F12: -15.61668 | G12: NaN | H12: NaN | I12: NaN | J12: NaN
A13: 36066 | B13: 292.85714 | C13: 48.103 | D13: -21.07407 | E13: 44.8857 | F13: -17.29662 | G13: NaN | H13: NaN | I13: NaN | J13: NaN
... A48: 240103 | B48: 0.1 | C48: 447.6814 | D48: 0.98441 | E48: 447.61533 | F48: 7.69131 | G48: NaN | H48: NaN | I48: NaN | J48: NaN

Sheet I40_P300_T50_HR50
A1: Temps (ms) | B1: Fr駲uence (Hz) | C1: Module de Z (mOhm) | D1: d駱hasage de Z (ｰ) | E1: Partie r馥lle | F1: Partie imaginaire | G1: Module de Zstack (mOhm) | H1: d駱hasage de Zstack (ｰ) | I1: Partie r馥lle stack | J1: Partie imaginaire stack
A2: 0 | B2: 1000 | C2: 40.62665 | D2: -13.75532 | E2: 39.46147 | F2: -9.66005 | G2: NaN | H2: NaN | I2: NaN | J2: NaN
A3: 3106 | B3: 935.71429 | C3: 40.36641 | D3: -14.85557 | E3: 39.01717 | F3: -10.34927 | G3: NaN | H3: NaN | I3: NaN | J3: NaN
A4: 6373 | B4: 871.42857 | C4: 41.2206 | D4: -13.76965 | E4: 40.03594 | F4: -9.81129 | G4: NaN | H4: NaN | I4: NaN | J4: NaN
A5: 9669 | B5: 807.14286 | C5: 41.28311 | D5: -15.315 | E5: 39.81707 | F5: -10.90392 | G5: NaN | H5: NaN | I5: NaN | J5: NaN
A6: 12968 | B6: 742.85714 | C6: 41.67295 | D6: -375.03936 | E6: 40.24556 | F6: -10.81341 | G6: NaN | H6: NaN | I6: NaN | J6: NaN
A7: 16699 | B7: 678.57143 | C7: 42.36459 | D7: -375.71225 | E7: 40.78159 | F7: -11.4726 | G7: NaN | H7: NaN | I7: NaN | J7: NaN
A8: 20024 | B8: 614.28571 | C8: 43.12754 | D8: -375.96852 | E8: 41.46338 | F8: -11.86478 | G8: NaN | H8: NaN | I8: NaN | J8: NaN
A9: 23373 | B9: 550 | C9: 44.13566 | D9: -376.86425 | E9: 42.23759 | F9: -12.80398 | G9: NaN | H9: NaN | I9: NaN | J9: NaN
A10: 26504 | B10: 485.71429 | C10: 44.66779 | D10: -377.45043 | E10: 42.61203 | F10: -13.395 | G10: NaN | H10: NaN | I10: NaN | J10: NaN
A11: 29856 | B11: 421.42857 | C11: 45.68345 | D11: -378.7116 | E11: 43.26886 | F11: -14.65547 | G11: NaN | H11: NaN | I11: NaN | J11: NaN
A12: 33630 | B12: 357.14286 | C12: 46.87199 | D12: -379.89516 | E12: 44.07452 | F12: -15.95054 | G12: NaN | H12: NaN | I12: NaN | J12: NaN
A13: 37023 | B13: 292.85714 | C13: 48.62769 | D13: -21.48667 | E13: 45.2482 | F13: -17.81158 | G13: NaN | H13: NaN | I13: NaN | J13: NaN
... A48: 252914 | B48: 0.1 | C48: 561.75089 | D48: 1.71505 | E48: 561.49924 | F48: 16.81258 | G48: NaN | H48: NaN | I48: NaN | J48: NaN

Sheet I40_P400_T50_HR50
A1: Temps (ms) | B1: Fr駲uence (Hz) | C1: Module de Z (mOhm) | D1: d駱hasage de Z (ｰ) | E1: Partie r馥lle | F1: Partie imaginaire | G1: Module de Zstack (mOhm) | H1: d駱hasage de Zstack (ｰ) | I1: Partie r馥lle stack | J1: Partie imaginaire stack
A2: 0 | B2: 1000 | C2: 39.35785 | D2: -14.64545 | E2: 38.07907 | F2: -9.95112 | G2: NaN | H2: NaN | I2: NaN | J2: NaN
A3: 3879 | B3: 935.71429 | C3: 39.45891 | D3: -14.25079 | E3: 38.24466 | F3: -9.71347 | G3: NaN | H3: NaN | I3: NaN | J3: NaN
A4: 7542 | B4: 871.42857 | C4: 40.22922 | D4: -14.25439 | E4: 38.99064 | F4: -9.90554 | G4: NaN | H4: NaN | I4: NaN | J4: NaN
A5: 11413 | B5: 807.14286 | C5: 40.91507 | D5: -15.46429 | E5: 39.43381 | F5: -10.9095 | G5: NaN | H5: NaN | I5: NaN | J5: NaN
A6: 15279 | B6: 742.85714 | C6: 41.47018 | D6: -375.06764 | E6: 40.04441 | F6: -10.78056 | G6: NaN | H6: NaN | I6: NaN | J6: NaN
A7: 19173 | B7: 678.57143 | C7: 41.95602 | D7: -375.4333 | E7: 40.44312 | F7: -11.16518 | G7: NaN | H7: NaN | I7: NaN | J7: NaN
A8: 23085 | B8: 614.28571 | C8: 42.47522 | D8: -375.77598 | E8: 40.87527 | F8: -11.54803 | G8: NaN | H8: NaN | I8: NaN | J8: NaN
A9: 26973 | B9: 550 | C9: 42.85139 | D9: -376.60691 | E9: 41.06398 | F9: -12.2471 | G9: NaN | H9: NaN | I9: NaN | J9: NaN
A10: 30870 | B10: 485.71429 | C10: 44.08623 | D10: -377.45081 | E10: 42.05716 | F10: -13.22088 | G10: NaN | H10: NaN | I10: NaN | J10: NaN
A11: 34797 | B11: 421.42857 | C11: 44.78705 | D11: -378.39519 | E11: 42.49854 | F11: -14.13342 | G11: NaN | H11: NaN | I11: NaN | J11: NaN
A12: 38732 | B12: 357.14286 | C12: 46.28064 | D12: -379.02176 | E12: 43.75348 | F12: -15.08412 | G12: NaN | H12: NaN | I12: NaN | J12: NaN
A13: 42474 | B13: 292.85714 | C13: 47.81319 | D13: -21.14275 | E13: 44.59463 | F13: -17.24587 | G13: NaN | H13: NaN | I13: NaN | J13: NaN
... A48: 259741 | B48: 0.1 | C48: 513.72121 | D48: 1.49505 | E48: 513.54633 | F48: 13.40333 | G48: NaN | H48: NaN | I48: NaN | J48: NaN

Sheet I40_P500_T50_HR50
A1: Temps (ms) | B1: Fréquence (Hz) | C1: Module de Z (mOhm) | D1: déphasage de Z (°) | E1: Partie réelle | F1: Partie imaginaire | G1: Module de Zstack (mOhm) | H1: déphasage de Zstack (°) | I1: Partie réelle stack | J1: Partie imaginaire stack | K1: Column1
A2: 0 | B2: 1000 | C2: 39.05659 | D2: -13.50979 | E2: 37.9759 | F2: -9.12407 | G2: #NUM! | H2: #NUM! | I2: #NUM! | J2: #NUM!
A3: 3819 | B3: 935.71429 | C3: 39.51698 | D3: -14.03196 | E3: 38.33782 | F3: -9.58141 | G3: #NUM! | H3: #NUM! | I3: #NUM! | J3: #NUM!
A4: 7697 | B4: 871.42857 | C4: 39.94009 | D4: -14.27331 | E4: 38.70717 | F4: -9.84713 | G4: #NUM! | H4: #NUM! | I4: #NUM! | J4: #NUM!
A5: 11528 | B5: 807.14286 | C5: 40.70032 | D5: -14.35398 | E5: 39.42976 | F5: -10.09009 | G5: #NUM! | H5: #NUM! | I5: #NUM! | J5: #NUM!
A6: 15581 | B6: 742.85714 | C6: 40.55514 | D6: -374.9118 | E6: 39.18937 | F6: -10.43613 | G6: #NUM! | H6: #NUM! | I6: #NUM! | J6: #NUM!
A7: 19468 | B7: 678.57143 | C7: 41.44749 | D7: -375.58238 | E7: 39.9241 | F7: -11.13378 | G7: #NUM! | H7: #NUM! | I7: #NUM! | J7: #NUM!
A8: 23347 | B8: 614.28571 | C8: 41.95146 | D8: -375.68079 | E8: 40.39013 | F8: -11.33855 | G8: #NUM! | H8: #NUM! | I8: #NUM! | J8: #NUM!
A9: 27228 | B9: 550 | C9: 42.30344 | D9: -376.26612 | E9: 40.61008 | F9: -11.84915 | G9: #NUM! | H9: #NUM! | I9: #NUM! | J9: #NUM!
A10: 31101 | B10: 485.71429 | C10: 43.48116 | D10: -376.87525 | E10: 41.60882 | F10: -12.62209 | G10: #NUM! | H10: #NUM! | I10: #NUM! | J10: #NUM!
A11: 34981 | B11: 421.42857 | C11: 44.21929 | D11: -378.23921 | E11: 41.99762 | F11: -13.83997 | G11: #NUM! | H11: #NUM! | I11: #NUM! | J11: #NUM!
A12: 38907 | B12: 357.14286 | C12: 45.60776 | D12: -379.26842 | E12: 43.05295 | F12: -15.05029 | G12: #NUM! | H12: #NUM! | I12: #NUM! | J12: #NUM!
A13: 42825 | B13: 292.85714 | C13: 47.0713 | D13: -20.88754 | E13: 43.97787 | F13: -16.78256 | G13: #NUM! | H13: #NUM! | I13: #NUM! | J13: #NUM!
... A48: 265890 | B48: 0.1 | C48: 492.88745 | D48: 1.75807 | E48: 492.65544 | F48: 15.12144 | G48: #NUM! | H48: #NUM! | I48: #NUM! | J48: #NUM!

Sheet I45_P300_T50_HR50
A1: Temps (ms) | B1: Fréquence (Hz) | C1: Module de Z (mOhm) | D1: déphasage de Z (°) | E1: Partie réelle | F1: Partie imaginaire | G1: Module de Zstack (mOhm) | H1: déphasage de Zstack (°) | I1: Partie réelle stack | J1: Partie imaginaire stack | K1: Column1
A2: 0 | B2: 1000 | C2: 40.85701 | D2: -13.85488 | E2: 39.66829 | F2: -9.78377 | G2: #NUM! | H2: #NUM! | I2: #NUM! | J2: #NUM!
A3: 3985 | B3: 935.71429 | C3: 41.55109 | D3: -13.99148 | E3: 40.31834 | F3: -10.04612 | G3: #NUM! | H3: #NUM! | I3: #NUM! | J3: #NUM!
A4: 8598 | B4: 871.42857 | C4: 41.60763 | D4: -14.89721 | E4: 40.20913 | F4: -10.69673 | G4: #NUM! | H4: #NUM! | I4: #NUM! | J4: #NUM!
A5: 13140 | B5: 807.14286 | C5: 42.323 | D5: -15.0834 | E5: 40.86489 | F5: -11.01349 | G5: #NUM! | H5: #NUM! | I5: #NUM! | J5: #NUM!
A6: 17734 | B6: 742.85714 | C6: 42.55759 | D6: -375.41564 | E6: 41.02649 | F6: -11.31263 | G6: #NUM! | H6: #NUM! | I6: #NUM! | J6: #NUM!
A7: 22155 | B7: 678.57143 | C7: 43.40299 | D7: -376.1704 | E7: 41.68587 | F7: -12.08751 | G7: #NUM! | H7: #NUM! | I7: #NUM! | J7: #NUM!
A8: 26771 | B8: 614.28571 | C8: 43.86284 | D8: -376.15407 | E8: 42.13101 | F8: -12.20357 | G8: #NUM! | H8: #NUM! | I8: #NUM! | J8: #NUM!
A9: 31214 | B9: 550 | C9: 44.31751 | D9: -376.94246 | E9: 42.39404 | F9: -12.91462 | G9: #NUM! | H9: #NUM! | I9: #NUM! | J9: #NUM!
A10: 35827 | B10: 485.71429 | C10: 45.35881 | D10: -377.52369 | E10: 43.25382 | F10: -13.65754 | G10: #NUM! | H10: #NUM! | I10: #NUM! | J10: #NUM!
A11: 40520 | B11: 421.42857 | C11: 46.29721 | D11: -378.77858 | E11: 43.83279 | F11: -14.90361 | G11: #NUM! | H11: #NUM! | I11: #NUM! | J11: #NUM!
A12: 45078 | B12: 357.14286 | C12: 47.42937 | D12: -379.88453 | E12: 44.60163 | F12: -16.13195 | G12: #NUM! | H12: #NUM! | I12: #NUM! | J12: #NUM!
A13: 49554 | B13: 292.85714 | C13: 49.28733 | D13: -21.38353 | E13: 45.89442 | F13: -17.97061 | G13: #NUM! | H13: #NUM! | I13: #NUM! | J13: #NUM!
... A48: 285691 | B48: 0.1 | C48: 734.08763 | D48: 1.90223 | E48: 733.6831 | F48: 24.36731 | G48: #NUM! | H48: #NUM! | I48: #NUM! | J48: #NUM!

Sheet I45_P400_T50_HR50
A1: Temps (ms) | B1: Fréquence (Hz) | C1: Module de Z (mOhm) | D1: déphasage de Z (°) | E1: Partie réelle | F1: Partie imaginaire | G1: Module de Zstack (mOhm) | H1: déphasage de Zstack (°) | I1: Partie réelle stack | J1: Partie imaginaire stack | K1: Column1
A2: 0 | B2: 1000 | C2: 39.69845 | D2: -13.17013 | E2: 38.6543 | F2: -9.04502 | G2: #NUM! | H2: #NUM! | I2: #NUM! | J2: #NUM!
A3: 4186 | B3: 935.71429 | C3: 40.07917 | D3: -13.89135 | E3: 38.90696 | F3: -9.62226 | G3: #NUM! | H3: #NUM! | I3: #NUM! | J3: #NUM!
A4: 8677 | B4: 871.42857 | C4: 40.52763 | D4: -14.36202 | E4: 39.26106 | F4: -10.05279 | G4: #NUM! | H4: #NUM! | I4: #NUM! | J4: #NUM!
A5: 12708 | B5: 807.14286 | C5: 41.37198 | D5: -14.20068 | E5: 40.10776 | F5: -10.14933 | G5: #NUM! | H5: #NUM! | I5: #NUM! | J5: #NUM!
A6: 17154 | B6: 742.85714 | C6: 41.74131 | D6: -375.1006 | E6: 40.29997 | F6: -10.87422 | G6: #NUM! | H6: #NUM! | I6: #NUM! | J6: #NUM!
A7: 20988 | B7: 678.57143 | C7: 42.27287 | D7: -375.4534 | E7: 40.7446 | F7: -11.2638 | G7: #NUM! | H7: #NUM! | I7: #NUM! | J7: #NUM!
A8: 25028 | B8: 614.28571 | C8: 42.77418 | D8: -376.33834 | E8: 41.04684 | F8: -12.03276 | G8: #NUM! | H8: #NUM! | I8: #NUM! | J8: #NUM!
A9: 29460 | B9: 550 | C9: 43.6606 | D9: -376.50512 | E9: 41.86154 | F9: -12.40402 | G9: #NUM! | H9: #NUM! | I9: #NUM! | J9: #NUM!
A10: 33491 | B10: 485.71429 | C10: 44.1404 | D10: -377.34052 | E10: 42.13423 | F10: -13.15604 | G10: #NUM! | H10: #NUM! | I10: #NUM! | J10: #NUM!
A11: 37971 | B11: 421.42857 | C11: 45.54511 | D11: -378.1873 | E11: 43.26973 | F11: -14.21574 | G11: #NUM! | H11: #NUM! | I11: #NUM! | J11: #NUM!
A12: 41863 | B12: 357.14286 | C12: 46.68523 | D12: -379.35512 | E12: 44.0467 | F12: -15.47252 | G12: #NUM! | H12: #NUM! | I12: #NUM! | J12: #NUM!
A13: 45754 | B13: 292.85714 | C13: 48.02016 | D13: -21.28627 | E13: 44.74414 | F13: -17.43266 | G13: #NUM! | H13: #NUM! | I13: #NUM! | J13: #NUM!
... A48: 278758 | B48: 0.1 | C48: 672.33743 | D48: 2.50202 | E48: 671.69647 | F48: 29.35066 | G48: #NUM! | H48: #NUM! | I48: #NUM! | J48: #NUM!

Sheet I45_P500_T50_HR50
A1: Temps (ms) | B1: Fréquence (Hz) | C1: Module de Z (mOhm) | D1: déphasage de Z (°) | E1: Partie réelle | F1: Partie imaginaire | G1: Module de Zstack (mOhm) | H1: déphasage de Zstack (°) | I1: Partie réelle stack | J1: Partie imaginaire stack | K1: Column1
A2: 0 | B2: 1000 | C2: 39.67724 | D2: -14.13703 | E2: 38.47559 | F2: -9.69084 | G2: #NUM! | H2: #NUM! | I2: #NUM! | J2: #NUM!
A3: 3810 | B3: 935.71429 | C3: 39.60904 | D3: -14.03018 | E3: 38.42743 | F3: -9.60253 | G3: #NUM! | H3: #NUM! | I3: #NUM! | J3: #NUM!
A4: 7647 | B4: 871.42857 | C4: 40.2253 | D4: -14.38332 | E4: 38.96446 | F4: -9.99228 | G4: #NUM! | H4: #NUM! | I4: #NUM! | J4: #NUM!
A5: 11658 | B5: 807.14286 | C5: 40.68033 | D5: -14.94689 | E5: 39.30392 | F5: -10.49242 | G5: #NUM! | H5: #NUM! | I5: #NUM! | J5: #NUM!
A6: 15505 | B6: 742.85714 | C6: 41.37426 | D6: -374.94648 | E6: 39.97445 | F6: -10.67111 | G6: #NUM! | H6: #NUM! | I6: #NUM! | J6: #NUM!
A7: 19351 | B7: 678.57143 | C7: 41.39889 | D7: -375.28497 | E7: 39.93447 | F7: -10.91357 | G7: #NUM! | H7: #NUM! | I7: #NUM! | J7: #NUM!
A8: 23227 | B8: 614.28571 | C8: 42.25525 | D8: -375.98442 | E8: 40.62152 | F8: -11.63608 | G8: #NUM! | H8: #NUM! | I8: #NUM! | J8: #NUM!
A9: 27085 | B9: 550 | C9: 42.83372 | D9: -376.69363 | E9: 41.02847 | F9: -12.30416 | G9: #NUM! | H9: #NUM! | I9: #NUM! | J9: #NUM!
A10: 31150 | B10: 485.71429 | C10: 43.52415 | D10: -377.28755 | E10: 41.55796 | F10: -12.93396 | G10: #NUM! | H10: #NUM! | I10: #NUM! | J10: #NUM!
A11: 35042 | B11: 421.42857 | C11: 44.47006 | D11: -378.57742 | E11: 42.1529 | F11: -14.16753 | G11: #NUM! | H11: #NUM! | I11: #NUM! | J11: #NUM!
A12: 38944 | B12: 357.14286 | C12: 45.79229 | D12: -379.21875 | E12: 43.24023 | F12: -15.07371 | G12: #NUM! | H12: #NUM! | I12: #NUM! | J12: #NUM!
A13: 42826 | B13: 292.85714 | C13: 47.49762 | D13: -21.42565 | E13: 44.21517 | F13: -17.35058 | G13: #NUM! | H13: #NUM! | I13: #NUM! | J13: #NUM!
... A48: 270467 | B48: 0.1 | C48: 592.67168 | D48: 1.99438 | E48: 592.31267 | F48: 20.62583 | G48: #NUM! | H48: #NUM! | I48: #NUM! | J48: #NUM!

Sheet I50_P300_T50_HR50
A1: Temps (ms) | B1: Fréquence (Hz) | C1: Module de Z (mOhm) | D1: déphasage de Z (°) | E1: Partie réelle | F1: Partie imaginaire | G1: Module de Zstack (mOhm) | H1: déphasage de Zstack (°) | I1: Partie réelle stack | J1: Partie imaginaire stack | K1: Column1
A2: 0 | B2: 1000 | C2: 42.13127 | D2: -14.60638 | E2: 40.76963 | F2: -10.62454 | G2: #NUM! | H2: #NUM! | I2: #NUM! | J2: #NUM!
A3: 4574 | B3: 935.71429 | C3: 42.54314 | D3: -14.94516 | E3: 41.10404 | F3: -10.97164 | G3: #NUM! | H3: #NUM! | I3: #NUM! | J3: #NUM!
A4: 9205 | B4: 871.42857 | C4: 43.4178 | D4: -15.56868 | E4: 41.82477 | F4: -11.65305 | G4: #NUM! | H4: #NUM! | I4: #NUM! | J4: #NUM!
A5: 13761 | B5: 807.14286 | C5: 44.35238 | D5: -15.14589 | E5: 42.81174 | F5: -11.58828 | G5: #NUM! | H5: #NUM! | I5: #NUM! | J5: #NUM!
A6: 18171 | B6: 742.85714 | C6: 44.40585 | D6: -376.10252 | E6: 42.66367 | F6: -12.31627 | G6: #NUM! | H6: #NUM! | I6: #NUM! | J6: #NUM!
A7: 22762 | B7: 678.57143 | C7: 45.18648 | D7: -376.26145 | E7: 43.37874 | F7: -12.65316 | G7: #NUM! | H7: #NUM! | I7: #NUM! | J7: #NUM!
A8: 27352 | B8: 614.28571 | C8: 45.74149 | D8: -376.97735 | E8: 43.74809 | F8: -13.35622 | G8: #NUM! | H8: #NUM! | I8: #NUM! | J8: #NUM!
A9: 31957 | B9: 550 | C9: 46.21811 | D9: -377.60032 | E9: 44.05459 | F9: -13.97521 | G9: #NUM! | H9: #NUM! | I9: #NUM! | J9: #NUM!
A10: 36531 | B10: 485.71429 | C10: 47.33221 | D10: -378.28585 | E10: 44.94208 | F10: -14.85086 | G10: #NUM! | H10: #NUM! | I10: #NUM! | J10: #NUM!
A11: 40940 | B11: 421.42857 | C11: 48.48027 | D11: -378.94904 | E11: 45.85301 | F11: -15.74286 | G11: #NUM! | H11: #NUM! | I11: #NUM! | J11: #NUM!
A12: 45594 | B12: 357.14286 | C12: 49.77144 | D12: -380.31635 | E12: 46.67515 | F12: -17.28081 | G12: #NUM! | H12: #NUM! | I12: #NUM! | J12: #NUM!
A13: 50058 | B13: 292.85714 | C13: 51.51815 | D13: -22.25076 | E13: 47.68188 | F13: -19.50791 | G13: #NUM! | H13: #NUM! | I13: #NUM! | J13: #NUM!
... A48: 289401 | B48: 0.1 | C48: 1027.0799 | D48: 1.45129 | E48: 1026.7504 | F48: 26.01292 | G48: #NUM! | H48: #NUM! | I48: #NUM! | J48: #NUM!

Sheet I50_P400_T50_HR50
A1: Temps (ms) | B1: Fréquence (Hz) | C1: Module de Z (mOhm) | D1: déphasage de Z (°) | E1: Partie réelle | F1: Partie imaginaire | G1: Module de Zstack (mOhm) | H1: déphasage de Zstack (°) | I1: Partie réelle stack | J1: Partie imaginaire stack | K1: Column1
A2: 0 | B2: 1000 | C2: 41.65825 | D2: -14.02351 | E2: 40.41669 | F2: -10.09463 | G2: #NUM! | H2: #NUM! | I2: #NUM! | J2: #NUM!
A3: 4717 | B3: 935.71429 | C3: 41.95785 | D3: -14.43602 | E3: 40.6331 | F3: -10.46004 | G3: #NUM! | H3: #NUM! | I3: #NUM! | J3: #NUM!
A4: 9293 | B4: 871.42857 | C4: 42.55533 | D4: -15.12015 | E4: 41.0821 | F4: -11.1003 | G4: #NUM! | H4: #NUM! | I4: #NUM! | J4: #NUM!
A5: 13817 | B5: 807.14286 | C5: 42.61703 | D5: -15.38182 | E5: 41.09047 | F5: -11.30418 | G5: #NUM! | H5: #NUM! | I5: #NUM! | J5: #NUM!
A6: 18373 | B6: 742.85714 | C6: 43.0705 | D6: -375.06375 | E6: 41.59047 | F6: -11.19375 | G6: #NUM! | H6: #NUM! | I6: #NUM! | J6: #NUM!
A7: 22916 | B7: 678.57143 | C7: 43.76725 | D7: -375.7643 | E7: 42.12105 | F7: -11.89071 | G7: #NUM! | H7: #NUM! | I7: #NUM! | J7: #NUM!
A8: 27514 | B8: 614.28571 | C8: 44.47162 | D8: -376.58709 | E8: 42.62102 | F8: -12.69542 | G8: #NUM! | H8: #NUM! | I8: #NUM! | J8: #NUM!
A9: 32080 | B9: 550 | C9: 44.8621 | D9: -377.04964 | E9: 42.89045 | F9: -13.15357 | G9: #NUM! | H9: #NUM! | I9: #NUM! | J9: #NUM!
A10: 36647 | B10: 485.71429 | C10: 45.84957 | D10: -377.59175 | E10: 43.70538 | F10: -13.85724 | G10: #NUM! | H10: #NUM! | I10: #NUM! | J10: #NUM!
A11: 41264 | B11: 421.42857 | C11: 47.09828 | D11: -378.79795 | E11: 44.58609 | F11: -15.17656 | G11: #NUM! | H11: #NUM! | I11: #NUM! | J11: #NUM!
A12: 45688 | B12: 357.14286 | C12: 48.3206 | D12: -379.82092 | E12: 45.45795 | F12: -16.38462 | G12: #NUM! | H12: #NUM! | I12: #NUM! | J12: #NUM!
A13: 50312 | B13: 292.85714 | C13: 49.86209 | D13: -21.60342 | E13: 46.35951 | F13: -18.35823 | G13: #NUM! | H13: #NUM! | I13: #NUM! | J13: #NUM!
... A48: 294849 | B48: 0.1 | C48: 888.03823 | D48: 2.51237 | E48: 887.18463 | F48: 38.92721 | G48: #NUM! | H48: #NUM! | I48: #NUM! | J48: #NUM!

Sheet I50_P500_T50_HR50
A1: Temps (ms) | B1: Fréquence (Hz) | C1: Module de Z (mOhm) | D1: déphasage de Z (°) | E1: Partie réelle | F1: Partie imaginaire | G1: Module de Zstack (mOhm) | H1: déphasage de Zstack (°) | I1: Partie réelle stack | J1: Partie imaginaire stack | K1: Column1
A2: 0 | B2: 1000 | C2: 39.9252 | D2: -13.66661 | E2: 38.7948 | F2: -9.43321 | G2: #NUM! | H2: #NUM! | I2: #NUM! | J2: #NUM!
A3: 4685 | B3: 935.71429 | C3: 40.92792 | D3: -14.2703 | E3: 39.66503 | F3: -10.0886 | G3: #NUM! | H3: #NUM! | I3: #NUM! | J3: #NUM!
A4: 9857 | B4: 871.42857 | C4: 41.09213 | D4: -15.26026 | E4: 39.64323 | F4: -10.81561 | G4: #NUM! | H4: #NUM! | I4: #NUM! | J4: #NUM!
A5: 14353 | B5: 807.14286 | C5: 41.72597 | D5: -14.49527 | E5: 40.39776 | F5: -10.44401 | G5: #NUM! | H5: #NUM! | I5: #NUM! | J5: #NUM!
A6: 18916 | B6: 742.85714 | C6: 42.15661 | D6: -374.91072 | E6: 40.73711 | F6: -10.84747 | G6: #NUM! | H6: #NUM! | I6: #NUM! | J6: #NUM!
A7: 23462 | B7: 678.57143 | C7: 42.64613 | D7: -375.27026 | E7: 41.14048 | F7: -11.23181 | G7: #NUM! | H7: #NUM! | I7: #NUM! | J7: #NUM!
A8: 28616 | B8: 614.28571 | C8: 43.33755 | D8: -376.14975 | E8: 41.62736 | F8: -12.05428 | G8: #NUM! | H8: #NUM! | I8: #NUM! | J8: #NUM!
A9: 33189 | B9: 550 | C9: 44.01764 | D9: -376.68042 | E9: 42.16541 | F9: -12.63452 | G9: #NUM! | H9: #NUM! | I9: #NUM! | J9: #NUM!
A10: 37734 | B10: 485.71429 | C10: 44.62804 | D10: -377.44061 | E10: 42.57641 | F10: -13.37578 | G10: #NUM! | H10: #NUM! | I10: #NUM! | J10: #NUM!
A11: 42306 | B11: 421.42857 | C11: 45.65742 | D11: -378.35869 | E11: 43.33361 | F11: -14.38048 | G11: #NUM! | H11: #NUM! | I11: #NUM! | J11: #NUM!
A12: 46864 | B12: 357.14286 | C12: 47.03766 | D12: -379.34893 | E12: 44.3809 | F12: -15.58453 | G12: #NUM! | H12: #NUM! | I12: #NUM! | J12: #NUM!
A13: 52061 | B13: 292.85714 | C13: 48.39983 | D13: -20.98473 | E13: 45.18976 | F13: -17.3329 | G13: #NUM! | H13: #NUM! | I13: #NUM! | J13: #NUM!
... A48: 303064 | B48: 0.1 | C48: 774.63203 | D48: 1.91197 | E48: 774.20076 | F48: 25.84484 | G48: #NUM! | H48: #NUM! | I48: #NUM! | J48: #NUM!

Sheet I20_P300_T50_HRLOW_TBH2_20
A1: Temps (ms) | B1: Fréquence (Hz) | C1: Module de Z (mOhm) | D1: déphasage de Z (°) | E1: Partie réelle | F1: Partie imaginaire | G1: Module de Zstack (mOhm) | H1: déphasage de Zstack (°) | I1: Partie réelle stack | J1: Partie imaginaire stack | K1: Column1
A2: 0 | B2: 1000 | C2: 42.71422 | D2: -13.27 | E2: 41.57371 | F2: -9.80463 | G2: NaN | H2: NaN | I2: NaN | J2: NaN
A3: 1397 | B3: 935.71429 | C3: 41.5591 | D3: -14.48215 | E3: 40.23858 | F3: -10.39303 | G3: NaN | H3: NaN | I3: NaN | J3: NaN
A4: 2600 | B4: 871.42857 | C4: 42.63577 | D4: -13.47546 | E4: 41.462 | F4: -9.93537 | G4: NaN | H4: NaN | I4: NaN | J4: NaN
A5: 3845 | B5: 807.14286 | C5: 42.58254 | D5: -14.74569 | E5: 41.18009 | F5: -10.8385 | G5: NaN | H5: NaN | I5: NaN | J5: NaN
A6: 5026 | B6: 742.85714 | C6: 43.18555 | D6: -374.31521 | E6: 41.84464 | F6: -10.67789 | G6: NaN | H6: NaN | I6: NaN | J6: NaN
A7: 6542 | B7: 678.57143 | C7: 43.59272 | D7: -375.9306 | E7: 41.91853 | F7: -11.96502 | G7: NaN | H7: NaN | I7: NaN | J7: NaN
A8: 7646 | B8: 614.28571 | C8: 45.33198 | D8: -375.93726 | E8: 43.58955 | F8: -12.44746 | G8: NaN | H8: NaN | I8: NaN | J8: NaN
A9: 9052 | B9: 550 | C9: 45.79429 | D9: -376.64696 | E9: 43.87497 | F9: -13.11886 | G9: NaN | H9: NaN | I9: NaN | J9: NaN
A10: 10270 | B10: 485.71429 | C10: 46.54288 | D10: -377.54822 | E10: 44.37694 | F10: -14.03307 | G10: NaN | H10: NaN | I10: NaN | J10: NaN
A11: 11699 | B11: 421.42857 | C11: 47.38677 | D11: -378.19397 | E11: 45.01767 | F11: -14.7958 | G11: NaN | H11: NaN | I11: NaN | J11: NaN
A12: 12879 | B12: 357.14286 | C12: 49.30488 | D12: -379.42707 | E12: 46.49774 | F12: -16.39913 | G12: NaN | H12: NaN | I12: NaN | J12: NaN
A13: 14329 | B13: 292.85714 | C13: 51.29431 | D13: -20.72772 | E13: 47.97418 | F13: -18.15446 | G13: NaN | H13: NaN | I13: NaN | J13: NaN
... A55: 244394 | B55: 0.1 | C55: 167.38872 | D55: 1.09444 | E55: 167.35819 | F55: 3.1972 | G55: NaN | H55: NaN | I55: NaN | J55: NaN

Sheet I20_P300_T50_HRLOW_TBH2_40
A1: Temps (ms) | B1: Fréquence (Hz) | C1: Module de Z (mOhm) | D1: déphasage de Z (°) | E1: Partie réelle | F1: Partie imaginaire | G1: Module de Zstack (mOhm) | H1: déphasage de Zstack (°) | I1: Partie réelle stack | J1: Partie imaginaire stack | K1: Column1
A2: 0 | B2: 1000 | C2: 40.37302 | D2: -14.56169 | E2: 39.07614 | F2: -10.15067 | G2: NaN | H2: NaN | I2: NaN | J2: NaN
A3: 1635 | B3: 935.71429 | C3: 41.02297 | D3: -13.58174 | E3: 39.87579 | F3: -9.63352 | G3: NaN | H3: NaN | I3: NaN | J3: NaN
A4: 3007 | B4: 871.42857 | C4: 41.97446 | D4: -14.41073 | E4: 40.6538 | F4: -10.44624 | G4: NaN | H4: NaN | I4: NaN | J4: NaN
A5: 4668 | B5: 807.14286 | C5: 41.79849 | D5: -16.47088 | E5: 40.08324 | F5: -11.85104 | G5: NaN | H5: NaN | I5: NaN | J5: NaN
A6: 6275 | B6: 742.85714 | C6: 42.52571 | D6: -374.92863 | E6: 41.09036 | F6: -10.95529 | G6: NaN | H6: NaN | I6: NaN | J6: NaN
A7: 7475 | B7: 678.57143 | C7: 43.77995 | D7: -376.13939 | E7: 42.05451 | F7: -12.16974 | G7: NaN | H7: NaN | I7: NaN | J7: NaN
A8: 8874 | B8: 614.28571 | C8: 44.4072 | D8: -376.39597 | E8: 42.60133 | F8: -12.535 | G8: NaN | H8: NaN | I8: NaN | J8: NaN
A9: 10117 | B9: 550 | C9: 45.29932 | D9: -377.02949 | E9: 43.31313 | F9: -13.26653 | G9: NaN | H9: NaN | I9: NaN | J9: NaN
A10: 11307 | B10: 485.71429 | C10: 45.64285 | D10: -377.26206 | E10: 43.58698 | F10: -13.54418 | G10: NaN | H10: NaN | I10: NaN | J10: NaN
A11: 12717 | B11: 421.42857 | C11: 46.99902 | D11: -377.9013 | E11: 44.72368 | F11: -14.44648 | G11: NaN | H11: NaN | I11: NaN | J11: NaN
A12: 13929 | B12: 357.14286 | C12: 48.29815 | D12: -379.16128 | E12: 45.62236 | F12: -15.85282 | G12: NaN | H12: NaN | I12: NaN | J12: NaN
A13: 15381 | B13: 292.85714 | C13: 50.46636 | D13: -20.6518 | E13: 47.22345 | F13: -17.79887 | G13: NaN | H13: NaN | I13: NaN | J13: NaN
... A55: 250142 | B55: 0.1 | C55: 164.70763 | D55: 1.24172 | E55: 164.66895 | F55: 3.56928 | G55: NaN | H55: NaN | I55: NaN | J55: NaN

Sheet I20_P300_T50_HRLOW_TBH2_65
A1: Temps (ms) | B1: Fr駲uence (Hz) | C1: Module de Z (mOhm) | D1: d駱hasage de Z (ｰ) | E1: Partie r馥lle | F1: Partie imaginaire | G1: Module de Zstack (mOhm) | H1: d駱hasage de Zstack (ｰ) | I1: Partie r馥lle stack | J1: Partie imaginaire stack
A2: 0 | B2: 1000 | C2: 38.79899 | D2: -11.79742 | E2: 37.97942 | F2: -7.93253 | G2: NaN | H2: NaN | I2: NaN | J2: NaN
A3: 71019 | B3: 935.71429 | C3: 39.66208 | D3: -14.90373 | E3: 38.32782 | F3: -10.20092 | G3: NaN | H3: NaN | I3: NaN | J3: NaN
A4: 72747 | B4: 871.42857 | C4: 39.89583 | D4: -14.08221 | E4: 38.69686 | F4: -9.70721 | G4: NaN | H4: NaN | I4: NaN | J4: NaN
A5: 74067 | B5: 807.14286 | C5: 41.12869 | D5: -15.302 | E5: 39.67061 | F5: -10.85414 | G5: NaN | H5: NaN | I5: NaN | J5: NaN
A6: 76031 | B6: 742.85714 | C6: 40.81903 | D6: -374.14349 | E6: 39.58168 | F6: -9.97417 | G6: NaN | H6: NaN | I6: NaN | J6: NaN
A7: 78085 | B7: 678.57143 | C7: 42.26078 | D7: -376.17709 | E7: 40.58747 | F7: -11.77415 | G7: NaN | H7: NaN | I7: NaN | J7: NaN
A8: 79958 | B8: 614.28571 | C8: 42.41091 | D8: -375.43868 | E8: 40.88055 | F8: -11.29008 | G8: NaN | H8: NaN | I8: NaN | J8: NaN
A9: 82015 | B9: 550 | C9: 43.16014 | D9: -376.52675 | E9: 41.37707 | F9: -12.27746 | G9: NaN | H9: NaN | I9: NaN | J9: NaN
A10: 83894 | B10: 485.71429 | C10: 43.99713 | D10: -376.6867 | E10: 42.14437 | F10: -12.63325 | G10: NaN | H10: NaN | I10: NaN | J10: NaN
A11: 85849 | B11: 421.42857 | C11: 45.24079 | D11: -377.93264 | E11: 43.04296 | F11: -13.92958 | G11: NaN | H11: NaN | I11: NaN | J11: NaN
A12: 87813 | B12: 357.14286 | C12: 46.48327 | D12: -379.30532 | E12: 43.86953 | F12: -15.36746 | G12: NaN | H12: NaN | I12: NaN | J12: NaN
A13: 89751 | B13: 292.85714 | C13: 48.39711 | D13: -20.83614 | E13: 45.23202 | F13: -17.21469 | G13: NaN | H13: NaN | I13: NaN | J13: NaN
... A55: 862290 | B55: 0.1 | C55: 163.22506 | D55: 0.14029 | E55: 163.22457 | F55: 0.39965 | G55: NaN | H55: NaN | I55: NaN | J55: NaN

Sheet I10_P300_T50_HR0
A1: Temps (ms) | B1: Fr駲uence (Hz) | C1: Module de Z (mOhm) | D1: d駱hasage de Z (ｰ) | E1: Partie r馥lle | F1: Partie imaginaire | G1: Module de Zstack (mOhm) | H1: d駱hasage de Zstack (ｰ) | I1: Partie r馥lle stack | J1: Partie imaginaire stack
A2: 0 | B2: 1000 | C2: 40.74084 | D2: -13.27043 | E2: 39.65295 | F2: -9.35196 | G2: NaN | H2: NaN | I2: NaN | J2: NaN
A3: 2400 | B3: 935.71429 | C3: 42.289 | D3: -14.59569 | E3: 40.92425 | F3: -10.65668 | G3: NaN | H3: NaN | I3: NaN | J3: NaN
A4: 3796 | B4: 871.42857 | C4: 42.38094 | D4: -15.38052 | E4: 40.8631 | F4: -11.24063 | G4: NaN | H4: NaN | I4: NaN | J4: NaN
A5: 5294 | B5: 807.14286 | C5: 43.39522 | D5: -13.85577 | E5: 42.13249 | F5: -10.39222 | G5: NaN | H5: NaN | I5: NaN | J5: NaN
A6: 6448 | B6: 742.85714 | C6: 43.80595 | D6: -374.48976 | E6: 42.41259 | F6: -10.96056 | G6: NaN | H6: NaN | I6: NaN | J6: NaN
A7: 7670 | B7: 678.57143 | C7: 43.92117 | D7: -375.39833 | E7: 42.34454 | F7: -11.6623 | G7: NaN | H7: NaN | I7: NaN | J7: NaN
A8: 9087 | B8: 614.28571 | C8: 43.80128 | D8: -376.03029 | E8: 42.0981 | F8: -12.09553 | G8: NaN | H8: NaN | I8: NaN | J8: NaN
A9: 10326 | B9: 550 | C9: 45.34667 | D9: -376.29835 | E9: 43.52434 | F9: -12.72605 | G9: NaN | H9: NaN | I9: NaN | J9: NaN
A10: 11595 | B10: 485.71429 | C10: 46.51259 | D10: -376.75025 | E10: 44.53906 | F10: -13.40495 | G10: NaN | H10: NaN | I10: NaN | J10: NaN
A11: 12987 | B11: 421.42857 | C11: 47.25361 | D11: -378.17751 | E11: 44.8954 | F11: -14.74133 | G11: NaN | H11: NaN | I11: NaN | J11: NaN
A12: 14197 | B12: 357.14286 | C12: 48.86655 | D12: -379.65228 | E12: 46.02012 | F12: -16.43436 | G12: NaN | H12: NaN | I12: NaN | J12: NaN
A13: 15689 | B13: 292.85714 | C13: 50.24216 | D13: -20.39165 | E13: 47.09362 | F13: -17.50615 | G13: NaN | H13: NaN | I13: NaN | J13: NaN
... A55: 250912 | B55: 0.1 | C55: 314.26119 | D55: -2.04468 | E55: 314.0611 | F55: -11.21244 | G55: NaN | H55: NaN | I55: NaN | J55: NaN

Sheet I20_P300_T50_HR0
A1: Temps (ms) | B1: Fr駲uence (Hz) | C1: Module de Z (mOhm) | D1: d駱hasage de Z (ｰ) | E1: Partie r馥lle | F1: Partie imaginaire | G1: Module de Zstack (mOhm) | H1: d駱hasage de Zstack (ｰ) | I1: Partie r馥lle stack | J1: Partie imaginaire stack
A2: 0 | B2: 1000 | C2: 42.6679 | D2: -13.01094 | E2: 41.57249 | F2: -9.60613 | G2: NaN | H2: NaN | I2: NaN | J2: NaN
A3: 1202 | B3: 935.71429 | C3: 41.63166 | D3: -13.68823 | E3: 40.44922 | F3: -9.85166 | G3: NaN | H3: NaN | I3: NaN | J3: NaN
A4: 2634 | B4: 871.42857 | C4: 42.07231 | D4: -14.09229 | E4: 40.80613 | F4: -10.24396 | G4: NaN | H4: NaN | I4: NaN | J4: NaN
A5: 3809 | B5: 807.14286 | C5: 42.72997 | D5: -14.20601 | E5: 41.42328 | F5: -10.48632 | G5: NaN | H5: NaN | I5: NaN | J5: NaN
A6: 5019 | B6: 742.85714 | C6: 42.65788 | D6: -374.68462 | E6: 41.26449 | F6: -10.8137 | G6: NaN | H6: NaN | I6: NaN | J6: NaN
A7: 6445 | B7: 678.57143 | C7: 43.73198 | D7: -374.79078 | E7: 42.2829 | F7: -11.16434 | G7: NaN | H7: NaN | I7: NaN | J7: NaN
A8: 7637 | B8: 614.28571 | C8: 44.67706 | D8: -375.24708 | E8: 43.10446 | F8: -11.74926 | G8: NaN | H8: NaN | I8: NaN | J8: NaN
A9: 9066 | B9: 550 | C9: 45.25564 | D9: -376.35312 | E9: 43.42481 | F9: -12.74202 | G9: NaN | H9: NaN | I9: NaN | J9: NaN
A10: 10259 | B10: 485.71429 | C10: 46.38408 | D10: -377.34474 | E10: 44.27492 | F10: -13.82804 | G10: NaN | H10: NaN | I10: NaN | J10: NaN
A11: 11680 | B11: 421.42857 | C11: 47.00407 | D11: -378.00369 | E11: 44.70259 | F11: -14.52794 | G11: NaN | H11: NaN | I11: NaN | J11: NaN
A12: 12864 | B12: 357.14286 | C12: 48.65291 | D12: -378.43182 | E12: 46.15704 | F12: -15.38288 | G12: NaN | H12: NaN | I12: NaN | J12: NaN
A13: 14096 | B13: 292.85714 | C13: 50.61524 | D13: -19.99677 | E13: 47.56374 | F13: -17.30875 | G13: NaN | H13: NaN | I13: NaN | J13: NaN
... A55: 247053 | B55: 0.1 | C55: 245.16758 | D55: 0.27511 | E55: 245.16476 | F55: 1.17719 | G55: NaN | H55: NaN | I55: NaN | J55: NaN

Sheet I30_P300_T50_HR0
A1: Temps (ms) | B1: Fr駲uence (Hz) | C1: Module de Z (mOhm) | D1: d駱hasage de Z (ｰ) | E1: Partie r馥lle | F1: Partie imaginaire | G1: Module de Zstack (mOhm) | H1: d駱hasage de Zstack (ｰ) | I1: Partie r馥lle stack | J1: Partie imaginaire stack
A2: 0 | B2: 1000 | C2: 42.21151 | D2: -14.74787 | E2: 40.82087 | F2: -10.74561 | G2: NaN | H2: NaN | I2: NaN | J2: NaN
A3: 1191 | B3: 935.71429 | C3: 41.63551 | D3: -13.94238 | E3: 40.40887 | F3: -10.03191 | G3: NaN | H3: NaN | I3: NaN | J3: NaN
A4: 2430 | B4: 871.42857 | C4: 42.60793 | D4: -14.01553 | E4: 41.3395 | F4: -10.319 | G4: NaN | H4: NaN | I4: NaN | J4: NaN
A5: 3822 | B5: 807.14286 | C5: 43.03453 | D5: -14.64987 | E5: 41.63545 | F5: -10.88393 | G5: NaN | H5: NaN | I5: NaN | J5: NaN
A6: 5241 | B6: 742.85714 | C6: 43.64897 | D6: -374.85315 | E6: 42.19048 | F6: -11.18909 | G6: NaN | H6: NaN | I6: NaN | J6: NaN
A7: 6427 | B7: 678.57143 | C7: 44.77146 | D7: -375.1309 | E7: 43.21932 | F7: -11.68647 | G7: NaN | H7: NaN | I7: NaN | J7: NaN
A8: 7702 | B8: 614.28571 | C8: 44.84481 | D8: -375.44777 | E8: 43.22473 | F8: -11.94486 | G8: NaN | H8: NaN | I8: NaN | J8: NaN
A9: 9051 | B9: 550 | C9: 45.96866 | D9: -376.44704 | E9: 44.08771 | F9: -13.01506 | G9: NaN | H9: NaN | I9: NaN | J9: NaN
A10: 10357 | B10: 485.71429 | C10: 46.39017 | D10: -376.73685 | E10: 44.42497 | F10: -13.35928 | G10: NaN | H10: NaN | I10: NaN | J10: NaN
A11: 11680 | B11: 421.42857 | C11: 47.82122 | D11: -378.06052 | E11: 45.46505 | F11: -14.8256 | G11: NaN | H11: NaN | I11: NaN | J11: NaN
A12: 12925 | B12: 357.14286 | C12: 49.04662 | D12: -379.23247 | E12: 46.30932 | F12: -16.15605 | G12: NaN | H12: NaN | I12: NaN | J12: NaN
A13: 14101 | B13: 292.85714 | C13: 50.60156 | D13: -20.2873 | E13: 47.46254 | F13: -17.54497 | G13: NaN | H13: NaN | I13: NaN | J13: NaN
... A55: 247631 | B55: 0.1 | C55: 323.12249 | D55: 0.79348 | E55: 323.0915 | F55: 4.47473 | G55: NaN | H55: NaN | I55: NaN | J55: NaN

Sheet I35_P300_T50_HR0
A1: Temps (ms) | B1: Fr駲uence (Hz) | C1: Module de Z (mOhm) | D1: d駱hasage de Z (ｰ) | E1: Partie r馥lle | F1: Partie imaginaire | G1: Module de Zstack (mOhm) | H1: d駱hasage de Zstack (ｰ) | I1: Partie r馥lle stack | J1: Partie imaginaire stack
A2: 0 | B2: 1000 | C2: 40.7791 | D2: -13.93794 | E2: 39.57845 | F2: -9.8225 | G2: NaN | H2: NaN | I2: NaN | J2: NaN
A3: 1476 | B3: 935.71429 | C3: 41.54002 | D3: -13.87674 | E3: 40.32763 | F3: -9.9627 | G3: NaN | H3: NaN | I3: NaN | J3: NaN
A4: 3398 | B4: 871.42857 | C4: 42.45937 | D4: -13.57557 | E4: 41.27311 | F4: -9.96639 | G4: NaN | H4: NaN | I4: NaN | J4: NaN
A5: 4712 | B5: 807.14286 | C5: 42.66818 | D5: -14.80372 | E5: 41.25189 | F5: -10.90209 | G5: NaN | H5: NaN | I5: NaN | J5: NaN
A6: 6732 | B6: 742.85714 | C6: 43.50559 | D6: -374.26951 | E6: 42.16332 | F6: -10.7234 | G6: NaN | H6: NaN | I6: NaN | J6: NaN
A7: 8526 | B7: 678.57143 | C7: 44.16359 | D7: -374.96129 | E7: 42.66647 | F7: -11.40156 | G7: NaN | H7: NaN | I7: NaN | J7: NaN
A8: 10597 | B8: 614.28571 | C8: 45.41917 | D8: -375.6702 | E8: 43.73104 | F8: -12.26771 | G8: NaN | H8: NaN | I8: NaN | J8: NaN
A9: 12647 | B9: 550 | C9: 45.5547 | D9: -376.26654 | E9: 43.73111 | F9: -12.76015 | G9: NaN | H9: NaN | I9: NaN | J9: NaN
A10: 14524 | B10: 485.71429 | C10: 46.4438 | D10: -377.1664 | E10: 44.3748 | F10: -13.70779 | G10: NaN | H10: NaN | I10: NaN | J10: NaN
A11: 16455 | B11: 421.42857 | C11: 47.43471 | D11: -378.23502 | E11: 45.05258 | F11: -14.84306 | G11: NaN | H11: NaN | I11: NaN | J11: NaN
A12: 18419 | B12: 357.14286 | C12: 48.82954 | D12: -379.1874 | E12: 46.11699 | F12: -16.04827 | G12: NaN | H12: NaN | I12: NaN | J12: NaN
A13: 20398 | B13: 292.85714 | C13: 50.56424 | D13: -20.78107 | E13: 47.27468 | F13: -17.9401 | G13: NaN | H13: NaN | I13: NaN | J13: NaN
... A55: 275348 | B55: 0.1 | C55: 371.57652 | D55: 1.05153 | E55: 371.51395 | F55: 6.81903 | G55: NaN | H55: NaN | I55: NaN | J55: NaN

Sheet I40_P300_T50_HR0
A1: Temps (ms) | B1: Fr駲uence (Hz) | C1: Module de Z (mOhm) | D1: d駱hasage de Z (ｰ) | E1: Partie r馥lle | F1: Partie imaginaire | G1: Module de Zstack (mOhm) | H1: d駱hasage de Zstack (ｰ) | I1: Partie r馥lle stack | J1: Partie imaginaire stack
A2: 0 | B2: 1000 | C2: 42.02105 | D2: -14.23428 | E2: 40.73094 | F2: -10.33244 | G2: NaN | H2: NaN | I2: NaN | J2: NaN
A3: 2211 | B3: 935.71429 | C3: 42.53802 | D3: -13.85476 | E3: 41.30041 | F3: -10.18622 | G3: NaN | H3: NaN | I3: NaN | J3: NaN
A4: 4242 | B4: 871.42857 | C4: 42.57492 | D4: -14.5774 | E4: 41.20437 | F4: -10.71558 | G4: NaN | H4: NaN | I4: NaN | J4: NaN
A5: 6064 | B5: 807.14286 | C5: 43.3522 | D5: -14.45208 | E5: 41.98039 | F5: -10.81942 | G5: NaN | H5: NaN | I5: NaN | J5: NaN
A6: 8065 | B6: 742.85714 | C6: 43.77262 | D6: -374.73091 | E6: 42.33384 | F6: -11.13049 | G6: NaN | H6: NaN | I6: NaN | J6: NaN
A7: 10072 | B7: 678.57143 | C7: 44.61332 | D7: -375.66414 | E7: 42.95642 | F7: -12.0455 | G7: NaN | H7: NaN | I7: NaN | J7: NaN
A8: 11916 | B8: 614.28571 | C8: 45.14902 | D8: -375.57803 | E8: 43.49049 | F8: -12.12479 | G8: NaN | H8: NaN | I8: NaN | J8: NaN
A9: 13940 | B9: 550 | C9: 45.88939 | D9: -376.54435 | E9: 43.98955 | F9: -13.06734 | G9: NaN | H9: NaN | I9: NaN | J9: NaN
A10: 15960 | B10: 485.71429 | C10: 46.51128 | D10: -377.23495 | E10: 44.42282 | F10: -13.78086 | G10: NaN | H10: NaN | I10: NaN | J10: NaN
A11: 18419 | B11: 421.42857 | C11: 47.73901 | D11: -378.12245 | E11: 45.37086 | F11: -14.84916 | G11: NaN | H11: NaN | I11: NaN | J11: NaN
A12: 20502 | B12: 357.14286 | C12: 49.24225 | D12: -378.83581 | E12: 46.60522 | F12: -15.89822 | G12: NaN | H12: NaN | I12: NaN | J12: NaN
A13: 22365 | B13: 292.85714 | C13: 50.80666 | D13: -20.81211 | E13: 47.49155 | F13: -18.05184 | G13: NaN | H13: NaN | I13: NaN | J13: NaN
... A55: 287066 | B55: 0.1 | C55: 449.77057 | D55: 0.04852 | E55: 449.77041 | F55: 0.38092 | G55: NaN | H55: NaN | I55: NaN | J55: NaN

Sheet I45_P300_T50_HR0
A1: Temps (ms) | B1: Fr駲uence (Hz) | C1: Module de Z (mOhm) | D1: d駱hasage de Z (ｰ) | E1: Partie r馥lle | F1: Partie imaginaire | G1: Module de Zstack (mOhm) | H1: d駱hasage de Zstack (ｰ) | I1: Partie r馥lle stack | J1: Partie imaginaire stack
A2: 0 | B2: 1000 | C2: 43.20011 | D2: -13.3859 | E2: 42.02649 | F2: -10.00119 | G2: NaN | H2: NaN | I2: NaN | J2: NaN
A3: 2249 | B3: 935.71429 | C3: 43.43509 | D3: -14.20745 | E3: 42.10656 | F3: -10.66042 | G3: NaN | H3: NaN | I3: NaN | J3: NaN
A4: 4891 | B4: 871.42857 | C4: 43.20913 | D4: -14.79034 | E4: 41.77746 | F4: -11.03055 | G4: NaN | H4: NaN | I4: NaN | J4: NaN
A5: 7500 | B5: 807.14286 | C5: 44.04876 | D5: -15.11554 | E5: 42.52476 | F5: -11.48644 | G5: NaN | H5: NaN | I5: NaN | J5: NaN
A6: 9931 | B6: 742.85714 | C6: 44.56106 | D6: -375.11258 | E6: 43.01994 | F6: -11.61781 | G6: NaN | H6: NaN | I6: NaN | J6: NaN
A7: 12593 | B7: 678.57143 | C7: 45.55174 | D7: -375.58884 | E7: 43.87612 | F7: -12.24122 | G7: NaN | H7: NaN | I7: NaN | J7: NaN
A8: 15280 | B8: 614.28571 | C8: 45.71757 | D8: -375.82793 | E8: 43.9842 | F8: -12.46943 | G8: NaN | H8: NaN | I8: NaN | J8: NaN
